Workbook

Sheet Sheet1
R1: 1
P2: =SUM(P4:P5) -> 0 | Q2: =SUM(Q4:Q5) -> 0 | R2: =SUM(R4:R5) -> 0
J3: ABS 포지션 | K3: =ABS(K4)+K5 -> 0 | O3: 상품 | P3: ETF 델타 | Q3: 선물 델타 | R3: NET 델타 | S3: 계약수 환산 | T3: 필요 계약수 | U3: 당일 손익 | V3: NET
J4: 매도 포지션 | K4: =SUMIFS($N$15:$N$977,$N$15:$N$977,"<0") -> 0 | N4: =U4/ABS(N14) -> #DIV/0! | O4: KOSPI 200 | P4: =X14 -> 0 | Q4: =N10 -> 0 | R4: =(P4+Q4)*R1 -> 0 | S4: =R4/T10 -> 0 | T4: =S4*-1 -> 0 | U4: =S9+T14 -> -11835291 | V4: 바스켓
J5: 매수 포재션 | K5: =SUMIFS($N$15:$N$977,$N$15:$N$977,">0") -> 0 | N5: =U4/N12 -> #DIV/0! | O5: KOSDAQ 150 | P5: =Y14 -> 0 | Q5: =N11 -> 0 | R5: =(P5+Q5)*R1 -> 0 | S5: =R5/T11 -> 0 | T5: =S5*-1 -> 0 | V5: 현금
B7: 종목코드 | C7: 종목명 | D7: 1CU | E7: 시장 거래량 | F7: 펀드코드 | G7: 당일매도수량 | H7: 당일매도금액 | I7: 매도단가 | J7: 당일매수수량 | K7: 당일매수금액 | L7: 매수단가 | M7: NET 포지션 수량 | N7: NET 포지션 금액 | O7: CU 비중 | P7: 현재가 | Q7: 매도 손익 | R7: 매수 손익 | S7: 당일 손익 | T7: 1계약 델타 | U7: 전체 잔고 수량
B9: - | C9: - | D9: - | E9: - | F9: - | G9: =SUM(G10:G11) -> 74 | H9: =SUM(H10:H11) -> 1592640000 | I9: - | J9: =SUM(J10:J11) -> 74 | K9: =SUM(K10:K11) -> 1590088000 | L9: - | M9: =SUM(M10:M11) -> 0 | N9: =SUM(N10:N11) -> 0 | O9: - | P9: - | Q9: =SUM(Q10:Q11) -> -3167000 | R9: =SUM(R10:R11) -> 5719000 | S9: =SUM(S10:S11) -> 2552000 | T9: =SUM(T10:T11) -> 68987000 | U9: =SUM(U10:U11) -> 0
B10: A0569 | C10: 미니 코스피 200 선물 | D10: 0 | E10: - | F10: 028875 | G10: =IF([1]!'028875^A0569:SELL_TDY_QTY'="NO", 0, [1]!'028875^A0569:SELL_TDY_QTY') -> 13 | H10: =IF([1]!'028875^A0569:SELL_TDY_AMT'="NO", 0, [1]!'028875^A0569:SELL_TDY_AMT') -> 711099000 | I10: =IFERROR(H10/G10/50000,0) -> 1093.9985 | J10: =IF([1]!'028875^A0569:BUY_TDY_QTY'="NO", 0, [1]!'028875^A0569:BUY_TDY_QTY') -> 13 | K10: =IF([1]!'028875^A0569:BUY_TDY_AMT'="NO", 0, [1]!'028875^A0569:BUY_TDY_AMT') -> 706016000 | L10: =IFERROR(K10/J10/50000,0) -> 1086.1785 | M10: =J10-G10 -> 0 | N10: =M10*P10*50000 -> 0 | O10: - | P10: =[1]!'A0569:LAST' -> 1088.5 | Q10: =(P10-I10)*-1*G10*50000 -> 3574000 | R10: =(P10-L10)*J10*50000 -> 1509000 | S10: =Q10+R10 -> 5083000 | T10: =P10*50000 -> 54425000 | U10: =IF([1]!'028875^A0569:QTY'="NO", 0, [1]!'028875^A0569:QTY') -> 0
B11: A0669 | C11: 코스닥 150 선물 | D11: 0 | E11: - | F11: 028875 | G11: =IF([1]!'028875^A0669:SELL_TDY_QTY'="NO", 0, [1]!'028875^A0669:SELL_TDY_QTY') -> 61 | H11: =IF([1]!'028875^A0669:SELL_TDY_AMT'="NO", 0, [1]!'028875^A0669:SELL_TDY_AMT') -> 881541000 | I11: =IFERROR(H11/G11/10000,0) -> 1445.1492 | J11: =IF([1]!'028875^A0669:BUY_TDY_QTY'="NO", 0, [1]!'028875^A0669:BUY_TDY_QTY') -> 61 | K11: =IF([1]!'028875^A0669:BUY_TDY_AMT'="NO", 0, [1]!'028875^A0669:BUY_TDY_AMT') -> 884072000 | L11: =IFERROR(K11/J11/10000,0) -> 1449.2984 | M11: =J11-G11 -> 0 | N11: =M11*P11*10000 -> 0 | O11: - | P11: =[1]!'A0669:LAST' -> 1456.2 | Q11: =(P11-I11)*-1*G11*10000 -> -6741000 | R11: =(P11-L11)*J11*10000 -> 4210000 | S11: =Q11+R11 -> -2531000 | T11: =P11*10000 -> 14562000 | U11: =IF([1]!'028875^A0669:QTY'="NO", 0, [1]!'028875^A0669:QTY') -> 0
G12: =@IF(@KBMonitor|DATA!'019875^091220:SELL_TDY_QTY'="NO", 0, KBMonitor|DATA!'019875^091220:SELL_TDY_QTY') | N12: =AE14 -> 0 | T12: * 200과 150은 전일종가(금액)으로 계산 | AA12: 유리 여부
B13: 종목코드 | C13: 종목명 | D13: 1CU | E13: 시장 거래량 | F13: 펀드코드 | G13: 당일매도수량 | H13: 당일매도금액 | I13: 매도단가 | J13: 당일매수수량 | K13: 당일매수금액 | L13: 매수단가 | M13: NET 포지션 수량 | N13: NET 포지션 금액 | O13: CU 비중 | P13: 현재가 | Q13: NAV | R13: 매도 손익 | S13: 매수 손익 | T13: 당일 손익 | U13: KS 베타 | V13: KQ 베타 | W13: R-Squared | X13: W.KOSPI200 | Y13: W.KOSDAQ150 | Z13: W.200&150 외 | AA13: 매도 손익 (nav 대비) | AB13: 매수 손익 (nav 대비) | AC13: 매도 손익 (nav 대비) | AD13: 매수 손익 (nav 대비) | AE13: 포지션 abs
B14: - | C14: - | D14: - | E14: - | F14: - | G14: =SUM(G15:G943) -> 381774 | H14: =SUM(H15:H943) -> 5113049433 | I14: - | J14: =SUM(J15:J943) -> 381774 | K14: =SUM(K15:K943) -> 5127436724 | L14: - | M14: =SUM(M15:M943) -> 0 | N14: =SUM(N15:N943) -> 0 | O14: - | P14: - | R14: =SUM(R15:R943) -> -31576227 | S14: =SUM(S15:S943) -> 17188936 | T14: =SUM(T15:T943) -> -14387291 | U14: =AVERAGE(U15:U978) -> 0.26038158 | V14: =AVERAGE(V15:V978) -> 0.48707105 | W14: =AVERAGE(W15:W978) -> 0.63083158 | X14: =SUM(X15:X978) -> 0 | Y14: =SUM(Y15:Y978) -> 0 | Z14: =SUM(Z15:Z978) -> 0 | AA14: =SUM(AA15:AA978) -> 0 | AB14: =SUM(AB15:AB978) -> 0 | AC14: =SUM(AC15:AC978) -> 0 | AD14: =SUM(AD15:AD978) -> 0 | AE14: =SUM(AE15:AE978) -> 0 | AJ14: 매도 bp | AK14: 매수 bp
B15: 396500 | C15: TIGER 반도체TOP10 | D15: =VLOOKUP("A"&B15,[2]ETF!$A$4:$M$10000,13,FALSE) -> 50000 | E15: =[1]!'396500:VOL'+0 -> 10073000 | F15: 019875 | G15: =IF([1]!'019875^396500:SELL_TDY_QTY'="NO", 0, [1]!'019875^396500:SELL_TDY_QTY') -> 4995 | H15: =IF([1]!'019875^396500:SELL_TDY_AMT'="NO", 0, [1]!'019875^396500:SELL_TDY_AMT') -> 178173125 | I15: =IFERROR(H15/G15,0) -> 35670.295 | J15: =IF([1]!'019875^396500:BUY_TDY_QTY'="NO", 0, [1]!'019875^396500:BUY_TDY_QTY') -> 4995 | K15: =IF([1]!'019875^396500:BUY_TDY_AMT'="NO", 0, [1]!'019875^396500:BUY_TDY_AMT') -> 179881495 | L15: =IFERROR(K15/J15,0) -> 36012.311 | M15: =J15-G15 -> 0 | N15: =M15*P15 -> 0 | O15: =M15/D15 -> 0 | P15: =[1]!'396500:LAST' -> 35865 | Q15: =[1]!'396500:NAV' -> 35878.57 | R15: =(P15-I15)*-1*G15 -> -972550 | S15: =(P15-L15)*J15 -> -735820 | T15: =R15+S15 -> -1708370 | U15: =_xlfn.IFNA(VLOOKUP(B15,[2]베타!$A$2:$C$1000,3,FALSE),0) -> 1.1067 | V15: =_xlfn.IFNA(VLOOKUP(B15,[2]베타!$A$2:$D$1000,4,FALSE),0) -> 0.1884 | W15: =_xlfn.IFNA(VLOOKUP(B15,[2]베타!$A$2:$E$1000,5,FALSE),0) -> 0.928 | X15: =M15*Q15*U15 -> 0 | Y15: =M15*Q15*V15 -> 0 | Z15: =(P15*M15)-(X15+Y15) -> 0 | AA15: =IF(M15<0, P15-Q15, 0) -> 0 | AB15: =IF(M15>0, Q15*(1-0.2%)-P15, 0) -> 0 | AC15: =AA15/Q15*10000 -> 0 | AD15: =AB15/Q15*10000 -> 0 | AE15: =ABS(N15) -> 0 | AG15: =B15 -> 396500 | AH15: =-1*M15 -> 0 | AJ15: =ROUNDUP(VLOOKUP(B15,[2]베타!$A$2:$J$1000,10,FALSE),0) -> -2 | AK15: =ROUNDUP(VLOOKUP(B15,[2]베타!$A$2:$K$1000,11,FALSE),0) -> -19
B16: 228790 | C16: TIGER 화장품 | D16: =VLOOKUP("A"&B16,[2]ETF!$A$4:$M$10000,13,FALSE) -> 30000 | E16: =[1]!'228790:VOL'+0 -> 6940082 | F16: 019875 | G16: =IF([1]!'019875^228790:SELL_TDY_QTY'="NO", 0, [1]!'019875^228790:SELL_TDY_QTY') -> 101422 | H16: =IF([1]!'019875^228790:SELL_TDY_AMT'="NO", 0, [1]!'019875^228790:SELL_TDY_AMT') -> 480830847 | I16: =IFERROR(H16/G16,0) -> 4740.893 | J16: =IF([1]!'019875^228790:BUY_TDY_QTY'="NO", 0, [1]!'019875^228790:BUY_TDY_QTY') -> 101422 | K16: =IF([1]!'019875^228790:BUY_TDY_AMT'="NO", 0, [1]!'019875^228790:BUY_TDY_AMT') -> 479329965 | L16: =IFERROR(K16/J16,0) -> 4726.0946 | M16: =J16-G16 -> 0 | N16: =M16*P16 -> 0 | O16: =M16/D16 -> 0 | P16: =[1]!'228790:LAST' -> 4740 | Q16: =[1]!'228790:NAV' -> 4736.35 | R16: =(P16-I16)*-1*G16 -> 90567 | S16: =(P16-L16)*J16 -> 1410315 | T16: =R16+S16 -> 1500882 | U16: =_xlfn.IFNA(VLOOKUP(B16,[2]베타!$A$2:$C$1000,3,FALSE),0) -> -0.1759 | V16: =_xlfn.IFNA(VLOOKUP(B16,[2]베타!$A$2:$D$1000,4,FALSE),0) -> 0.5739 | W16: =_xlfn.IFNA(VLOOKUP(B16,[2]베타!$A$2:$E$1000,5,FALSE),0) -> 0.4315 | X16: =M16*Q16*U16 -> 0 | Y16: =M16*Q16*V16 -> 0 | Z16: =(P16*M16)-(X16+Y16) -> 0 | AA16: =IF(M16<0, P16-Q16, 0) -> 0 | AB16: =IF(M16>0, Q16*(1-0.2%)-P16, 0) -> 0 | AC16: =AA16/Q16*10000 -> 0 | AD16: =AB16/Q16*10000 -> 0 | AE16: =ABS(N16) -> 0 | AG16: =B16 -> 228790 | AH16: =-1*M16 -> 0 | AJ16: =ROUNDUP(VLOOKUP(B16,[2]베타!$A$2:$J$1000,10,FALSE),0) -> 8 | AK16: =ROUNDUP(VLOOKUP(B16,[2]베타!$A$2:$K$1000,11,FALSE),0) -> -30
B17: 462010 | C17: TIGER 2차전지소재Fn | D17: =VLOOKUP("A"&B17,[2]ETF!$A$4:$M$10000,13,FALSE) -> 50000 | E17: =[1]!'462010:VOL'+0 -> 5603384 | F17: 019875 | G17: =IF([1]!'019875^462010:SELL_TDY_QTY'="NO", 0, [1]!'019875^462010:SELL_TDY_QTY') -> 26269 | H17: =IF([1]!'019875^462010:SELL_TDY_AMT'="NO", 0, [1]!'019875^462010:SELL_TDY_AMT') -> 132269795 | I17: =IFERROR(H17/G17,0) -> 5035.2048 | J17: =IF([1]!'019875^462010:BUY_TDY_QTY'="NO", 0, [1]!'019875^462010:BUY_TDY_QTY') -> 26269 | K17: =IF([1]!'019875^462010:BUY_TDY_AMT'="NO", 0, [1]!'019875^462010:BUY_TDY_AMT') -> 131250250 | L17: =IFERROR(K17/J17,0) -> 4996.3931 | M17: =J17-G17 -> 0 | N17: =M17*P17 -> 0 | O17: =M17/D17 -> 0 | P17: =[1]!'462010:LAST' -> 5080 | Q17: =[1]!'462010:NAV' -> 5087.1 | R17: =(P17-I17)*-1*G17 -> -1176725 | S17: =(P17-L17)*J17 -> 2196270 | T17: =R17+S17 -> 1019545 | U17: =_xlfn.IFNA(VLOOKUP(B17,[2]베타!$A$2:$C$1000,3,FALSE),0) -> 0.0571 | V17: =_xlfn.IFNA(VLOOKUP(B17,[2]베타!$A$2:$D$1000,4,FALSE),0) -> 0.866 | W17: =_xlfn.IFNA(VLOOKUP(B17,[2]베타!$A$2:$E$1000,5,FALSE),0) -> 0.69 | X17: =M17*Q17*U17 -> 0 | Y17: =M17*Q17*V17 -> 0 | Z17: =(P17*M17)-(X17+Y17) -> 0 | AA17: =IF(M17<0, P17-Q17, 0) -> 0 | AB17: =IF(M17>0, Q17*(1-0.2%)-P17, 0) -> 0 | AC17: =AA17/Q17*10000 -> 0 | AD17: =AB17/Q17*10000 -> 0 | AE17: =ABS(N17) -> 0 | AG17: =B17 -> 462010 | AH17: =-1*M17 -> 0 | AJ17: =ROUNDUP(VLOOKUP(B17,[2]베타!$A$2:$J$1000,10,FALSE),0) -> 9 | AK17: =ROUNDUP(VLOOKUP(B17,[2]베타!$A$2:$K$1000,11,FALSE),0) -> -26
B18: 364980 | C18: TIGER 2차전지TOP10 | D18: =VLOOKUP("A"&B18,[2]ETF!$A$4:$M$10000,13,FALSE) -> 50000 | E18: =[1]!'364980:VOL'+0 -> 3636198 | F18: 019875 | G18: =IF([1]!'019875^364980:SELL_TDY_QTY'="NO", 0, [1]!'019875^364980:SELL_TDY_QTY') -> 51023 | H18: =IF([1]!'019875^364980:SELL_TDY_AMT'="NO", 0, [1]!'019875^364980:SELL_TDY_AMT') -> 538393491 | I18: =IFERROR(H18/G18,0) -> 10551.976 | J18: =IF([1]!'019875^364980:BUY_TDY_QTY'="NO", 0, [1]!'019875^364980:BUY_TDY_QTY') -> 51023 | K18: =IF([1]!'019875^364980:BUY_TDY_AMT'="NO", 0, [1]!'019875^364980:BUY_TDY_AMT') -> 539525575 | L18: =IFERROR(K18/J18,0) -> 10574.164 | M18: =J18-G18 -> 0 | N18: =M18*P18 -> 0 | O18: =M18/D18 -> 0 | P18: =[1]!'364980:LAST' -> 10655 | Q18: =[1]!'364980:NAV' -> 10676.47 | R18: =(P18-I18)*-1*G18 -> -5256574 | S18: =(P18-L18)*J18 -> 4124490 | T18: =R18+S18 -> -1132084 | U18: =_xlfn.IFNA(VLOOKUP(B18,[2]베타!$A$2:$C$1000,3,FALSE),0) -> 0.0798 | V18: =_xlfn.IFNA(VLOOKUP(B18,[2]베타!$A$2:$D$1000,4,FALSE),0) -> 0.7019 | W18: =_xlfn.IFNA(VLOOKUP(B18,[2]베타!$A$2:$E$1000,5,FALSE),0) -> 0.5663 | X18: =M18*Q18*U18 -> 0 | Y18: =M18*Q18*V18 -> 0 | Z18: =(P18*M18)-(X18+Y18) -> 0 | AA18: =IF(M18<0, P18-Q18, 0) -> 0 | AB18: =IF(M18>0, Q18*(1-0.2%)-P18, 0) -> 0 | AC18: =AA18/Q18*10000 -> 0 | AD18: =AB18/Q18*10000 -> 0 | AE18: =ABS(N18) -> 0 | AG18: =B18 -> 364980 | AH18: =-1*M18 -> 0 | AJ18: =ROUNDUP(VLOOKUP(B18,[2]베타!$A$2:$J$1000,10,FALSE),0) -> 6 | AK18: =ROUNDUP(VLOOKUP(B18,[2]베타!$A$2:$K$1000,11,FALSE),0) -> -26
B19: 0117V0 | C19: TIGER 코리아AI전력기기TOP3플러스 | D19: =VLOOKUP("A"&B19,[2]ETF!$A$4:$M$10000,13,FALSE) -> 50000 | E19: =[1]!'0117V0:VOL'+0 -> 3420066 | F19: 019875 | G19: =IF([1]!'019875^0117V0:SELL_TDY_QTY'="NO", 0, [1]!'019875^0117V0:SELL_TDY_QTY') -> 35981 | H19: =IF([1]!'019875^0117V0:SELL_TDY_AMT'="NO", 0, [1]!'019875^0117V0:SELL_TDY_AMT') -> 690841280 | I19: =IFERROR(H19/G19,0) -> 19200.169 | J19: =IF([1]!'019875^0117V0:BUY_TDY_QTY'="NO", 0, [1]!'019875^0117V0:BUY_TDY_QTY') -> 35981 | K19: =IF([1]!'019875^0117V0:BUY_TDY_AMT'="NO", 0, [1]!'019875^0117V0:BUY_TDY_AMT') -> 698177099 | L19: =IFERROR(K19/J19,0) -> 19404.049 | M19: =J19-G19 -> 0 | N19: =M19*P19 -> 0 | O19: =M19/D19 -> 0 | P19: =[1]!'0117V0:LAST' -> 19705 | Q19: =[1]!'0117V0:NAV' -> 19739.54 | R19: =(P19-I19)*-1*G19 -> -18164325 | S19: =(P19-L19)*J19 -> 10828506 | T19: =R19+S19 -> -7335819 | U19: =_xlfn.IFNA(VLOOKUP(B19,[2]베타!$A$2:$C$1000,3,FALSE),0) -> 0.4329 | V19: =_xlfn.IFNA(VLOOKUP(B19,[2]베타!$A$2:$D$1000,4,FALSE),0) -> 0.6516 | W19: =_xlfn.IFNA(VLOOKUP(B19,[2]베타!$A$2:$E$1000,5,FALSE),0) -> 0.6751 | X19: =M19*Q19*U19 -> 0 | Y19: =M19*Q19*V19 -> 0 | Z19: =(P19*M19)-(X19+Y19) -> 0 | AA19: =IF(M19<0, P19-Q19, 0) -> 0 | AB19: =IF(M19>0, Q19*(1-0.2%)-P19, 0) -> 0 | AC19: =AA19/Q19*10000 -> 0 | AD19: =AB19/Q19*10000 -> 0 | AE19: =ABS(N19) -> 0 | AG19: =B19 -> 0117V0 | AH19: =-1*M19 -> 0 | AJ19: =ROUNDUP(VLOOKUP(B19,[2]베타!$A$2:$J$1000,10,FALSE),0) -> 5 | AK19: =ROUNDUP(VLOOKUP(B19,[2]베타!$A$2:$K$1000,11,FALSE),0) -> -25
B20: 305540 | C20: TIGER 2차전지테마 | D20: =VLOOKUP("A"&B20,[2]ETF!$A$4:$M$10000,13,FALSE) -> 50000 | E20: =[1]!'305540:VOL'+0 -> 613424 | F20: 019875 | G20: =IF([1]!'019875^305540:SELL_TDY_QTY'="NO", 0, [1]!'019875^305540:SELL_TDY_QTY') -> 20535 | H20: =IF([1]!'019875^305540:SELL_TDY_AMT'="NO", 0, [1]!'019875^305540:SELL_TDY_AMT') -> 388285730 | I20: =IFERROR(H20/G20,0) -> 18908.485 | J20: =IF([1]!'019875^305540:BUY_TDY_QTY'="NO", 0, [1]!'019875^305540:BUY_TDY_QTY') -> 20535 | K20: =IF([1]!'019875^305540:BUY_TDY_AMT'="NO", 0, [1]!'019875^305540:BUY_TDY_AMT') -> 386277850 | L20: =IFERROR(K20/J20,0) -> 18810.706 | M20: =J20-G20 -> 0 | N20: =M20*P20 -> 0 | O20: =M20/D20 -> 0 | P20: =[1]!'305540:LAST' -> 19050 | Q20: =[1]!'305540:NAV' -> 19092.5 | R20: =(P20-I20)*-1*G20 -> -2906020 | S20: =(P20-L20)*J20 -> 4913900 | T20: =R20+S20 -> 2007880 | U20: =_xlfn.IFNA(VLOOKUP(B20,[2]베타!$A$2:$C$1000,3,FALSE),0) -> 0.048 | V20: =_xlfn.IFNA(VLOOKUP(B20,[2]베타!$A$2:$D$1000,4,FALSE),0) -> 0.7342 | W20: =_xlfn.IFNA(VLOOKUP(B20,[2]베타!$A$2:$E$1000,5,FALSE),0) -> 0.615 | X20: =M20*Q20*U20 -> 0 | Y20: =M20*Q20*V20 -> 0 | Z20: =(P20*M20)-(X20+Y20) -> 0 | AA20: =IF(M20<0, P20-Q20, 0) -> 0 | AB20: =IF(M20>0, Q20*(1-0.2%)-P20, 0) -> 0 | AC20: =AA20/Q20*10000 -> 0 | AD20: =AB20/Q20*10000 -> 0 | AE20: =ABS(N20) -> 0 | AG20: =B20 -> 305540 | AH20: =-1*M20 -> 0 | AJ20: =ROUNDUP(VLOOKUP(B20,[2]베타!$A$2:$J$1000,10,FALSE),0) -> 6 | AK20: =ROUNDUP(VLOOKUP(B20,[2]베타!$A$2:$K$1000,11,FALSE),0) -> -26
B21: 494670 | C21: TIGER 조선TOP10 | D21: =VLOOKUP("A"&B21,[2]ETF!$A$4:$M$10000,13,FALSE) -> 50000 | E21: =[1]!'494670:VOL'+0 -> 209692 | F21: 019875 | G21: =IF([1]!'019875^494670:SELL_TDY_QTY'="NO", 0, [1]!'019875^494670:SELL_TDY_QTY') -> 6667 | H21: =IF([1]!'019875^494670:SELL_TDY_AMT'="NO", 0, [1]!'019875^494670:SELL_TDY_AMT') -> 149412545 | I21: =IFERROR(H21/G21,0) -> 22410.761 | J21: =IF([1]!'019875^494670:BUY_TDY_QTY'="NO", 0, [1]!'019875^494670:BUY_TDY_QTY') -> 6667 | K21: =IF([1]!'019875^494670:BUY_TDY_AMT'="NO", 0, [1]!'019875^494670:BUY_TDY_AMT') -> 150538835 | L21: =IFERROR(K21/J21,0) -> 22579.696 | M21: =J21-G21 -> 0 | N21: =M21*P21 -> 0 | O21: =M21/D21 -> 0 | P21: =[1]!'494670:LAST' -> 22450 | Q21: =[1]!'494670:NAV' -> 22470.21 | R21: =(P21-I21)*-1*G21 -> -261605 | S21: =(P21-L21)*J21 -> -864685 | T21: =R21+S21 -> -1126290 | U21: =_xlfn.IFNA(VLOOKUP(B21,[2]베타!$A$2:$C$1000,3,FALSE),0) -> 0.1542 | V21: =_xlfn.IFNA(VLOOKUP(B21,[2]베타!$A$2:$D$1000,4,FALSE),0) -> 0.4998 | W21: =_xlfn.IFNA(VLOOKUP(B21,[2]베타!$A$2:$E$1000,5,FALSE),0) -> 0.4757 | X21: =M21*Q21*U21 -> 0 | Y21: =M21*Q21*V21 -> 0 | Z21: =(P21*M21)-(X21+Y21) -> 0 | AA21: =IF(M21<0, P21-Q21, 0) -> 0 | AB21: =IF(M21>0, Q21*(1-0.2%)-P21, 0) -> 0 | AC21: =AA21/Q21*10000 -> 0 | AD21: =AB21/Q21*10000 -> 0 | AE21: =ABS(N21) -> 0 | AG21: =B21 -> 494670 | AH21: =-1*M21 -> 0 | AJ21: =ROUNDUP(VLOOKUP(B21,[2]베타!$A$2:$J$1000,10,FALSE),0) -> 4 | AK21: =ROUNDUP(VLOOKUP(B21,[2]베타!$A$2:$K$1000,11,FALSE),0) -> -24
B22: 364970 | C22: TIGER 바이오TOP10 | D22: =VLOOKUP("A"&B22,[2]ETF!$A$4:$M$10000,13,FALSE) -> 50000 | E22: =[1]!'364970:VOL'+0 -> 721069 | F22: 019875 | G22: =IF([1]!'019875^364970:SELL_TDY_QTY'="NO", 0, [1]!'019875^364970:SELL_TDY_QTY') -> 2000 | H22: =IF([1]!'019875^364970:SELL_TDY_AMT'="NO", 0, [1]!'019875^364970:SELL_TDY_AMT') -> 15331765 | I22: =IFERROR(H22/G22,0) -> 7665.8825 | J22: =IF([1]!'019875^364970:BUY_TDY_QTY'="NO", 0, [1]!'019875^364970:BUY_TDY_QTY') -> 2000 | K22: =IF([1]!'019875^364970:BUY_TDY_AMT'="NO", 0, [1]!'019875^364970:BUY_TDY_AMT') -> 15325000 | L22: =IFERROR(K22/J22,0) -> 7662.5 | M22: =J22-G22 -> 0 | N22: =M22*P22 -> 0 | O22: =M22/D22 -> 0 | P22: =[1]!'364970:LAST' -> 7665 | Q22: =[1]!'364970:NAV' -> 7660.62 | R22: =(P22-I22)*-1*G22 -> 1765 | S22: =(P22-L22)*J22 -> 5000 | T22: =R22+S22 -> 6765 | U22: =_xlfn.IFNA(VLOOKUP(B22,[2]베타!$A$2:$C$1000,3,FALSE),0) -> -0.0401 | V22: =_xlfn.IFNA(VLOOKUP(B22,[2]베타!$A$2:$D$1000,4,FALSE),0) -> 0.6018 | W22: =_xlfn.IFNA(VLOOKUP(B22,[2]베타!$A$2:$E$1000,5,FALSE),0) -> 0.5906 | X22: =M22*Q22*U22 -> 0 | Y22: =M22*Q22*V22 -> 0 | Z22: =(P22*M22)-(X22+Y22) -> 0 | AA22: =IF(M22<0, P22-Q22, 0) -> 0 | AB22: =IF(M22>0, Q22*(1-0.2%)-P22, 0) -> 0 | AC22: =AA22/Q22*10000 -> 0 | AD22: =AB22/Q22*10000 -> 0 | AE22: =ABS(N22) -> 0 | AG22: =B22 -> 364970 | AH22: =-1*M22 -> 0 | AJ22: =ROUNDUP(VLOOKUP(B22,[2]베타!$A$2:$J$1000,10,FALSE),0) -> 4 | AK22: =ROUNDUP(VLOOKUP(B22,[2]베타!$A$2:$K$1000,11,FALSE),0) -> -26
B23: 0091P0 | C23: TIGER 코리아원자력 | D23: =VLOOKUP("A"&B23,[2]ETF!$A$4:$M$10000,13,FALSE) -> 50000 | E23: =[1]!'0091P0:VOL'+0 -> 3997902 | F23: 019875 | G23: =IF([1]!'019875^0091P0:SELL_TDY_QTY'="NO", 0, [1]!'019875^0091P0:SELL_TDY_QTY') -> 38448 | H23: =IF([1]!'019875^0091P0:SELL_TDY_AMT'="NO", 0, [1]!'019875^0091P0:SELL_TDY_AMT') -> 691124830 | I23: =IFERROR(H23/G23,0) -> 17975.573 | J23: =IF([1]!'019875^0091P0:BUY_TDY_QTY'="NO", 0, [1]!'019875^0091P0:BUY_TDY_QTY') -> 38448 | K23: =IF([1]!'019875^0091P0:BUY_TDY_AMT'="NO", 0, [1]!'019875^0091P0:BUY_TDY_AMT') -> 692694175 | L23: =IFERROR(K23/J23,0) -> 18016.39 | M23: =J23-G23 -> 0 | N23: =M23*P23 -> 0 | O23: =M23/D23 -> 0 | P23: =[1]!'0091P0:LAST' -> 17950 | Q23: =[1]!'0091P0:NAV' -> 17982.73 | R23: =(P23-I23)*-1*G23 -> 983230 | S23: =(P23-L23)*J23 -> -2552575 | T23: =R23+S23 -> -1569345 | U23: =_xlfn.IFNA(VLOOKUP(B23,[2]베타!$A$2:$C$1000,3,FALSE),0) -> 0.202 | V23: =_xlfn.IFNA(VLOOKUP(B23,[2]베타!$A$2:$D$1000,4,FALSE),0) -> 0.8348 | W23: =_xlfn.IFNA(VLOOKUP(B23,[2]베타!$A$2:$E$1000,5,FALSE),0) -> 0.687 | X23: =M23*Q23*U23 -> 0 | Y23: =M23*Q23*V23 -> 0 | Z23: =(P23*M23)-(X23+Y23) -> 0 | AA23: =IF(M23<0, P23-Q23, 0) -> 0 | AB23: =IF(M23>0, Q23*(1-0.2%)-P23, 0) -> 0 | AC23: =AA23/Q23*10000 -> 0 | AD23: =AB23/Q23*10000 -> 0 | AE23: =ABS(N23) -> 0 | AG23: =B23 -> 0091P0 | AH23: =-1*M23 -> 0 | AJ23: =ROUNDUP(VLOOKUP(B23,[2]베타!$A$2:$J$1000,10,FALSE),0) -> 5 | AK23: =ROUNDUP(VLOOKUP(B23,[2]베타!$A$2:$K$1000,11,FALSE),0) -> -26
B24: 292150 | C24: TIGER 코리아TOP10 | D24: =VLOOKUP("A"&B24,[2]ETF!$A$4:$M$10000,13,FALSE) -> 50000 | E24: =[1]!'292150:VOL'+0 -> 296325 | F24: 019875 | G24: =IF([1]!'019875^292150:SELL_TDY_QTY'="NO", 0, [1]!'019875^292150:SELL_TDY_QTY') -> 6977 | H24: =IF([1]!'019875^292150:SELL_TDY_AMT'="NO", 0, [1]!'019875^292150:SELL_TDY_AMT') -> 265941510 | I24: =IFERROR(H24/G24,0) -> 38116.885 | J24: =IF([1]!'019875^292150:BUY_TDY_QTY'="NO", 0, [1]!'019875^292150:BUY_TDY_QTY') -> 6977 | K24: =IF([1]!'019875^292150:BUY_TDY_AMT'="NO", 0, [1]!'019875^292150:BUY_TDY_AMT') -> 266982650 | L24: =IFERROR(K24/J24,0) -> 38266.11 | M24: =J24-G24 -> 0 | N24: =M24*P24 -> 0 | O24: =M24/D24 -> 0 | P24: =[1]!'292150:LAST' -> 38210 | Q24: =[1]!'292150:NAV' -> 38273.65 | R24: =(P24-I24)*-1*G24 -> -649660 | S24: =(P24-L24)*J24 -> -391480 | T24: =R24+S24 -> -1041140 | U24: =_xlfn.IFNA(VLOOKUP(B24,[2]베타!$A$2:$C$1000,3,FALSE),0) -> 0.9683 | V24: =_xlfn.IFNA(VLOOKUP(B24,[2]베타!$A$2:$D$1000,4,FALSE),0) -> -0.0005 | W24: =_xlfn.IFNA(VLOOKUP(B24,[2]베타!$A$2:$E$1000,5,FALSE),0) -> 0.9822 | X24: =M24*Q24*U24 -> 0 | Y24: =M24*Q24*V24 -> 0 | Z24: =(P24*M24)-(X24+Y24) -> 0 | AA24: =IF(M24<0, P24-Q24, 0) -> 0 | AB24: =IF(M24>0, Q24*(1-0.2%)-P24, 0) -> 0 | AC24: =AA24/Q24*10000 -> 0 | AD24: =AB24/Q24*10000 -> 0 | AE24: =ABS(N24) -> 0 | AG24: =B24 -> 292150 | AH24: =-1*M24 -> 0 | AJ24: =ROUNDUP(VLOOKUP(B24,[2]베타!$A$2:$J$1000,10,FALSE),0) -> 2 | AK24: =ROUNDUP(VLOOKUP(B24,[2]베타!$A$2:$K$1000,11,FALSE),0) -> -23
B25: 139230 | C25: TIGER 200 중공업 | D25: =VLOOKUP("A"&B25,[2]ETF!$A$4:$M$10000,13,FALSE) -> 20000 | E25: =[1]!'139230:VOL'+0 -> 226761 | F25: 019875 | G25: =IF([1]!'019875^139230:SELL_TDY_QTY'="NO", 0, [1]!'019875^139230:SELL_TDY_QTY') -> 396 | H25: =IF([1]!'019875^139230:SELL_TDY_AMT'="NO", 0, [1]!'019875^139230:SELL_TDY_AMT') -> 5340060 | I25: =IFERROR(H25/G25,0) -> 13485 | J25: =IF([1]!'019875^139230:BUY_TDY_QTY'="NO", 0, [1]!'019875^139230:BUY_TDY_QTY') -> 396 | K25: =IF([1]!'019875^139230:BUY_TDY_AMT'="NO", 0, [1]!'019875^139230:BUY_TDY_AMT') -> 5339585 | L25: =IFERROR(K25/J25,0) -> 13483.801 | M25: =J25-G25 -> 0 | N25: =M25*P25 -> 0 | O25: =M25/D25 -> 0 | P25: =[1]!'139230:LAST' -> 13515 | Q25: =[1]!'139230:NAV' -> 13546.11 | R25: =(P25-I25)*-1*G25 -> -11880 | S25: =(P25-L25)*J25 -> 12355 | T25: =R25+S25 -> 475 | U25: =_xlfn.IFNA(VLOOKUP(B25,[2]베타!$A$2:$C$1000,3,FALSE),0) -> 0.2426 | V25: =_xlfn.IFNA(VLOOKUP(B25,[2]베타!$A$2:$D$1000,4,FALSE),0) -> 0.5695 | W25: =_xlfn.IFNA(VLOOKUP(B25,[2]베타!$A$2:$E$1000,5,FALSE),0) -> 0.6763 | X25: =M25*Q25*U25 -> 0 | Y25: =M25*Q25*V25 -> 0 | Z25: =(P25*M25)-(X25+Y25) -> 0 | AA25: =IF(M25<0, P25-Q25, 0) -> 0 | AB25: =IF(M25>0, Q25*(1-0.2%)-P25, 0) -> 0 | AC25: =AA25/Q25*10000 -> 0 | AD25: =AB25/Q25*10000 -> 0 | AE25: =ABS(N25) -> 0 | AG25: =B25 -> 139230 | AH25: =-1*M25 -> 0 | AJ25: =ROUNDUP(VLOOKUP(B25,[2]베타!$A$2:$J$1000,10,FALSE),0) -> 10 | AK25: =ROUNDUP(VLOOKUP(B25,[2]베타!$A$2:$K$1000,11,FALSE),0) -> -27
B26: 364990 | C26: TIGER 게임TOP10 | D26: =VLOOKUP("A"&B26,[2]ETF!$A$4:$M$10000,13,FALSE) -> 50000 | E26: =[1]!'364990:VOL'+0 -> 101715 | F26: 019875 | G26: =IF([1]!'019875^364990:SELL_TDY_QTY'="NO", 0, [1]!'019875^364990:SELL_TDY_QTY') -> 1467 | H26: =IF([1]!'019875^364990:SELL_TDY_AMT'="NO", 0, [1]!'019875^364990:SELL_TDY_AMT') -> 6979285 | I26: =IFERROR(H26/G26,0) -> 4757.5222 | J26: =IF([1]!'019875^364990:BUY_TDY_QTY'="NO", 0, [1]!'019875^364990:BUY_TDY_QTY') -> 1467 | K26: =IF([1]!'019875^364990:BUY_TDY_AMT'="NO", 0, [1]!'019875^364990:BUY_TDY_AMT') -> 6894900 | L26: =IFERROR(K26/J26,0) -> 4700 | M26: =J26-G26 -> 0 | N26: =M26*P26 -> 0 | O26: =M26/D26 -> 0 | P26: =[1]!'364990:LAST' -> 4705 | Q26: =[1]!'364990:NAV' -> 4710.44 | R26: =(P26-I26)*-1*G26 -> 77050 | S26: =(P26-L26)*J26 -> 7335 | T26: =R26+S26 -> 84385 | U26: =_xlfn.IFNA(VLOOKUP(B26,[2]베타!$A$2:$C$1000,3,FALSE),0) -> -0.0908 | V26: =_xlfn.IFNA(VLOOKUP(B26,[2]베타!$A$2:$D$1000,4,FALSE),0) -> 0.3873 | W26: =_xlfn.IFNA(VLOOKUP(B26,[2]베타!$A$2:$E$1000,5,FALSE),0) -> 0.2399 | X26: =M26*Q26*U26 -> 0 | Y26: =M26*Q26*V26 -> 0 | Z26: =(P26*M26)-(X26+Y26) -> 0 | AA26: =IF(M26<0, P26-Q26, 0) -> 0 | AB26: =IF(M26>0, Q26*(1-0.2%)-P26, 0) -> 0 | AC26: =AA26/Q26*10000 -> 0 | AD26: =AB26/Q26*10000 -> 0 | AE26: =ABS(N26) -> 0 | AG26: =B26 -> 364990 | AH26: =-1*M26 -> 0 | AJ26: =ROUNDUP(VLOOKUP(B26,[2]베타!$A$2:$J$1000,10,FALSE),0) -> 20 | AK26: =ROUNDUP(VLOOKUP(B26,[2]베타!$A$2:$K$1000,11,FALSE),0) -> -32
B27: 157500 | C27: TIGER 증권 | D27: =VLOOKUP("A"&B27,[2]ETF!$A$4:$M$10000,13,FALSE) -> 20000 | E27: =[1]!'157500:VOL'+0 -> 298530 | F27: 019875 | G27: =IF([1]!'019875^157500:SELL_TDY_QTY'="NO", 0, [1]!'019875^157500:SELL_TDY_QTY') -> 1131 | H27: =IF([1]!'019875^157500:SELL_TDY_AMT'="NO", 0, [1]!'019875^157500:SELL_TDY_AMT') -> 14318965 | I27: =IFERROR(H27/G27,0) -> 12660.447 | J27: =IF([1]!'019875^157500:BUY_TDY_QTY'="NO", 0, [1]!'019875^157500:BUY_TDY_QTY') -> 1131 | K27: =IF([1]!'019875^157500:BUY_TDY_AMT'="NO", 0, [1]!'019875^157500:BUY_TDY_AMT') -> 14247795 | L27: =IFERROR(K27/J27,0) -> 12597.52 | M27: =J27-G27 -> 0 | N27: =M27*P27 -> 0 | O27: =M27/D27 -> 0 | P27: =[1]!'157500:LAST' -> 12535 | Q27: =[1]!'157500:NAV' -> 12560.92 | R27: =(P27-I27)*-1*G27 -> 141880 | S27: =(P27-L27)*J27 -> -70710 | T27: =R27+S27 -> 71170 | U27: =_xlfn.IFNA(VLOOKUP(B27,[2]베타!$A$2:$C$1000,3,FALSE),0) -> 0.4749 | V27: =_xlfn.IFNA(VLOOKUP(B27,[2]베타!$A$2:$D$1000,4,FALSE),0) -> 0.4484 | W27: =_xlfn.IFNA(VLOOKUP(B27,[2]베타!$A$2:$E$1000,5,FALSE),0) -> 0.6857 | X27: =M27*Q27*U27 -> 0 | Y27: =M27*Q27*V27 -> 0 | Z27: =(P27*M27)-(X27+Y27) -> 0 | AA27: =IF(M27<0, P27-Q27, 0) -> 0 | AB27: =IF(M27>0, Q27*(1-0.2%)-P27, 0) -> 0 | AC27: =AA27/Q27*10000 -> 0 | AD27: =AB27/Q27*10000 -> 0 | AE27: =ABS(N27) -> 0 | AG27: =B27 -> 157500 | AH27: =-1*M27 -> 0 | AJ27: =ROUNDUP(VLOOKUP(B27,[2]베타!$A$2:$J$1000,10,FALSE),0) -> 6 | AK27: =ROUNDUP(VLOOKUP(B27,[2]베타!$A$2:$K$1000,11,FALSE),0) -> -27
B28: 228810 | C28: TIGER 미디어컨텐츠 | D28: =VLOOKUP("A"&B28,[2]ETF!$A$4:$M$10000,13,FALSE) -> 30000 | E28: =[1]!'228810:VOL'+0 -> 248847 | F28: 019875 | G28: =IF([1]!'019875^228810:SELL_TDY_QTY'="NO", 0, [1]!'019875^228810:SELL_TDY_QTY') -> 1581 | H28: =IF([1]!'019875^228810:SELL_TDY_AMT'="NO", 0, [1]!'019875^228810:SELL_TDY_AMT') -> 4974065 | I28: =IFERROR(H28/G28,0) -> 3146.1512 | J28: =IF([1]!'019875^228810:BUY_TDY_QTY'="NO", 0, [1]!'019875^228810:BUY_TDY_QTY') -> 1581 | K28: =IF([1]!'019875^228810:BUY_TDY_AMT'="NO", 0, [1]!'019875^228810:BUY_TDY_AMT') -> 4884480 | L28: =IFERROR(K28/J28,0) -> 3089.4877 | M28: =J28-G28 -> 0 | N28: =M28*P28 -> 0 | O28: =M28/D28 -> 0 | P28: =[1]!'228810:LAST' -> 3085 | Q28: =[1]!'228810:NAV' -> 3083.49 | R28: =(P28-I28)*-1*G28 -> 96680 | S28: =(P28-L28)*J28 -> -7095 | T28: =R28+S28 -> 89585 | U28: =_xlfn.IFNA(VLOOKUP(B28,[2]베타!$A$2:$C$1000,3,FALSE),0) -> -0.1774 | V28: =_xlfn.IFNA(VLOOKUP(B28,[2]베타!$A$2:$D$1000,4,FALSE),0) -> 0.6771 | W28: =_xlfn.IFNA(VLOOKUP(B28,[2]베타!$A$2:$E$1000,5,FALSE),0) -> 0.5807 | X28: =M28*Q28*U28 -> 0 | Y28: =M28*Q28*V28 -> 0 | Z28: =(P28*M28)-(X28+Y28) -> 0 | AA28: =IF(M28<0, P28-Q28, 0) -> 0 | AB28: =IF(M28>0, Q28*(1-0.2%)-P28, 0) -> 0 | AC28: =AA28/Q28*10000 -> 0 | AD28: =AB28/Q28*10000 -> 0 | AE28: =ABS(N28) -> 0 | AG28: =B28 -> 228810 | AH28: =-1*M28 -> 0 | AJ28: =ROUNDUP(VLOOKUP(B28,[2]베타!$A$2:$J$1000,10,FALSE),0) -> 20 | AK28: =ROUNDUP(VLOOKUP(B28,[2]베타!$A$2:$K$1000,11,FALSE),0) -> -29
B29: 472150 | C29: TIGER 배당커버드콜액티브 | D29: =VLOOKUP("A"&B29,[2]ETF!$A$4:$M$10000,13,FALSE) -> 10000 | E29: =[1]!'472150:VOL'+0 -> 5119230 | F29: 019870 | G29: =IF([1]!'019870^472150:SELL_TDY_QTY'="NO", 0, [1]!'019870^472150:SELL_TDY_QTY') -> 0 | H29: =IF([1]!'019870^472150:SELL_TDY_AMT'="NO", 0, [1]!'019870^472150:SELL_TDY_AMT') -> 0 | I29: =IFERROR(H29/G29,0) -> 0 | J29: =IF([1]!'019870^472150:BUY_TDY_QTY'="NO", 0, [1]!'019870^472150:BUY_TDY_QTY') -> 0 | K29: =IF([1]!'019870^472150:BUY_TDY_AMT'="NO", 0, [1]!'019870^472150:BUY_TDY_AMT') -> 0 | L29: =IFERROR(K29/J29,0) -> 0 | M29: =J29-G29 -> 0 | N29: =M29*P29 -> 0 | O29: =M29/D29 -> 0 | P29: =[1]!'472150:LAST' -> 20870 | Q29: =[1]!'472150:NAV' -> 20878.91 | R29: =(P29-I29)*-1*G29 -> 0 | S29: =(P29-L29)*J29 -> 0 | T29: =R29+S29 -> 0 | U29: =_xlfn.IFNA(VLOOKUP(B29,[2]베타!$A$2:$C$1000,3,FALSE),0) -> 0.9746 | V29: =_xlfn.IFNA(VLOOKUP(B29,[2]베타!$A$2:$D$1000,4,FALSE),0) -> 0.0007 | W29: =_xlfn.IFNA(VLOOKUP(B29,[2]베타!$A$2:$E$1000,5,FALSE),0) -> 0.989 | X29: =M29*Q29*U29 -> 0 | Y29: =M29*Q29*V29 -> 0 | Z29: =(P29*M29)-(X29+Y29) -> 0 | AA29: =IF(M29<0, P29-Q29, 0) -> 0 | AB29: =IF(M29>0, Q29*(1-0.2%)-P29, 0) -> 0 | AC29: =AA29/Q29*10000 -> 0 | AD29: =AB29/Q29*10000 -> 0 | AE29: =ABS(N29) -> 0 | AG29: =B29 -> 472150 | AH29: =-1*M29 -> 0 | AJ29: =ROUNDUP(VLOOKUP(B29,[2]베타!$A$2:$J$1000,10,FALSE),0) -> 14 | AK29: =ROUNDUP(VLOOKUP(B29,[2]베타!$A$2:$K$1000,11,FALSE),0) -> -24
B30: 307520 | C30: TIGER 지주회사 | D30: =VLOOKUP("A"&B30,[2]ETF!$A$4:$M$10000,13,FALSE) -> 50000 | E30: =[1]!'307520:VOL'+0 -> 309407 | F30: 019875 | G30: =IF([1]!'019875^307520:SELL_TDY_QTY'="NO", 0, [1]!'019875^307520:SELL_TDY_QTY') -> 2272 | H30: =IF([1]!'019875^307520:SELL_TDY_AMT'="NO", 0, [1]!'019875^307520:SELL_TDY_AMT') -> 50532220 | I30: =IFERROR(H30/G30,0) -> 22241.294 | J30: =IF([1]!'019875^307520:BUY_TDY_QTY'="NO", 0, [1]!'019875^307520:BUY_TDY_QTY') -> 2272 | K30: =IF([1]!'019875^307520:BUY_TDY_AMT'="NO", 0, [1]!'019875^307520:BUY_TDY_AMT') -> 50415940 | L30: =IFERROR(K30/J30,0) -> 22190.114 | M30: =J30-G30 -> 0 | N30: =M30*P30 -> 0 | O30: =M30/D30 -> 0 | P30: =[1]!'307520:LAST' -> 22270 | Q30: =[1]!'307520:NAV' -> 22314.38 | R30: =(P30-I30)*-1*G30 -> -65220 | S30: =(P30-L30)*J30 -> 181500 | T30: =R30+S30 -> 116280 | U30: =_xlfn.IFNA(VLOOKUP(B30,[2]베타!$A$2:$C$1000,3,FALSE),0) -> 0.3769 | V30: =_xlfn.IFNA(VLOOKUP(B30,[2]베타!$A$2:$D$1000,4,FALSE),0) -> 0.3911 | W30: =_xlfn.IFNA(VLOOKUP(B30,[2]베타!$A$2:$E$1000,5,FALSE),0) -> 0.7876 | X30: =M30*Q30*U30 -> 0 | Y30: =M30*Q30*V30 -> 0 | Z30: =(P30*M30)-(X30+Y30) -> 0 | AA30: =IF(M30<0, P30-Q30, 0) -> 0 | AB30: =IF(M30>0, Q30*(1-0.2%)-P30, 0) -> 0 | AC30: =AA30/Q30*10000 -> 0 | AD30: =AB30/Q30*10000 -> 0 | AE30: =ABS(N30) -> 0 | AG30: =B30 -> 307520 | AH30: =-1*M30 -> 0 | AJ30: =ROUNDUP(VLOOKUP(B30,[2]베타!$A$2:$J$1000,10,FALSE),0) -> 4 | AK30: =ROUNDUP(VLOOKUP(B30,[2]베타!$A$2:$K$1000,11,FALSE),0) -> -29
B31: 157490 | C31: TIGER 소프트웨어 | D31: =VLOOKUP("A"&B31,[2]ETF!$A$4:$M$10000,13,FALSE) -> 20000 | E31: =[1]!'157490:VOL'+0 -> 237161 | F31: 019875 | G31: =IF([1]!'019875^157490:SELL_TDY_QTY'="NO", 0, [1]!'019875^157490:SELL_TDY_QTY') -> 14240 | H31: =IF([1]!'019875^157490:SELL_TDY_AMT'="NO", 0, [1]!'019875^157490:SELL_TDY_AMT') -> 120171970 | I31: =IFERROR(H31/G31,0) -> 8439.0428 | J31: =IF([1]!'019875^157490:BUY_TDY_QTY'="NO", 0, [1]!'019875^157490:BUY_TDY_QTY') -> 14240 | K31: =IF([1]!'019875^157490:BUY_TDY_AMT'="NO", 0, [1]!'019875^157490:BUY_TDY_AMT') -> 120484280 | L31: =IFERROR(K31/J31,0) -> 8460.9747 | M31: =J31-G31 -> 0 | N31: =M31*P31 -> 0 | O31: =M31/D31 -> 0 | P31: =[1]!'157490:LAST' -> 8450 | Q31: =[1]!'157490:NAV' -> 8469.89 | R31: =(P31-I31)*-1*G31 -> -156030 | S31: =(P31-L31)*J31 -> -156280 | T31: =R31+S31 -> -312310 | U31: =_xlfn.IFNA(VLOOKUP(B31,[2]베타!$A$2:$C$1000,3,FALSE),0) -> 0.1899 | V31: =_xlfn.IFNA(VLOOKUP(B31,[2]베타!$A$2:$D$1000,4,FALSE),0) -> 0.3417 | W31: =_xlfn.IFNA(VLOOKUP(B31,[2]베타!$A$2:$E$1000,5,FALSE),0) -> 0.4479 | X31: =M31*Q31*U31 -> 0 | Y31: =M31*Q31*V31 -> 0 | Z31: =(P31*M31)-(X31+Y31) -> 0 | AA31: =IF(M31<0, P31-Q31, 0) -> 0 | AB31: =IF(M31>0, Q31*(1-0.2%)-P31, 0) -> 0 | AC31: =AA31/Q31*10000 -> 0 | AD31: =AB31/Q31*10000 -> 0 | AE31: =ABS(N31) -> 0 | AG31: =B31 -> 157490 | AH31: =-1*M31 -> 0 | AJ31: =ROUNDUP(VLOOKUP(B31,[2]베타!$A$2:$J$1000,10,FALSE),0) -> 10 | AK31: =ROUNDUP(VLOOKUP(B31,[2]베타!$A$2:$K$1000,11,FALSE),0) -> -30
B32: 471760 | C32: TIGER AI반도체핵심공정 | D32: =VLOOKUP("A"&B32,[2]ETF!$A$4:$M$10000,13,FALSE) -> 50000 | E32: =[1]!'471760:VOL'+0 -> 515361 | F32: 019875 | G32: =IF([1]!'019875^471760:SELL_TDY_QTY'="NO", 0, [1]!'019875^471760:SELL_TDY_QTY') -> 2906 | H32: =IF([1]!'019875^471760:SELL_TDY_AMT'="NO", 0, [1]!'019875^471760:SELL_TDY_AMT') -> 41162105 | I32: =IFERROR(H32/G32,0) -> 14164.523 | J32: =IF([1]!'019875^471760:BUY_TDY_QTY'="NO", 0, [1]!'019875^471760:BUY_TDY_QTY') -> 2906 | K32: =IF([1]!'019875^471760:BUY_TDY_AMT'="NO", 0, [1]!'019875^471760:BUY_TDY_AMT') -> 41628450 | L32: =IFERROR(K32/J32,0) -> 14325 | M32: =J32-G32 -> 0 | N32: =M32*P32 -> 0 | O32: =M32/D32 -> 0 | P32: =[1]!'471760:LAST' -> 14380 | Q32: =[1]!'471760:NAV' -> 14382.73 | R32: =(P32-I32)*-1*G32 -> -626175 | S32: =(P32-L32)*J32 -> 159830 | T32: =R32+S32 -> -466345 | U32: =_xlfn.IFNA(VLOOKUP(B32,[2]베타!$A$2:$C$1000,3,FALSE),0) -> 0.5011 | V32: =_xlfn.IFNA(VLOOKUP(B32,[2]베타!$A$2:$D$1000,4,FALSE),0) -> 0.808 | W32: =_xlfn.IFNA(VLOOKUP(B32,[2]베타!$A$2:$E$1000,5,FALSE),0) -> 0.8164 | X32: =M32*Q32*U32 -> 0 | Y32: =M32*Q32*V32 -> 0 | Z32: =(P32*M32)-(X32+Y32) -> 0 | AA32: =IF(M32<0, P32-Q32, 0) -> 0 | AB32: =IF(M32>0, Q32*(1-0.2%)-P32, 0) -> 0 | AC32: =AA32/Q32*10000 -> 0 | AD32: =AB32/Q32*10000 -> 0 | AE32: =ABS(N32) -> 0 | AG32: =B32 -> 471760 | AH32: =-1*M32 -> 0 | AJ32: =ROUNDUP(VLOOKUP(B32,[2]베타!$A$2:$J$1000,10,FALSE),0) -> 6 | AK32: =ROUNDUP(VLOOKUP(B32,[2]베타!$A$2:$K$1000,11,FALSE),0) -> -29
B33: 0052D0 | C33: TIGER 코리아배당다우존스 | D33: =VLOOKUP("A"&B33,[2]ETF!$A$4:$M$10000,13,FALSE) -> 50000 | E33: =[1]!'0052D0:VOL'+0 -> 89425 | F33: 019875 | G33: =IF([1]!'019875^0052D0:SELL_TDY_QTY'="NO", 0, [1]!'019875^0052D0:SELL_TDY_QTY') -> 7372 | H33: =IF([1]!'019875^0052D0:SELL_TDY_AMT'="NO", 0, [1]!'019875^0052D0:SELL_TDY_AMT') -> 113898630 | I33: =IFERROR(H33/G33,0) -> 15450.167 | J33: =IF([1]!'019875^0052D0:BUY_TDY_QTY'="NO", 0, [1]!'019875^0052D0:BUY_TDY_QTY') -> 7372 | K33: =IF([1]!'019875^0052D0:BUY_TDY_AMT'="NO", 0, [1]!'019875^0052D0:BUY_TDY_AMT') -> 114571655 | L33: =IFERROR(K33/J33,0) -> 15541.462 | M33: =J33-G33 -> 0 | N33: =M33*P33 -> 0 | O33: =M33/D33 -> 0 | P33: =[1]!'0052D0:LAST' -> 15450 | Q33: =[1]!'0052D0:NAV' -> 15454.61 | R33: =(P33-I33)*-1*G33 -> 1230 | S33: =(P33-L33)*J33 -> -674255 | T33: =R33+S33 -> -673025 | U33: =_xlfn.IFNA(VLOOKUP(B33,[2]베타!$A$2:$C$1000,3,FALSE),0) -> 0.1078 | V33: =_xlfn.IFNA(VLOOKUP(B33,[2]베타!$A$2:$D$1000,4,FALSE),0) -> 0.2999 | W33: =_xlfn.IFNA(VLOOKUP(B33,[2]베타!$A$2:$E$1000,5,FALSE),0) -> 0.5164 | X33: =M33*Q33*U33 -> 0 | Y33: =M33*Q33*V33 -> 0 | Z33: =(P33*M33)-(X33+Y33) -> 0 | AA33: =IF(M33<0, P33-Q33, 0) -> 0 | AB33: =IF(M33>0, Q33*(1-0.2%)-P33, 0) -> 0 | AC33: =AA33/Q33*10000 -> 0 | AD33: =AB33/Q33*10000 -> 0 | AE33: =ABS(N33) -> 0 | AG33: =B33 -> 0052D0 | AH33: =-1*M33 -> 0 | AJ33: =ROUNDUP(VLOOKUP(B33,[2]베타!$A$2:$J$1000,10,FALSE),0) -> 5 | AK33: =ROUNDUP(VLOOKUP(B33,[2]베타!$A$2:$K$1000,11,FALSE),0) -> -22
B34: 466940 | C34: TIGER 은행고배당플러스TOP10 | D34: =VLOOKUP("A"&B34,[2]ETF!$A$4:$M$10000,13,FALSE) -> 50000 | E34: =[1]!'466940:VOL'+0 -> 546166 | F34: 019875 | G34: =IF([1]!'019875^466940:SELL_TDY_QTY'="NO", 0, [1]!'019875^466940:SELL_TDY_QTY') -> 17107 | H34: =IF([1]!'019875^466940:SELL_TDY_AMT'="NO", 0, [1]!'019875^466940:SELL_TDY_AMT') -> 449417525 | I34: =IFERROR(H34/G34,0) -> 26270.972 | J34: =IF([1]!'019875^466940:BUY_TDY_QTY'="NO", 0, [1]!'019875^466940:BUY_TDY_QTY') -> 17107 | K34: =IF([1]!'019875^466940:BUY_TDY_AMT'="NO", 0, [1]!'019875^466940:BUY_TDY_AMT') -> 451760475 | L34: =IFERROR(K34/J34,0) -> 26407.931 | M34: =J34-G34 -> 0 | N34: =M34*P34 -> 0 | O34: =M34/D34 -> 0 | P34: =[1]!'466940:LAST' -> 26320 | Q34: =[1]!'466940:NAV' -> 26332.64 | R34: =(P34-I34)*-1*G34 -> -838715 | S34: =(P34-L34)*J34 -> -1504235 | T34: =R34+S34 -> -2342950 | U34: =_xlfn.IFNA(VLOOKUP(B34,[2]베타!$A$2:$C$1000,3,FALSE),0) -> 0.1136 | V34: =_xlfn.IFNA(VLOOKUP(B34,[2]베타!$A$2:$D$1000,4,FALSE),0) -> 0.2359 | W34: =_xlfn.IFNA(VLOOKUP(B34,[2]베타!$A$2:$E$1000,5,FALSE),0) -> 0.3722 | X34: =M34*Q34*U34 -> 0 | Y34: =M34*Q34*V34 -> 0 | Z34: =(P34*M34)-(X34+Y34) -> 0 | AA34: =IF(M34<0, P34-Q34, 0) -> 0 | AB34: =IF(M34>0, Q34*(1-0.2%)-P34, 0) -> 0 | AC34: =AA34/Q34*10000 -> 0 | AD34: =AB34/Q34*10000 -> 0 | AE34: =ABS(N34) -> 0 | AG34: =B34 -> 466940 | AH34: =-1*M34 -> 0 | AJ34: =ROUNDUP(VLOOKUP(B34,[2]베타!$A$2:$J$1000,10,FALSE),0) -> 3 | AK34: =ROUNDUP(VLOOKUP(B34,[2]베타!$A$2:$K$1000,11,FALSE),0) -> -21
B35: 139220 | C35: TIGER 200 건설 | D35: =VLOOKUP("A"&B35,[2]ETF!$A$4:$M$10000,13,FALSE) -> 20000 | E35: =[1]!'139220:VOL'+0 -> 697787 | F35: 019875 | G35: =IF([1]!'019875^139220:SELL_TDY_QTY'="NO", 0, [1]!'019875^139220:SELL_TDY_QTY') -> 4596 | H35: =IF([1]!'019875^139220:SELL_TDY_AMT'="NO", 0, [1]!'019875^139220:SELL_TDY_AMT') -> 37897305 | I35: =IFERROR(H35/G35,0) -> 8245.7148 | J35: =IF([1]!'019875^139220:BUY_TDY_QTY'="NO", 0, [1]!'019875^139220:BUY_TDY_QTY') -> 4596 | K35: =IF([1]!'019875^139220:BUY_TDY_AMT'="NO", 0, [1]!'019875^139220:BUY_TDY_AMT') -> 37112700 | L35: =IFERROR(K35/J35,0) -> 8075 | M35: =J35-G35 -> 0 | N35: =M35*P35 -> 0 | O35: =M35/D35 -> 0 | P35: =[1]!'139220:LAST' -> 8100 | Q35: =[1]!'139220:NAV' -> 8100.1 | R35: =(P35-I35)*-1*G35 -> 669705 | S35: =(P35-L35)*J35 -> 114900 | T35: =R35+S35 -> 784605 | U35: =_xlfn.IFNA(VLOOKUP(B35,[2]베타!$A$2:$C$1000,3,FALSE),0) -> 0.4294 | V35: =_xlfn.IFNA(VLOOKUP(B35,[2]베타!$A$2:$D$1000,4,FALSE),0) -> 0.5138 | W35: =_xlfn.IFNA(VLOOKUP(B35,[2]베타!$A$2:$E$1000,5,FALSE),0) -> 0.6631 | X35: =M35*Q35*U35 -> 0 | Y35: =M35*Q35*V35 -> 0 | Z35: =(P35*M35)-(X35+Y35) -> 0 | AA35: =IF(M35<0, P35-Q35, 0) -> 0 | AB35: =IF(M35>0, Q35*(1-0.2%)-P35, 0) -> 0 | AC35: =AA35/Q35*10000 -> 0 | AD35: =AB35/Q35*10000 -> 0 | AE35: =ABS(N35) -> 0 | AG35: =B35 -> 139220 | AH35: =-1*M35 -> 0 | AJ35: =ROUNDUP(VLOOKUP(B35,[2]베타!$A$2:$J$1000,10,FALSE),0) -> 9 | AK35: =ROUNDUP(VLOOKUP(B35,[2]베타!$A$2:$K$1000,11,FALSE),0) -> -30
B36: 365000 | C36: TIGER 인터넷TOP10 | D36: =VLOOKUP("A"&B36,[2]ETF!$A$4:$M$10000,13,FALSE) -> 50000 | E36: =[1]!'365000:VOL'+0 -> 60413 | F36: 019875 | G36: =IF([1]!'019875^365000:SELL_TDY_QTY'="NO", 0, [1]!'019875^365000:SELL_TDY_QTY') -> 963 | H36: =IF([1]!'019875^365000:SELL_TDY_AMT'="NO", 0, [1]!'019875^365000:SELL_TDY_AMT') -> 3577650 | I36: =IFERROR(H36/G36,0) -> 3715.109 | J36: =IF([1]!'019875^365000:BUY_TDY_QTY'="NO", 0, [1]!'019875^365000:BUY_TDY_QTY') -> 963 | K36: =IF([1]!'019875^365000:BUY_TDY_AMT'="NO", 0, [1]!'019875^365000:BUY_TDY_AMT') -> 3572730 | L36: =IFERROR(K36/J36,0) -> 3710 | M36: =J36-G36 -> 0 | N36: =M36*P36 -> 0 | O36: =M36/D36 -> 0 | P36: =[1]!'365000:LAST' -> 3725 | Q36: =[1]!'365000:NAV' -> 3720.56 | R36: =(P36-I36)*-1*G36 -> -9525 | S36: =(P36-L36)*J36 -> 14445 | T36: =R36+S36 -> 4920 | U36: =_xlfn.IFNA(VLOOKUP(B36,[2]베타!$A$2:$C$1000,3,FALSE),0) -> 0.0897 | V36: =_xlfn.IFNA(VLOOKUP(B36,[2]베타!$A$2:$D$1000,4,FALSE),0) -> 0.4693 | W36: =_xlfn.IFNA(VLOOKUP(B36,[2]베타!$A$2:$E$1000,5,FALSE),0) -> 0.5899 | X36: =M36*Q36*U36 -> 0 | Y36: =M36*Q36*V36 -> 0 | Z36: =(P36*M36)-(X36+Y36) -> 0 | AA36: =IF(M36<0, P36-Q36, 0) -> 0 | AB36: =IF(M36>0, Q36*(1-0.2%)-P36, 0) -> 0 | AC36: =AA36/Q36*10000 -> 0 | AD36: =AB36/Q36*10000 -> 0 | AE36: =ABS(N36) -> 0 | AG36: =B36 -> 365000 | AH36: =-1*M36 -> 0 | AJ36: =ROUNDUP(VLOOKUP(B36,[2]베타!$A$2:$J$1000,10,FALSE),0) -> 13 | AK36: =ROUNDUP(VLOOKUP(B36,[2]베타!$A$2:$K$1000,11,FALSE),0) -> -33
B37: 228800 | C37: TIGER 여행레저 | D37: =VLOOKUP("A"&B37,[2]ETF!$A$4:$M$10000,13,FALSE) -> 30000 | E37: =[1]!'228800:VOL'+0 -> 156774 | F37: 019875 | G37: =IF([1]!'019875^228800:SELL_TDY_QTY'="NO", 0, [1]!'019875^228800:SELL_TDY_QTY') -> 3520 | H37: =IF([1]!'019875^228800:SELL_TDY_AMT'="NO", 0, [1]!'019875^228800:SELL_TDY_AMT') -> 9441350 | I37: =IFERROR(H37/G37,0) -> 2682.2017 | J37: =IF([1]!'019875^228800:BUY_TDY_QTY'="NO", 0, [1]!'019875^228800:BUY_TDY_QTY') -> 3520 | K37: =IF([1]!'019875^228800:BUY_TDY_AMT'="NO", 0, [1]!'019875^228800:BUY_TDY_AMT') -> 9416030 | L37: =IFERROR(K37/J37,0) -> 2675.0085 | M37: =J37-G37 -> 0 | N37: =M37*P37 -> 0 | O37: =M37/D37 -> 0 | P37: =[1]!'228800:LAST' -> 2675 | Q37: =[1]!'228800:NAV' -> 2674.94 | R37: =(P37-I37)*-1*G37 -> 25350 | S37: =(P37-L37)*J37 -> -30 | T37: =R37+S37 -> 25320 | U37: =_xlfn.IFNA(VLOOKUP(B37,[2]베타!$A$2:$C$1000,3,FALSE),0) -> 0.0029 | V37: =_xlfn.IFNA(VLOOKUP(B37,[2]베타!$A$2:$D$1000,4,FALSE),0) -> 0.3796 | W37: =_xlfn.IFNA(VLOOKUP(B37,[2]베타!$A$2:$E$1000,5,FALSE),0) -> 0.405 | X37: =M37*Q37*U37 -> 0 | Y37: =M37*Q37*V37 -> 0 | Z37: =(P37*M37)-(X37+Y37) -> 0 | AA37: =IF(M37<0, P37-Q37, 0) -> 0 | AB37: =IF(M37>0, Q37*(1-0.2%)-P37, 0) -> 0 | AC37: =AA37/Q37*10000 -> 0 | AD37: =AB37/Q37*10000 -> 0 | AE37: =ABS(N37) -> 0 | AG37: =B37 -> 228800 | AH37: =-1*M37 -> 0 | AJ37: =ROUNDUP(VLOOKUP(B37,[2]베타!$A$2:$J$1000,10,FALSE),0) -> 16 | AK37: =ROUNDUP(VLOOKUP(B37,[2]베타!$A$2:$K$1000,11,FALSE),0) -> -30
B38: 138540 | C38: TIGER 현대차그룹플러스 | D38: =VLOOKUP("A"&B38,[2]ETF!$A$4:$M$10000,13,FALSE) -> 20000 | E38: =[1]!'138540:VOL'+0 -> 112884 | F38: 019875 | G38: =IF([1]!'019875^138540:SELL_TDY_QTY'="NO", 0, [1]!'019875^138540:SELL_TDY_QTY') -> 920 | H38: =IF([1]!'019875^138540:SELL_TDY_AMT'="NO", 0, [1]!'019875^138540:SELL_TDY_AMT') -> 47601105 | I38: =IFERROR(H38/G38,0) -> 51740.332 | J38: =IF([1]!'019875^138540:BUY_TDY_QTY'="NO", 0, [1]!'019875^138540:BUY_TDY_QTY') -> 920 | K38: =IF([1]!'019875^138540:BUY_TDY_AMT'="NO", 0, [1]!'019875^138540:BUY_TDY_AMT') -> 47076585 | L38: =IFERROR(K38/J38,0) -> 51170.201 | M38: =J38-G38 -> 0 | N38: =M38*P38 -> 0 | O38: =M38/D38 -> 0 | P38: =[1]!'138540:LAST' -> 51065 | Q38: =[1]!'138540:NAV' -> 51059.74 | R38: =(P38-I38)*-1*G38 -> 621305 | S38: =(P38-L38)*J38 -> -96785 | T38: =R38+S38 -> 524520 | U38: =_xlfn.IFNA(VLOOKUP(B38,[2]베타!$A$2:$C$1000,3,FALSE),0) -> 0.3866 | V38: =_xlfn.IFNA(VLOOKUP(B38,[2]베타!$A$2:$D$1000,4,FALSE),0) -> 0.3391 | W38: =_xlfn.IFNA(VLOOKUP(B38,[2]베타!$A$2:$E$1000,5,FALSE),0) -> 0.6046 | X38: =M38*Q38*U38 -> 0 | Y38: =M38*Q38*V38 -> 0 | Z38: =(P38*M38)-(X38+Y38) -> 0 | AA38: =IF(M38<0, P38-Q38, 0) -> 0 | AB38: =IF(M38>0, Q38*(1-0.2%)-P38, 0) -> 0 | AC38: =AA38/Q38*10000 -> 0 | AD38: =AB38/Q38*10000 -> 0 | AG38: =B38 -> 138540 | AH38: =-1*M38 -> 0 | AJ38: =ROUNDUP(VLOOKUP(B38,[2]베타!$A$2:$J$1000,10,FALSE),0) -> 5 | AK38: =ROUNDUP(VLOOKUP(B38,[2]베타!$A$2:$K$1000,11,FALSE),0) -> -22
B39: 377990 | C39: TIGER Fn신재생에너지 | D39: =VLOOKUP("A"&B39,[2]ETF!$A$4:$M$10000,13,FALSE) -> 50000 | E39: =[1]!'377990:VOL'+0 -> 152242 | F39: 019875 | G39: =IF([1]!'019875^377990:SELL_TDY_QTY'="NO", 0, [1]!'019875^377990:SELL_TDY_QTY') -> 1000 | H39: =IF([1]!'019875^377990:SELL_TDY_AMT'="NO", 0, [1]!'019875^377990:SELL_TDY_AMT') -> 25740000 | I39: =IFERROR(H39/G39,0) -> 25740 | J39: =IF([1]!'019875^377990:BUY_TDY_QTY'="NO", 0, [1]!'019875^377990:BUY_TDY_QTY') -> 1000 | K39: =IF([1]!'019875^377990:BUY_TDY_AMT'="NO", 0, [1]!'019875^377990:BUY_TDY_AMT') -> 25355000 | L39: =IFERROR(K39/J39,0) -> 25355 | M39: =J39-G39 -> 0 | N39: =M39*P39 -> 0 | O39: =M39/D39 -> 0 | P39: =[1]!'377990:LAST' -> 25820 | Q39: =[1]!'377990:NAV' -> 25889.9 | R39: =(P39-I39)*-1*G39 -> -80000 | S39: =(P39-L39)*J39 -> 465000 | T39: =R39+S39 -> 385000 | U39: =_xlfn.IFNA(VLOOKUP(B39,[2]베타!$A$2:$C$1000,3,FALSE),0) -> 0.1999 | V39: =_xlfn.IFNA(VLOOKUP(B39,[2]베타!$A$2:$D$1000,4,FALSE),0) -> 0.8172 | W39: =_xlfn.IFNA(VLOOKUP(B39,[2]베타!$A$2:$E$1000,5,FALSE),0) -> 0.6897 | X39: =M39*Q39*U39 -> 0 | Y39: =M39*Q39*V39 -> 0 | Z39: =(P39*M39)-(X39+Y39) -> 0 | AA39: =IF(M39<0, P39-Q39, 0) -> 0 | AB39: =IF(M39>0, Q39*(1-0.2%)-P39, 0) -> 0 | AC39: =AA39/Q39*10000 -> 0 | AD39: =AB39/Q39*10000 -> 0 | AE39: =ABS(N39) -> 0 | AG39: =B39 -> 377990 | AH39: =-1*M39 -> 0 | AJ39: =ROUNDUP(VLOOKUP(B39,[2]베타!$A$2:$J$1000,10,FALSE),0) -> 8 | AK39: =ROUNDUP(VLOOKUP(B39,[2]베타!$A$2:$K$1000,11,FALSE),0) -> -28
B40: 395270 | C40: HANARO Fn K-반도체 | D40: =VLOOKUP("A"&B40,[2]ETF!$A$4:$M$10000,13,FALSE) -> 50000 | E40: =[1]!'395270:VOL'+0 -> 704590 | F40: 019875 | G40: =IF([1]!'019875^395270:SELL_TDY_QTY'="NO", 0, [1]!'019875^395270:SELL_TDY_QTY') -> 8425 | H40: =IF([1]!'019875^395270:SELL_TDY_AMT'="NO", 0, [1]!'019875^395270:SELL_TDY_AMT') -> 471563425 | I40: =IFERROR(H40/G40,0) -> 55971.92 | J40: =IF([1]!'019875^395270:BUY_TDY_QTY'="NO", 0, [1]!'019875^395270:BUY_TDY_QTY') -> 8425 | K40: =IF([1]!'019875^395270:BUY_TDY_AMT'="NO", 0, [1]!'019875^395270:BUY_TDY_AMT') -> 474731085 | L40: =IFERROR(K40/J40,0) -> 56347.903 | M40: =J40-G40 -> 0 | N40: =M40*P40 -> 0 | O40: =M40/D40 -> 0 | P40: =[1]!'395270:LAST' -> 56200 | Q40: =[1]!'395270:NAV' -> 56261.59 | R40: =(P40-I40)*-1*G40 -> -1921575 | S40: =(P40-L40)*J40 -> -1246085 | T40: =R40+S40 -> -3167660 | U40: =_xlfn.IFNA(VLOOKUP(B40,[2]베타!$A$2:$C$1000,3,FALSE),0) -> 1.171 | V40: =_xlfn.IFNA(VLOOKUP(B40,[2]베타!$A$2:$D$1000,4,FALSE),0) -> 0.0911 | W40: =_xlfn.IFNA(VLOOKUP(B40,[2]베타!$A$2:$E$1000,5,FALSE),0) -> 0.9176 | X40: =M40*Q40*U40 -> 0 | Y40: =M40*Q40*V40 -> 0 | Z40: =(P40*M40)-(X40+Y40) -> 0 | AA40: =IF(M40<0, P40-Q40, 0) -> 0 | AB40: =IF(M40>0, Q40*(1-0.2%)-P40, 0) -> 0 | AC40: =AA40/Q40*10000 -> 0 | AD40: =AB40/Q40*10000 -> 0 | AE40: =ABS(N40) -> 0 | AG40: =B40 -> 395270 | AH40: =-1*M40 -> 0 | AJ40: =ROUNDUP(VLOOKUP(B40,[2]베타!$A$2:$J$1000,10,FALSE),0) -> 2 | AK40: =ROUNDUP(VLOOKUP(B40,[2]베타!$A$2:$K$1000,11,FALSE),0) -> -23
B41: 091220 | C41: TIGER 은행 | D41: =VLOOKUP("A"&B41,[2]ETF!$A$4:$M$10000,13,FALSE) -> 20000 | E41: =[1]!'091220:VOL'+0 -> 22990 | F41: 019875 | G41: =IF([1]!'019875^091220:SELL_TDY_QTY'="NO", 0, [1]!'019875^091220:SELL_TDY_QTY') -> 10 | H41: =IF([1]!'019875^091220:SELL_TDY_AMT'="NO", 0, [1]!'019875^091220:SELL_TDY_AMT') -> 166750 | I41: =IFERROR(H41/G41,0) -> 16675 | J41: =IF([1]!'019875^091220:BUY_TDY_QTY'="NO", 0, [1]!'019875^091220:BUY_TDY_QTY') -> 10 | K41: =IF([1]!'019875^091220:BUY_TDY_AMT'="NO", 0, [1]!'019875^091220:BUY_TDY_AMT') -> 168350 | L41: =IFERROR(K41/J41,0) -> 16835 | M41: =J41-G41 -> 0 | N41: =M41*P41 -> 0 | O41: =M41/D41 -> 0 | P41: =[1]!'091220:LAST' -> 16710 | Q41: =[1]!'091220:NAV' -> 16734.95 | R41: =(P41-I41)*-1*G41 -> -350 | S41: =(P41-L41)*J41 -> -1250 | T41: =R41+S41 -> -1600 | U41: =_xlfn.IFNA(VLOOKUP(B41,[2]베타!$A$2:$C$1000,3,FALSE),0) -> 0.0584 | V41: =_xlfn.IFNA(VLOOKUP(B41,[2]베타!$A$2:$D$1000,4,FALSE),0) -> 0.2659 | W41: =_xlfn.IFNA(VLOOKUP(B41,[2]베타!$A$2:$E$1000,5,FALSE),0) -> 0.2943 | X41: =M41*Q41*U41 -> 0 | Y41: =M41*Q41*V41 -> 0 | Z41: =(P41*M41)-(X41+Y41) -> 0 | AA41: =IF(M41<0, P41-Q41, 0) -> 0 | AB41: =IF(M41>0, Q41*(1-0.2%)-P41, 0) -> 0 | AC41: =AA41/Q41*10000 -> 0 | AD41: =AB41/Q41*10000 -> 0 | AE41: =ABS(N41) -> 0 | AG41: =B41 -> 091220 | AH41: =-1*M41 -> 0 | AJ41: =ROUNDUP(VLOOKUP(B41,[2]베타!$A$2:$J$1000,10,FALSE),0) -> 7 | AK41: =ROUNDUP(VLOOKUP(B41,[2]베타!$A$2:$K$1000,11,FALSE),0) -> -29
B42: 261070 | C42: TIGER 코스닥150바이오테크 | D42: =VLOOKUP("A"&B42,[2]ETF!$A$4:$M$10000,13,FALSE) -> 20000 | E42: =[1]!'261070:VOL'+0 -> 128747 | F42: 019875 | G42: =IF([1]!'019875^261070:SELL_TDY_QTY'="NO", 0, [1]!'019875^261070:SELL_TDY_QTY') -> 58 | H42: =IF([1]!'019875^261070:SELL_TDY_AMT'="NO", 0, [1]!'019875^261070:SELL_TDY_AMT') -> 758930 | I42: =IFERROR(H42/G42,0) -> 13085 | J42: =IF([1]!'019875^261070:BUY_TDY_QTY'="NO", 0, [1]!'019875^261070:BUY_TDY_QTY') -> 58 | K42: =IF([1]!'019875^261070:BUY_TDY_AMT'="NO", 0, [1]!'019875^261070:BUY_TDY_AMT') -> 758930 | L42: =IFERROR(K42/J42,0) -> 13085 | M42: =J42-G42 -> 0 | N42: =M42*P42 -> 0 | O42: =M42/D42 -> 0 | P42: =[1]!'261070:LAST'+0 -> 13085 | Q42: =[1]!'261070:NAV'+0 -> 13096.78 | R42: =(P42-I42)*-1*G42 -> 0 | S42: =(P42-L42)*J42 -> 0 | T42: =R42+S42 -> 0 | U42: =_xlfn.IFNA(VLOOKUP(B42,[2]베타!$A$2:$C$1000,3,FALSE),0) -> -0.2537 | V42: =_xlfn.IFNA(VLOOKUP(B42,[2]베타!$A$2:$D$1000,4,FALSE),0) -> 1.071 | W42: =_xlfn.IFNA(VLOOKUP(B42,[2]베타!$A$2:$E$1000,5,FALSE),0) -> 0.7505 | X42: =M42*Q42*U42 -> 0 | Y42: =M42*Q42*V42 -> 0 | Z42: =(P42*M42)-(X42+Y42) -> 0 | AA42: =IF(M42<0, P42-Q42, 0) -> 0 | AB42: =IF(M42>0, Q42*(1-0.2%)-P42, 0) -> 0 | AC42: =AA42/Q42*10000 -> 0 | AD42: =AB42/Q42*10000 -> 0 | AG42: =B42 -> 261070 | AH42: =-1*M42 -> 0 | AJ42: =ROUNDUP(VLOOKUP(B42,[2]베타!$A$2:$J$1000,10,FALSE),0) -> 8 | AK42: =ROUNDUP(VLOOKUP(B42,[2]베타!$A$2:$K$1000,11,FALSE),0) -> -33
...

Sheet Sheet2
R1: 1
P2: 0 | Q2: 0 | R2: 0
J3: ABS 포지션 | K3: 0 | O3: 상품 | P3: ETF 델타 | Q3: 선물 델타 | R3: NET 델타 | S3: 계약수 환산 | T3: 필요 계약수 | U3: 당일 손익 | V3: NET
J4: 매도 포지션 | K4: 0 | N4: #DIV/0! | O4: KOSPI 200 | P4: 0 | Q4: 0 | R4: 0 | S4: 0 | T4: 0 | U4: -11835291 | V4: 바스켓
J5: 매수 포재션 | K5: 0 | N5: #DIV/0! | O5: KOSDAQ 150 | P5: 0 | Q5: 0 | R5: 0 | S5: 0 | T5: 0 | V5: 현금
B7: 종목코드 | C7: 종목명 | D7: 1CU | E7: 시장 거래량 | F7: 펀드코드 | G7: 당일매도수량 | H7: 당일매도금액 | I7: 매도단가 | J7: 당일매수수량 | K7: 당일매수금액 | L7: 매수단가 | M7: NET 포지션 수량 | N7: NET 포지션 금액 | O7: CU 비중 | P7: 현재가 | Q7: 매도 손익 | R7: 매수 손익 | S7: 당일 손익 | T7: 1계약 델타 | U7: 전체 잔고 수량
B9: - | C9: - | D9: - | E9: - | F9: - | G9: 74 | H9: 1592640000 | I9: - | J9: 74 | K9: 1590088000 | L9: - | M9: 0 | N9: 0 | O9: - | P9: - | Q9: -2893000 | R9: 5445000 | S9: 2552000 | T9: 68977000 | U9: 0
B10: A0569 | C10: 미니 코스피 200 선물 | D10: 0 | E10: - | F10: 028875 | G10: 13 | H10: 711099000 | I10: 1093.9985 | J10: 13 | K10: 706016000 | L10: 1086.1785 | M10: 0 | N10: 0 | O10: - | P10: 1088.36 | Q10: 3665000 | R10: 1418000 | S10: 5083000 | T10: 54418000 | U10: 0
B11: A0669 | C11: 코스닥 150 선물 | D11: 0 | E11: - | F11: 028875 | G11: 61 | H11: 881541000 | I11: 1445.1492 | J11: 61 | K11: 884072000 | L11: 1449.2984 | M11: 0 | N11: 0 | O11: - | P11: 1455.9 | Q11: -6558000 | R11: 4027000 | S11: -2531000 | T11: 14559000 | U11: 0
G12: =@IF(@KBMonitor|DATA!'019875^091220:SELL_TDY_QTY'="NO", 0, KBMonitor|DATA!'019875^091220:SELL_TDY_QTY') | N12: 0 | T12: * 200과 150은 전일종가(금액)으로 계산 | AA12: 유리 여부
B13: 종목코드 | C13: 종목명 | D13: 1CU | E13: 시장 거래량 | F13: 펀드코드 | G13: 당일매도수량 | H13: 당일매도금액 | I13: 매도단가 | J13: 당일매수수량 | K13: 당일매수금액 | L13: 매수단가 | M13: NET 포지션 수량 | N13: NET 포지션 금액 | O13: CU 비중 | P13: 현재가 | Q13: NAV | R13: 매도 손익 | S13: 매수 손익 | T13: 당일 손익 | U13: KS 베타 | V13: KQ 베타 | W13: R-Squared | X13: W.KOSPI200 | Y13: W.KOSDAQ150 | Z13: W.200&150 외 | AA13: 매도 손익 (nav 대비) | AB13: 매수 손익 (nav 대비) | AC13: 매도 손익 (nav 대비) | AD13: 매수 손익 (nav 대비) | AE13: 포지션 abs
B14: - | C14: - | D14: - | E14: - | F14: - | G14: 381774 | H14: 5113049433 | I14: - | J14: 381774 | K14: 5127436724 | L14: - | M14: 0 | N14: 0 | O14: - | P14: - | R14: -30619682 | S14: 16232391 | T14: -14387291 | U14: 0.26038158 | V14: 0.48707105 | W14: 0.63083158 | X14: 0 | Y14: 0 | Z14: 0 | AA14: 0 | AB14: 0 | AC14: 0 | AD14: 0 | AE14: 0 | AJ14: 매도 bp | AK14: 매수 bp
B15: 396500 | C15: TIGER 반도체TOP10 | D15: 50000 | E15: 10068511 | F15: 019875 | G15: 4995 | H15: 178173125 | I15: 35670.295 | J15: 4995 | K15: 179881495 | L15: 36012.311 | M15: 0 | N15: 0 | O15: 0 | P15: 35840 | Q15: 35862.12 | R15: -847675 | S15: -860695 | T15: -1708370 | U15: 1.1067 | V15: 0.1884 | W15: 0.928 | X15: 0 | Y15: 0 | Z15: 0 | AA15: 0 | AB15: 0 | AC15: 0 | AD15: 0 | AE15: 0 | AG15: 396500 | AH15: 0 | AJ15: -2 | AK15: -19
B16: 228790 | C16: TIGER 화장품 | D16: 30000 | E16: 6940013 | F16: 019875 | G16: 101422 | H16: 480830847 | I16: 4740.893 | J16: 101422 | K16: 479329965 | L16: 4726.0946 | M16: 0 | N16: 0 | O16: 0 | P16: 4740 | Q16: 4734.94 | R16: 90567 | S16: 1410315 | T16: 1500882 | U16: -0.1759 | V16: 0.5739 | W16: 0.4315 | X16: 0 | Y16: 0 | Z16: 0 | AA16: 0 | AB16: 0 | AC16: 0 | AD16: 0 | AE16: 0 | AG16: 228790 | AH16: 0 | AJ16: 8 | AK16: -30
B17: 462010 | C17: TIGER 2차전지소재Fn | D17: 50000 | E17: 5603384 | F17: 019875 | G17: 26269 | H17: 132269795 | I17: 5035.2048 | J17: 26269 | K17: 131250250 | L17: 4996.3931 | M17: 0 | N17: 0 | O17: 0 | P17: 5080 | Q17: 5083.16 | R17: -1176725 | S17: 2196270 | T17: 1019545 | U17: 0.0571 | V17: 0.866 | W17: 0.69 | X17: 0 | Y17: 0 | Z17: 0 | AA17: 0 | AB17: 0 | AC17: 0 | AD17: 0 | AE17: 0 | AG17: 462010 | AH17: 0 | AJ17: 9 | AK17: -26
B18: 364980 | C18: TIGER 2차전지TOP10 | D18: 50000 | E18: 3632976 | F18: 019875 | G18: 51023 | H18: 538393491 | I18: 10551.976 | J18: 51023 | K18: 539525575 | L18: 10574.164 | M18: 0 | N18: 0 | O18: 0 | P18: 10645 | Q18: 10668.09 | R18: -4746344 | S18: 3614260 | T18: -1132084 | U18: 0.0798 | V18: 0.7019 | W18: 0.5663 | X18: 0 | Y18: 0 | Z18: 0 | AA18: 0 | AB18: 0 | AC18: 0 | AD18: 0 | AE18: 0 | AG18: 364980 | AH18: 0 | AJ18: 6 | AK18: -26
B19: 0117V0 | C19: TIGER 코리아AI전력기기TOP3플러스 | D19: 50000 | E19: 3420066 | F19: 019875 | G19: 35981 | H19: 690841280 | I19: 19200.169 | J19: 35981 | K19: 698177099 | L19: 19404.049 | M19: 0 | N19: 0 | O19: 0 | P19: 19705 | Q19: 19726.64 | R19: -18164325 | S19: 10828506 | T19: -7335819 | U19: 0.4329 | V19: 0.6516 | W19: 0.6751 | X19: 0 | Y19: 0 | Z19: 0 | AA19: 0 | AB19: 0 | AC19: 0 | AD19: 0 | AE19: 0 | AG19: 0117V0 | AH19: 0 | AJ19: 5 | AK19: -25
B20: 305540 | C20: TIGER 2차전지테마 | D20: 50000 | E20: 613423 | F20: 019875 | G20: 20535 | H20: 388285730 | I20: 18908.485 | J20: 20535 | K20: 386277850 | L20: 18810.706 | M20: 0 | N20: 0 | O20: 0 | P20: 19050 | Q20: 19079.04 | R20: -2906020 | S20: 4913900 | T20: 2007880 | U20: 0.048 | V20: 0.7342 | W20: 0.615 | X20: 0 | Y20: 0 | Z20: 0 | AA20: 0 | AB20: 0 | AC20: 0 | AD20: 0 | AE20: 0 | AG20: 305540 | AH20: 0 | AJ20: 6 | AK20: -26
B21: 494670 | C21: TIGER 조선TOP10 | D21: 50000 | E21: 209623 | F21: 019875 | G21: 6667 | H21: 149412545 | I21: 22410.761 | J21: 6667 | K21: 150538835 | L21: 22579.696 | M21: 0 | N21: 0 | O21: 0 | P21: 22430 | Q21: 22450.78 | R21: -128265 | S21: -998025 | T21: -1126290 | U21: 0.1542 | V21: 0.4998 | W21: 0.4757 | X21: 0 | Y21: 0 | Z21: 0 | AA21: 0 | AB21: 0 | AC21: 0 | AD21: 0 | AE21: 0 | AG21: 494670 | AH21: 0 | AJ21: 4 | AK21: -24
B22: 364970 | C22: TIGER 바이오TOP10 | D22: 50000 | E22: 721064 | F22: 019875 | G22: 2000 | H22: 15331765 | I22: 7665.8825 | J22: 2000 | K22: 15325000 | L22: 7662.5 | M22: 0 | N22: 0 | O22: 0 | P22: 7650 | Q22: 7662.75 | R22: 31765 | S22: -25000 | T22: 6765 | U22: -0.0401 | V22: 0.6018 | W22: 0.5906 | X22: 0 | Y22: 0 | Z22: 0 | AA22: 0 | AB22: 0 | AC22: 0 | AD22: 0 | AE22: 0 | AG22: 364970 | AH22: 0 | AJ22: 4 | AK22: -26
B23: 0091P0 | C23: TIGER 코리아원자력 | D23: 50000 | E23: 3997902 | F23: 019875 | G23: 38448 | H23: 691124830 | I23: 17975.573 | J23: 38448 | K23: 692694175 | L23: 18016.39 | M23: 0 | N23: 0 | O23: 0 | P23: 17950 | Q23: 17987.57 | R23: 983230 | S23: -2552575 | T23: -1569345 | U23: 0.202 | V23: 0.8348 | W23: 0.687 | X23: 0 | Y23: 0 | Z23: 0 | AA23: 0 | AB23: 0 | AC23: 0 | AD23: 0 | AE23: 0 | AG23: 0091P0 | AH23: 0 | AJ23: 5 | AK23: -26
B24: 292150 | C24: TIGER 코리아TOP10 | D24: 50000 | E24: 296322 | F24: 019875 | G24: 6977 | H24: 265941510 | I24: 38116.885 | J24: 6977 | K24: 266982650 | L24: 38266.11 | M24: 0 | N24: 0 | O24: 0 | P24: 38180 | Q24: 38261.91 | R24: -440350 | S24: -600790 | T24: -1041140 | U24: 0.9683 | V24: -0.0005 | W24: 0.9822 | X24: 0 | Y24: 0 | Z24: 0 | AA24: 0 | AB24: 0 | AC24: 0 | AD24: 0 | AE24: 0 | AG24: 292150 | AH24: 0 | AJ24: 2 | AK24: -23
B25: 139230 | C25: TIGER 200 중공업 | D25: 20000 | E25: 226761 | F25: 019875 | G25: 396 | H25: 5340060 | I25: 13485 | J25: 396 | K25: 5339585 | L25: 13483.801 | M25: 0 | N25: 0 | O25: 0 | P25: 13515 | Q25: 13541.38 | R25: -11880 | S25: 12355 | T25: 475 | U25: 0.2426 | V25: 0.5695 | W25: 0.6763 | X25: 0 | Y25: 0 | Z25: 0 | AA25: 0 | AB25: 0 | AC25: 0 | AD25: 0 | AE25: 0 | AG25: 139230 | AH25: 0 | AJ25: 10 | AK25: -27
B26: 364990 | C26: TIGER 게임TOP10 | D26: 50000 | E26: 101715 | F26: 019875 | G26: 1467 | H26: 6979285 | I26: 4757.5222 | J26: 1467 | K26: 6894900 | L26: 4700 | M26: 0 | N26: 0 | O26: 0 | P26: 4705 | Q26: 4707.37 | R26: 77050 | S26: 7335 | T26: 84385 | U26: -0.0908 | V26: 0.3873 | W26: 0.2399 | X26: 0 | Y26: 0 | Z26: 0 | AA26: 0 | AB26: 0 | AC26: 0 | AD26: 0 | AE26: 0 | AG26: 364990 | AH26: 0 | AJ26: 20 | AK26: -32
... B37: 228800 | C37: TIGER 여행레저 | D37: 30000 | E37: 156774 | F37: 019875 | G37: 3520 | H37: 9441350 | I37: 2682.2017 | J37: 3520 | K37: 9416030 | L37: 2675.0085 | M37: 0 | N37: 0 | O37: 0 | P37: 2675 | Q37: 2674.85 | R37: 25350 | S37: -30 | T37: 25320 | U37: 0.0029 | V37: 0.3796 | W37: 0.405 | X37: 0 | Y37: 0 | Z37: 0 | AA37: 0 | AB37: 0 | AC37: 0 | AD37: 0 | AE37: 0 | AG37: 228800 | AH37: 0 | AJ37: 16 | AK37: -30
B38: 138540 | C38: TIGER 현대차그룹플러스 | D38: 20000 | E38: 112884 | F38: 019875 | G38: 920 | H38: 47601105 | I38: 51740.332 | J38: 920 | K38: 47076585 | L38: 51170.201 | M38: 0 | N38: 0 | O38: 0 | P38: 51065 | Q38: 51057.22 | R38: 621305 | S38: -96785 | T38: 524520 | U38: 0.3866 | V38: 0.3391 | W38: 0.6046 | X38: 0 | Y38: 0 | Z38: 0 | AA38: 0 | AB38: 0 | AC38: 0 | AD38: 0 | AG38: 138540 | AH38: 0 | AJ38: 5 | AK38: -22
B39: 377990 | C39: TIGER Fn신재생에너지 | D39: 50000 | E39: 152242 | F39: 019875 | G39: 1000 | H39: 25740000 | I39: 25740 | J39: 1000 | K39: 25355000 | L39: 25355 | M39: 0 | N39: 0 | O39: 0 | P39: 25820 | Q39: 25882.88 | R39: -80000 | S39: 465000 | T39: 385000 | U39: 0.1999 | V39: 0.8172 | W39: 0.6897 | X39: 0 | Y39: 0 | Z39: 0 | AA39: 0 | AB39: 0 | AC39: 0 | AD39: 0 | AE39: 0 | AG39: 377990 | AH39: 0 | AJ39: 8 | AK39: -28
B40: 395270 | C40: HANARO Fn K-반도체 | D40: 50000 | E40: 704450 | F40: 019875 | G40: 8425 | H40: 471563425 | I40: 55971.92 | J40: 8425 | K40: 474731085 | L40: 56347.903 | M40: 0 | N40: 0 | O40: 0 | P40: 56195 | Q40: 56233.42 | R40: -1879450 | S40: -1288210 | T40: -3167660 | U40: 1.171 | V40: 0.0911 | W40: 0.9176 | X40: 0 | Y40: 0 | Z40: 0 | AA40: 0 | AB40: 0 | AC40: 0 | AD40: 0 | AE40: 0 | AG40: 395270 | AH40: 0 | AJ40: 2 | AK40: -23
B41: 091220 | C41: TIGER 은행 | D41: 20000 | E41: 22990 | F41: 019875 | G41: 10 | H41: 166750 | I41: 16675 | J41: 10 | K41: 168350 | L41: 16835 | M41: 0 | N41: 0 | O41: 0 | P41: 16710 | Q41: 16733.82 | R41: -350 | S41: -1250 | T41: -1600 | U41: 0.0584 | V41: 0.2659 | W41: 0.2943 | X41: 0 | Y41: 0 | Z41: 0 | AA41: 0 | AB41: 0 | AC41: 0 | AD41: 0 | AE41: 0 | AG41: 091220 | AH41: 0 | AJ41: 7 | AK41: -29
B42: 261070 | C42: TIGER 코스닥150바이오테크 | D42: 20000 | E42: 128747 | F42: 019875 | G42: 58 | H42: 758930 | I42: 13085 | J42: 58 | K42: 758930 | L42: 13085 | M42: 0 | N42: 0 | O42: 0 | P42: 13085 | Q42: 13099.14 | R42: 0 | S42: 0 | T42: 0 | U42: -0.2537 | V42: 1.071 | W42: 0.7505 | X42: 0 | Y42: 0 | Z42: 0 | AA42: 0 | AB42: 0 | AC42: 0 | AD42: 0 | AG42: 261070 | AH42: 0 | AJ42: 8 | AK42: -33
B43: 261060 | C43: TIGER 코스닥150IT | D43: 20000 | E43: 14634 | F43: 019875 | G43: 0 | H43: 0 | I43: 0 | J43: 0 | K43: 0 | L43: 0 | M43: 0 | N43: 0 | O43: 0 | P43: 23695 | Q43: 23746.14 | R43: 0 | S43: 0 | T43: 0 | U43: 0.2022 | V43: 1.0415 | W43: 0.8574 | X43: 0 | Y43: 0 | Z43: 0 | AA43: 0 | AB43: 0 | AC43: 0 | AD43: 0 | AG43: 261060 | AH43: 0 | AJ43: 13 | AK43: -39
B44: 138520 | C44: TIGER 삼성그룹 | D44: 20000 | E44: 15573 | F44: 019875 | G44: 11 | H44: 409530 | I44: 37230 | J44: 11 | K44: 410225 | L44: 37293.182 | M44: 0 | N44: 0 | O44: 0 | P44: 37245 | Q44: 37341.25 | R44: -165 | S44: -530 | T44: -695 | U44: 0.8026 | V44: 0.0874 | W44: 0.9219 | X44: 0 | Y44: 0 | Z44: 0 | AA44: 0 | AB44: 0 | AC44: 0 | AD44: 0 | AG44: 138520 | AH44: 0 | AJ44: 12 | AK44: -30
B45: 139250 | C45: TIGER 200 에너지화학 | D45: 20000 | E45: 15911 | F45: 019875 | G45: 0 | H45: 0 | I45: 0 | J45: 0 | K45: 0 | L45: 0 | M45: 0 | N45: 0 | O45: 0 | P45: 17500 | Q45: 17538.24 | R45: 0 | S45: 0 | T45: 0 | U45: 0.275 | V45: 0.4257 | W45: 0.6803 | X45: 0 | Y45: 0 | Z45: 0 | AA45: 0 | AB45: 0 | AC45: 0 | AD45: 0 | AG45: 139250 | AH45: 0 | AJ45: 15 | AK45: -32
B46: 138530 | C46: TIGER LG그룹플러스 | D46: 20000 | E46: 38434 | F46: 019875 | G46: 76 | H46: 948930 | I46: 12485.921 | J46: 76 | K46: 957210 | L46: 12594.868 | M46: 0 | N46: 0 | O46: 0 | P46: 12530 | Q46: 12551.74 | R46: -3350 | S46: -4930 | T46: -8280 | U46: 0.3339 | V46: 0.2608 | W46: 0.3648 | X46: 0 | Y46: 0 | Z46: 0 | AA46: 0 | AB46: 0 | AC46: 0 | AD46: 0 | AG46: 138530 | AH46: 0 | AJ46: 6 | AK46: -27
B47: 364960 | C47: TIGER BBIG | D47: 50000 | E47: 13593 | F47: 019875 | G47: 0 | H47: 0 | I47: 0 | J47: 0 | K47: 0 | L47: 0 | M47: 0 | N47: 0 | O47: 0 | P47: 6735 | Q47: 6741.92 | R47: 0 | S47: 0 | T47: 0 | U47: 0.0216 | V47: 0.4896 | W47: 0.6055 | X47: 0 | Y47: 0 | Z47: 0 | AA47: 0 | AB47: 0 | AC47: 0 | AD47: 0 | AG47: 364960 | AH47: 0 | AJ47: 12 | AK47: -35
B48: 400970 | C48: TIGER Fn메타버스 | D48: 50000 | E48: 13075 | F48: 019875 | G48: 0 | H48: 0 | I48: 0 | J48: 0 | K48: 0 | L48: 0 | M48: 0 | N48: 0 | O48: 0 | P48: 7485 | Q48: 7491.67 | R48: 0 | S48: 0 | T48: 0 | U48: 0.082 | V48: 0.3983 | W48: 0.4587 | X48: 0 | Y48: 0 | Z48: 0 | AA48: 0 | AB48: 0 | AC48: 0 | AD48: 0 | AG48: 400970 | AH48: 0 | AJ48: 13 | AK48: -30
B49: 227540 | C49: TIGER 200 헬스케어 | D49: 20000 | E49: 19334 | F49: 019875 | G49: 0 | H49: 0 | I49: 0 | J49: 0 | K49: 0 | L49: 0 | M49: 0 | N49: 0 | O49: 0 | P49: 20110 | Q49: 20145.75 | R49: 0 | S49: 0 | T49: 0 | U49: -0.0537 | V49: 0.5236 | W49: 0.4782 | X49: 0 | Y49: 0 | Z49: 0 | AA49: 0 | AB49: 0 | AC49: 0 | AD49: 0 | AG49: 227540 | AH49: 0 | AJ49: 8 | AK49: -28
B50: 150460 | C50: TIGER 중국소비테마 | D50: 30000 | E50: 9748 | F50: 019875 | G50: 0 | H50: 0 | I50: 0 | J50: 0 | K50: 0 | L50: 0 | M50: 0 | N50: 0 | O50: 0 | P50: 7845 | Q50: 7856.89 | R50: 0 | S50: 0 | T50: 0 | U50: -0.1041 | V50: 0.4693 | W50: 0.499 | X50: 0 | Y50: 0 | Z50: 0 | AA50: 0 | AB50: 0 | AC50: 0 | AD50: 0 | AG50: 150460 | AH50: 0 | AJ50: 15 | AK50: -37
B51: 417630 | C51: TIGER KEDI혁신기업ESG30 | D51: 50000 | E51: 993 | F51: 019875 | G51: 0 | H51: 0 | I51: 0 | J51: 0 | K51: 0 | L51: 0 | M51: 0 | N51: 0 | O51: 0 | P51: 20050 | Q51: 20080.23 | R51: 0 | S51: 0 | T51: 0 | U51: 0.3001 | V51: 0.4116 | W51: 0.839 | X51: 0 | Y51: 0 | Z51: 0 | AA51: 0 | AB51: 0 | AC51: 0 | AD51: 0 | AG51: 417630 | AH51: 0 | AJ51: 16 | AK51: -37
B52: 0148J0 | C52: TIGER 코리아휴머노이드로봇산업 | D52: 50000 | E52: 3338871 | F52: 019875 | G52: 19406 | H52: 177544715 | I52: 9148.9599 | J52: 19406 | K52: 177667425 | L52: 9155.2832 | M52: 0 | N52: 0 | O52: 0 | P52: 9210 | Q52: 9215.94 | R52: -1184545 | S52: 1061835 | T52: -122710 | U52: 0.4045 | V52: 0.6424 | W52: 0.5986 | X52: 0 | Y52: 0 | Z52: 0 | AA52: 0 | AB52: 0 | AC52: 0 | AD52: 0 | AG52: 0148J0 | AH52: 0 | AJ52: 5 | AK52: -26

Sheet Sheet3
A1: 종목코드 | B1: 종목명 | C1: 구분 | D1: 유형 | E1: 주문수량 | F1: 미체결 | G1: 체결수량 | H1: 주문가격 | I1: 체결가격 | J1: 주문시간 | K1: 체결시간 | L1: 상태 | M1: 에러 | N1: 주문번호 | O1: 주문Seq | P1: 원주문Seq | Q1: 정정취소 | R1: 공매도 | S1: 거부 | T1: 가격유형 | U1: 원주문번호 | V1: 자전방지 | W1: 알고전략구분 | X1: 프로그램
A2: 0117V0 | B2: TIGER 코리아AI전력기기TOP3플러스 | C2: 매도 | D2: 정정 | E2: 1000 | F2: 0 | G2: 1000 | H2: 19290 | I2: 19290 | J2: 0.38678241 | K2: 0.38679398 | L2: 체결 | N2: 80779 | O2: 80779 | P2: 80764 | Q2: 0 | R2: 일반 | S2: 0 | T2: 지정가 | U2: 80764 | W2: 알고리즘 | X2: 일반
