Workbook

Sheet Sheet1
R1: 0.9
P2: =SUM(P4:P5) -> 22644597 | Q2: =SUM(Q4:Q5) -> 0 | R2: =SUM(R4:R5) -> 20380137
J3: ABS 포지션 | K3: =ABS(K4)+K5 -> 30406600 | O3: 상품 | P3: ETF 델타 | Q3: 선물 델타 | R3: NET 델타 | S3: 계약수 환산 | T3: 필요 계약수 | U3: 당일 손익 | V3: NET
J4: 매도 포지션 | K4: =SUMIFS($N$15:$N$977,$N$15:$N$977,"<0") -> 0 | N4: =U4/ABS(N14) -> 0.20016713 | O4: KOSPI 200 | P4: =X14 -> 1234294 | Q4: =N10 -> 0 | R4: =(P4+Q4)*R1 -> 1110864.6 | S4: =R4/T10 -> 0.021581502 | T4: =S4*-1 -> -0.021581502 | U4: =S9+T14 -> 6086402 | V4: 바스켓
J5: 매수 포재션 | K5: =SUMIFS($N$15:$N$977,$N$15:$N$977,">0") -> 30406600 | N5: =U4/N12 -> 0.20142311 | O5: KOSDAQ 150 | P5: =Y14 -> 21410303 | Q5: =N11 -> 0 | R5: =(P5+Q5)*R1 -> 19269273 | S5: =R5/T11 -> 1.4059005 | T5: =S5*-1 -> -1.4059005 | V5: 현금
B7: 종목코드 | C7: 종목명 | D7: 1CU | E7: 시장 거래량 | F7: 펀드코드 | G7: 당일매도수량 | H7: 당일매도금액 | I7: 매도단가 | J7: 당일매수수량 | K7: 당일매수금액 | L7: 매수단가 | M7: NET 포지션 수량 | N7: NET 포지션 금액 | O7: CU 비중 | P7: 현재가 | Q7: 매도 손익 | R7: 매수 손익 | S7: 당일 손익 | T7: 1계약 델타 | U7: 전체 잔고 수량
B9: - | C9: - | D9: - | E9: - | F9: - | G9: =SUM(G10:G11) -> 93 | H9: =SUM(H10:H11) -> 2938118000 | I9: - | J9: =SUM(J10:J11) -> 93 | K9: =SUM(K10:K11) -> 2928765000 | L9: - | M9: =SUM(M10:M11) -> 0 | N9: =SUM(N10:N11) -> 0 | O9: - | P9: - | Q9: =SUM(Q10:Q11) -> 39479000 | R9: =SUM(R10:R11) -> -30126000 | S9: =SUM(S10:S11) -> 9353000 | T9: =SUM(T10:T11) -> 65179000 | U9: =SUM(U10:U11) -> 0
B10: A0569 | C10: 미니 코스피 200 선물 | D10: 0 | E10: - | F10: 028875 | G10: =IF([1]!'028875^A0569:SELL_TDY_QTY'="NO", 0, [1]!'028875^A0569:SELL_TDY_QTY') -> 43 | H10: =IF([1]!'028875^A0569:SELL_TDY_AMT'="NO", 0, [1]!'028875^A0569:SELL_TDY_AMT') -> 2242428000 | I10: =IFERROR(H10/G10/50000,0) -> 1042.9898 | J10: =IF([1]!'028875^A0569:BUY_TDY_QTY'="NO", 0, [1]!'028875^A0569:BUY_TDY_QTY') -> 43 | K10: =IF([1]!'028875^A0569:BUY_TDY_AMT'="NO", 0, [1]!'028875^A0569:BUY_TDY_AMT') -> 2233695000 | L10: =IFERROR(K10/J10/50000,0) -> 1038.9279 | M10: =J10-G10 -> 0 | N10: =M10*P10*50000 -> 0 | O10: - | P10: =[1]!'A0569:LAST' -> 1029.46 | Q10: =(P10-I10)*-1*G10*50000 -> 29089000 | R10: =(P10-L10)*J10*50000 -> -20356000 | S10: =Q10+R10 -> 8733000 | T10: =P10*50000 -> 51473000 | U10: =IF([1]!'028875^A0569:QTY'="NO", 0, [1]!'028875^A0569:QTY') -> 0
B11: A0669 | C11: 코스닥 150 선물 | D11: 0 | E11: - | F11: 028875 | G11: =IF([1]!'028875^A0669:SELL_TDY_QTY'="NO", 0, [1]!'028875^A0669:SELL_TDY_QTY') -> 50 | H11: =IF([1]!'028875^A0669:SELL_TDY_AMT'="NO", 0, [1]!'028875^A0669:SELL_TDY_AMT') -> 695690000 | I11: =IFERROR(H11/G11/10000,0) -> 1391.38 | J11: =IF([1]!'028875^A0669:BUY_TDY_QTY'="NO", 0, [1]!'028875^A0669:BUY_TDY_QTY') -> 50 | K11: =IF([1]!'028875^A0669:BUY_TDY_AMT'="NO", 0, [1]!'028875^A0669:BUY_TDY_AMT') -> 695070000 | L11: =IFERROR(K11/J11/10000,0) -> 1390.14 | M11: =J11-G11 -> 0 | N11: =M11*P11*10000 -> 0 | O11: - | P11: =[1]!'A0669:LAST' -> 1370.6 | Q11: =(P11-I11)*-1*G11*10000 -> 10390000 | R11: =(P11-L11)*J11*10000 -> -9770000 | S11: =Q11+R11 -> 620000 | T11: =P11*10000 -> 13706000 | U11: =IF([1]!'028875^A0669:QTY'="NO", 0, [1]!'028875^A0669:QTY') -> 0
G12: =@IF(@KBMonitor|DATA!'019875^091220:SELL_TDY_QTY'="NO", 0, KBMonitor|DATA!'019875^091220:SELL_TDY_QTY') | N12: =AE14 -> 30217000 | T12: * 200과 150은 전일종가(금액)으로 계산 | AA12: 유리 여부
B13: 종목코드 | C13: 종목명 | D13: 1CU | E13: 시장 거래량 | F13: 펀드코드 | G13: 당일매도수량 | H13: 당일매도금액 | I13: 매도단가 | J13: 당일매수수량 | K13: 당일매수금액 | L13: 매수단가 | M13: NET 포지션 수량 | N13: NET 포지션 금액 | O13: CU 비중 | P13: 현재가 | Q13: NAV | R13: 매도 손익 | S13: 매수 손익 | T13: 당일 손익 | U13: KS 베타 | V13: KQ 베타 | W13: R-Squared | X13: W.KOSPI200 | Y13: W.KOSDAQ150 | Z13: W.200&150 외 | AA13: 매도 손익 (nav 대비) | AB13: 매수 손익 (nav 대비) | AC13: 매도 손익 (nav 대비) | AD13: 매수 손익 (nav 대비) | AE13: 포지션 abs
B14: - | C14: - | D14: - | E14: - | F14: - | G14: =SUM(G15:G943) -> 218583 | H14: =SUM(H15:H943) -> 4781740996 | I14: - | J14: =SUM(J15:J943) -> 220247 | K14: =SUM(K15:K943) -> 4815414194 | L14: - | M14: =SUM(M15:M943) -> 1664 | N14: =SUM(N15:N943) -> 30406600 | O14: - | P14: - | Q14: - | R14: =SUM(R15:R943) -> 61580971 | S14: =SUM(S15:S943) -> -64847569 | T14: =SUM(T15:T943) -> -3266598 | U14: =AVERAGE(U15:U978) -> 0.25538684 | V14: =AVERAGE(V15:V978) -> 0.46778684 | W14: =AVERAGE(W15:W978) -> 0.5729 | X14: =SUM(X15:X978) -> 1234294 | Y14: =SUM(Y15:Y978) -> 21410303 | Z14: =SUM(Z15:Z978) -> 7762002.9 | AA14: =SUM(AA15:AA978) -> 0 | AB14: =SUM(AB15:AB978) -> -5.88372 | AC14: =SUM(AC15:AC978) -> 0 | AD14: =SUM(AD15:AD978) -> 4.0907217 | AE14: =SUM(AE15:AE978) -> 30217000 | AG14: 종목코드 | AH14: 정리매매 | AJ14: 매도 bp | AK14: 매수 bp
B15: 396500 | C15: TIGER 반도체TOP10 | D15: =VLOOKUP("A"&B15,[2]ETF!$A$4:$M$10000,13,FALSE) -> 50000 | E15: =[1]!'396500:VOL'+0 -> 7983087 | F15: 019875 | G15: =IF([1]!'019875^396500:SELL_TDY_QTY'="NO", 0, [1]!'019875^396500:SELL_TDY_QTY') -> 78372 | H15: =IF([1]!'019875^396500:SELL_TDY_AMT'="NO", 0, [1]!'019875^396500:SELL_TDY_AMT') -> 2680505060 | I15: =IFERROR(H15/G15,0) -> 34202.331 | J15: =IF([1]!'019875^396500:BUY_TDY_QTY'="NO", 0, [1]!'019875^396500:BUY_TDY_QTY') -> 78372 | K15: =IF([1]!'019875^396500:BUY_TDY_AMT'="NO", 0, [1]!'019875^396500:BUY_TDY_AMT') -> 2686885015 | L15: =IFERROR(K15/J15,0) -> 34283.737 | M15: =J15-G15 -> 0 | N15: =M15*P15 -> 0 | O15: =M15/D15 -> 0 | P15: =[1]!'396500:LAST' -> 33765 | Q15: =[1]!'396500:NAV' -> 33833.49 | R15: =(P15-I15)*-1*G15 -> 34274480 | S15: =(P15-L15)*J15 -> -40654435 | T15: =R15+S15 -> -6379955 | U15: =_xlfn.IFNA(VLOOKUP(B15,[2]베타!$A$2:$C$1000,3,FALSE),0) -> 1.1175 | V15: =_xlfn.IFNA(VLOOKUP(B15,[2]베타!$A$2:$D$1000,4,FALSE),0) -> 0.1842 | W15: =_xlfn.IFNA(VLOOKUP(B15,[2]베타!$A$2:$E$1000,5,FALSE),0) -> 0.9274 | X15: =M15*Q15*U15 -> 0 | Y15: =M15*Q15*V15 -> 0 | Z15: =(P15*M15)-(X15+Y15) -> 0 | AA15: =IF(M15<0, P15-Q15, 0) -> 0 | AB15: =IF(M15>0, Q15*(1-0.2%)-P15, 0) -> 0 | AC15: =AA15/Q15*10000 -> 0 | AD15: =AB15/Q15*10000 -> 0 | AE15: =ABS(N15) -> 0 | AG15: =B15 -> 396500 | AH15: =-1*M15 -> 0 | AJ15: =ROUNDUP(VLOOKUP(B15,[2]베타!$A$2:$L$1000,12,FALSE),0) -> -3 | AK15: =ROUNDUP(VLOOKUP(B15,[2]베타!$A$2:$M$1000,13,FALSE),0) -> -20
B16: 228790 | C16: TIGER 화장품 | D16: =VLOOKUP("A"&B16,[2]ETF!$A$4:$M$10000,13,FALSE) -> 30000 | E16: =[1]!'228790:VOL'+0 -> 10053039 | F16: 019875 | G16: =IF([1]!'019875^228790:SELL_TDY_QTY'="NO", 0, [1]!'019875^228790:SELL_TDY_QTY') -> 4059 | H16: =IF([1]!'019875^228790:SELL_TDY_AMT'="NO", 0, [1]!'019875^228790:SELL_TDY_AMT') -> 19281855 | I16: =IFERROR(H16/G16,0) -> 4750.3954 | J16: =IF([1]!'019875^228790:BUY_TDY_QTY'="NO", 0, [1]!'019875^228790:BUY_TDY_QTY') -> 4059 | K16: =IF([1]!'019875^228790:BUY_TDY_AMT'="NO", 0, [1]!'019875^228790:BUY_TDY_AMT') -> 19323495 | L16: =IFERROR(K16/J16,0) -> 4760.6541 | M16: =J16-G16 -> 0 | N16: =M16*P16 -> 0 | O16: =M16/D16 -> 0 | P16: =[1]!'228790:LAST' -> 4680 | Q16: =[1]!'228790:NAV' -> 4707.35 | R16: =(P16-I16)*-1*G16 -> 285735 | S16: =(P16-L16)*J16 -> -327375 | T16: =R16+S16 -> -41640 | U16: =_xlfn.IFNA(VLOOKUP(B16,[2]베타!$A$2:$C$1000,3,FALSE),0) -> -0.211 | V16: =_xlfn.IFNA(VLOOKUP(B16,[2]베타!$A$2:$D$1000,4,FALSE),0) -> 0.5851 | W16: =_xlfn.IFNA(VLOOKUP(B16,[2]베타!$A$2:$E$1000,5,FALSE),0) -> 0.3567 | X16: =M16*Q16*U16 -> 0 | Y16: =M16*Q16*V16 -> 0 | Z16: =(P16*M16)-(X16+Y16) -> 0 | AA16: =IF(M16<0, P16-Q16, 0) -> 0 | AB16: =IF(M16>0, Q16*(1-0.2%)-P16, 0) -> 0 | AC16: =AA16/Q16*10000 -> 0 | AD16: =AB16/Q16*10000 -> 0 | AE16: =ABS(N16) -> 0 | AG16: =B16 -> 228790 | AH16: =-1*M16 -> 0 | AJ16: =ROUNDUP(VLOOKUP(B16,[2]베타!$A$2:$L$1000,12,FALSE),0) -> 14 | AK16: =ROUNDUP(VLOOKUP(B16,[2]베타!$A$2:$M$1000,13,FALSE),0) -> -28
B17: 462010 | C17: TIGER 2차전지소재Fn | D17: =VLOOKUP("A"&B17,[2]ETF!$A$4:$M$10000,13,FALSE) -> 50000 | E17: =[1]!'462010:VOL'+0 -> 2680571 | F17: 019875 | G17: =IF([1]!'019875^462010:SELL_TDY_QTY'="NO", 0, [1]!'019875^462010:SELL_TDY_QTY') -> 1767 | H17: =IF([1]!'019875^462010:SELL_TDY_AMT'="NO", 0, [1]!'019875^462010:SELL_TDY_AMT') -> 8706400 | I17: =IFERROR(H17/G17,0) -> 4927.2213 | J17: =IF([1]!'019875^462010:BUY_TDY_QTY'="NO", 0, [1]!'019875^462010:BUY_TDY_QTY') -> 1767 | K17: =IF([1]!'019875^462010:BUY_TDY_AMT'="NO", 0, [1]!'019875^462010:BUY_TDY_AMT') -> 8494840 | L17: =IFERROR(K17/J17,0) -> 4807.4929 | M17: =J17-G17 -> 0 | N17: =M17*P17 -> 0 | O17: =M17/D17 -> 0 | P17: =[1]!'462010:LAST' -> 4765 | Q17: =[1]!'462010:NAV' -> 4775.7 | R17: =(P17-I17)*-1*G17 -> 286645 | S17: =(P17-L17)*J17 -> -75085 | T17: =R17+S17 -> 211560 | U17: =_xlfn.IFNA(VLOOKUP(B17,[2]베타!$A$2:$C$1000,3,FALSE),0) -> 0.0594 | V17: =_xlfn.IFNA(VLOOKUP(B17,[2]베타!$A$2:$D$1000,4,FALSE),0) -> 0.8415 | W17: =_xlfn.IFNA(VLOOKUP(B17,[2]베타!$A$2:$E$1000,5,FALSE),0) -> 0.6174 | X17: =M17*Q17*U17 -> 0 | Y17: =M17*Q17*V17 -> 0 | Z17: =(P17*M17)-(X17+Y17) -> 0 | AA17: =IF(M17<0, P17-Q17, 0) -> 0 | AB17: =IF(M17>0, Q17*(1-0.2%)-P17, 0) -> 0 | AC17: =AA17/Q17*10000 -> 0 | AD17: =AB17/Q17*10000 -> 0 | AE17: =ABS(N17) -> 0 | AG17: =B17 -> 462010 | AH17: =-1*M17 -> 0 | AJ17: =ROUNDUP(VLOOKUP(B17,[2]베타!$A$2:$L$1000,12,FALSE),0) -> 10 | AK17: =ROUNDUP(VLOOKUP(B17,[2]베타!$A$2:$M$1000,13,FALSE),0) -> -29
B18: 364980 | C18: TIGER 2차전지TOP10 | D18: =VLOOKUP("A"&B18,[2]ETF!$A$4:$M$10000,13,FALSE) -> 50000 | E18: =[1]!'364980:VOL'+0 -> 5426187 | F18: 019875 | G18: =IF([1]!'019875^364980:SELL_TDY_QTY'="NO", 0, [1]!'019875^364980:SELL_TDY_QTY') -> 47838 | H18: =IF([1]!'019875^364980:SELL_TDY_AMT'="NO", 0, [1]!'019875^364980:SELL_TDY_AMT') -> 495100400 | I18: =IFERROR(H18/G18,0) -> 10349.521 | J18: =IF([1]!'019875^364980:BUY_TDY_QTY'="NO", 0, [1]!'019875^364980:BUY_TDY_QTY') -> 47838 | K18: =IF([1]!'019875^364980:BUY_TDY_AMT'="NO", 0, [1]!'019875^364980:BUY_TDY_AMT') -> 492394585 | L18: =IFERROR(K18/J18,0) -> 10292.959 | M18: =J18-G18 -> 0 | N18: =M18*P18 -> 0 | O18: =M18/D18 -> 0 | P18: =[1]!'364980:LAST' -> 10140 | Q18: =[1]!'364980:NAV' -> 10202.37 | R18: =(P18-I18)*-1*G18 -> 10023080 | S18: =(P18-L18)*J18 -> -7317265 | T18: =R18+S18 -> 2705815 | U18: =_xlfn.IFNA(VLOOKUP(B18,[2]베타!$A$2:$C$1000,3,FALSE),0) -> 0.0699 | V18: =_xlfn.IFNA(VLOOKUP(B18,[2]베타!$A$2:$D$1000,4,FALSE),0) -> 0.6894 | W18: =_xlfn.IFNA(VLOOKUP(B18,[2]베타!$A$2:$E$1000,5,FALSE),0) -> 0.4887 | X18: =M18*Q18*U18 -> 0 | Y18: =M18*Q18*V18 -> 0 | Z18: =(P18*M18)-(X18+Y18) -> 0 | AA18: =IF(M18<0, P18-Q18, 0) -> 0 | AB18: =IF(M18>0, Q18*(1-0.2%)-P18, 0) -> 0 | AC18: =AA18/Q18*10000 -> 0 | AD18: =AB18/Q18*10000 -> 0 | AE18: =ABS(N18) -> 0 | AG18: =B18 -> 364980 | AH18: =-1*M18 -> 0 | AJ18: =ROUNDUP(VLOOKUP(B18,[2]베타!$A$2:$L$1000,12,FALSE),0) -> 9 | AK18: =ROUNDUP(VLOOKUP(B18,[2]베타!$A$2:$M$1000,13,FALSE),0) -> -28
B19: 0117V0 | C19: TIGER 코리아AI전력기기TOP3플러스 | D19: =VLOOKUP("A"&B19,[2]ETF!$A$4:$M$10000,13,FALSE) -> 50000 | E19: =[1]!'0117V0:VOL'+0 -> 1139385 | F19: 019875 | G19: =IF([1]!'019875^0117V0:SELL_TDY_QTY'="NO", 0, [1]!'019875^0117V0:SELL_TDY_QTY') -> 2729 | H19: =IF([1]!'019875^0117V0:SELL_TDY_AMT'="NO", 0, [1]!'019875^0117V0:SELL_TDY_AMT') -> 49657675 | I19: =IFERROR(H19/G19,0) -> 18196.29 | J19: =IF([1]!'019875^0117V0:BUY_TDY_QTY'="NO", 0, [1]!'019875^0117V0:BUY_TDY_QTY') -> 2729 | K19: =IF([1]!'019875^0117V0:BUY_TDY_AMT'="NO", 0, [1]!'019875^0117V0:BUY_TDY_AMT') -> 50436405 | L19: =IFERROR(K19/J19,0) -> 18481.643 | M19: =J19-G19 -> 0 | N19: =M19*P19 -> 0 | O19: =M19/D19 -> 0 | P19: =[1]!'0117V0:LAST' -> 17940 | Q19: =[1]!'0117V0:NAV' -> 17924.85 | R19: =(P19-I19)*-1*G19 -> 699415 | S19: =(P19-L19)*J19 -> -1478145 | T19: =R19+S19 -> -778730 | U19: =_xlfn.IFNA(VLOOKUP(B19,[2]베타!$A$2:$C$1000,3,FALSE),0) -> 0.4144 | V19: =_xlfn.IFNA(VLOOKUP(B19,[2]베타!$A$2:$D$1000,4,FALSE),0) -> 0.7155 | W19: =_xlfn.IFNA(VLOOKUP(B19,[2]베타!$A$2:$E$1000,5,FALSE),0) -> 0.6341 | X19: =M19*Q19*U19 -> 0 | Y19: =M19*Q19*V19 -> 0 | Z19: =(P19*M19)-(X19+Y19) -> 0 | AA19: =IF(M19<0, P19-Q19, 0) -> 0 | AB19: =IF(M19>0, Q19*(1-0.2%)-P19, 0) -> 0 | AC19: =AA19/Q19*10000 -> 0 | AD19: =AB19/Q19*10000 -> 0 | AE19: =ABS(N19) -> 0 | AG19: =B19 -> 0117V0 | AH19: =-1*M19 -> 0 | AJ19: =ROUNDUP(VLOOKUP(B19,[2]베타!$A$2:$L$1000,12,FALSE),0) -> 7 | AK19: =ROUNDUP(VLOOKUP(B19,[2]베타!$A$2:$M$1000,13,FALSE),0) -> -27
B20: 305540 | C20: TIGER 2차전지테마 | D20: =VLOOKUP("A"&B20,[2]ETF!$A$4:$M$10000,13,FALSE) -> 50000 | E20: =[1]!'305540:VOL'+0 -> 598038 | F20: 019875 | G20: =IF([1]!'019875^305540:SELL_TDY_QTY'="NO", 0, [1]!'019875^305540:SELL_TDY_QTY') -> 1001 | H20: =IF([1]!'019875^305540:SELL_TDY_AMT'="NO", 0, [1]!'019875^305540:SELL_TDY_AMT') -> 19023575 | I20: =IFERROR(H20/G20,0) -> 19004.57 | J20: =IF([1]!'019875^305540:BUY_TDY_QTY'="NO", 0, [1]!'019875^305540:BUY_TDY_QTY') -> 2641 | K20: =IF([1]!'019875^305540:BUY_TDY_AMT'="NO", 0, [1]!'019875^305540:BUY_TDY_AMT') -> 49170575 | L20: =IFERROR(K20/J20,0) -> 18618.165 | M20: =J20-G20 -> 1640 | N20: =M20*P20 -> 30217000 | O20: =M20/D20 -> 0.0328 | P20: =[1]!'305540:LAST' -> 18425 | Q20: =[1]!'305540:NAV' -> 18445.89 | R20: =(P20-I20)*-1*G20 -> 580150 | S20: =(P20-L20)*J20 -> -510150 | T20: =R20+S20 -> 70000 | U20: =_xlfn.IFNA(VLOOKUP(B20,[2]베타!$A$2:$C$1000,3,FALSE),0) -> 0.0416 | V20: =_xlfn.IFNA(VLOOKUP(B20,[2]베타!$A$2:$D$1000,4,FALSE),0) -> 0.7049 | W20: =_xlfn.IFNA(VLOOKUP(B20,[2]베타!$A$2:$E$1000,5,FALSE),0) -> 0.5319 | X20: =M20*Q20*U20 -> 1258452.4 | Y20: =M20*Q20*V20 -> 21324113 | Z20: =(P20*M20)-(X20+Y20) -> 7634434.7 | AA20: =IF(M20<0, P20-Q20, 0) -> 0 | AB20: =IF(M20>0, Q20*(1-0.2%)-P20, 0) -> -16.00178 | AC20: =AA20/Q20*10000 -> 0 | AD20: =AB20/Q20*10000 -> -8.674984 | AE20: =ABS(N20) -> 30217000 | AG20: =B20 -> 305540 | AH20: =-1*M20 -> -1640 | AJ20: =ROUNDUP(VLOOKUP(B20,[2]베타!$A$2:$L$1000,12,FALSE),0) -> 9 | AK20: =ROUNDUP(VLOOKUP(B20,[2]베타!$A$2:$M$1000,13,FALSE),0) -> -28
B21: 494670 | C21: TIGER 조선TOP10 | D21: =VLOOKUP("A"&B21,[2]ETF!$A$4:$M$10000,13,FALSE) -> 50000 | E21: =[1]!'494670:VOL'+0 -> 439147 | F21: 019875 | G21: =IF([1]!'019875^494670:SELL_TDY_QTY'="NO", 0, [1]!'019875^494670:SELL_TDY_QTY') -> 20807 | H21: =IF([1]!'019875^494670:SELL_TDY_AMT'="NO", 0, [1]!'019875^494670:SELL_TDY_AMT') -> 436190212 | I21: =IFERROR(H21/G21,0) -> 20963.628 | J21: =IF([1]!'019875^494670:BUY_TDY_QTY'="NO", 0, [1]!'019875^494670:BUY_TDY_QTY') -> 20807 | K21: =IF([1]!'019875^494670:BUY_TDY_AMT'="NO", 0, [1]!'019875^494670:BUY_TDY_AMT') -> 433007335 | L21: =IFERROR(K21/J21,0) -> 20810.657 | M21: =J21-G21 -> 0 | N21: =M21*P21 -> 0 | O21: =M21/D21 -> 0 | P21: =[1]!'494670:LAST' -> 20700 | Q21: =[1]!'494670:NAV' -> 20675.91 | R21: =(P21-I21)*-1*G21 -> 5485312 | S21: =(P21-L21)*J21 -> -2302435 | T21: =R21+S21 -> 3182877 | U21: =_xlfn.IFNA(VLOOKUP(B21,[2]베타!$A$2:$C$1000,3,FALSE),0) -> 0.1698 | V21: =_xlfn.IFNA(VLOOKUP(B21,[2]베타!$A$2:$D$1000,4,FALSE),0) -> 0.4181 | W21: =_xlfn.IFNA(VLOOKUP(B21,[2]베타!$A$2:$E$1000,5,FALSE),0) -> 0.3854 | X21: =M21*Q21*U21 -> 0 | Y21: =M21*Q21*V21 -> 0 | Z21: =(P21*M21)-(X21+Y21) -> 0 | AA21: =IF(M21<0, P21-Q21, 0) -> 0 | AB21: =IF(M21>0, Q21*(1-0.2%)-P21, 0) -> 0 | AC21: =AA21/Q21*10000 -> 0 | AD21: =AB21/Q21*10000 -> 0 | AE21: =ABS(N21) -> 0 | AG21: =B21 -> 494670 | AH21: =-1*M21 -> 0 | AJ21: =ROUNDUP(VLOOKUP(B21,[2]베타!$A$2:$L$1000,12,FALSE),0) -> 5 | AK21: =ROUNDUP(VLOOKUP(B21,[2]베타!$A$2:$M$1000,13,FALSE),0) -> -26
B22: 364970 | C22: TIGER 바이오TOP10 | D22: =VLOOKUP("A"&B22,[2]ETF!$A$4:$M$10000,13,FALSE) -> 50000 | E22: =[1]!'364970:VOL'+0 -> 1585985 | F22: 019875 | G22: =IF([1]!'019875^364970:SELL_TDY_QTY'="NO", 0, [1]!'019875^364970:SELL_TDY_QTY') -> 20055 | H22: =IF([1]!'019875^364970:SELL_TDY_AMT'="NO", 0, [1]!'019875^364970:SELL_TDY_AMT') -> 149019704 | I22: =IFERROR(H22/G22,0) -> 7430.5512 | J22: =IF([1]!'019875^364970:BUY_TDY_QTY'="NO", 0, [1]!'019875^364970:BUY_TDY_QTY') -> 20055 | K22: =IF([1]!'019875^364970:BUY_TDY_AMT'="NO", 0, [1]!'019875^364970:BUY_TDY_AMT') -> 148868755 | L22: =IFERROR(K22/J22,0) -> 7423.0244 | M22: =J22-G22 -> 0 | N22: =M22*P22 -> 0 | O22: =M22/D22 -> 0 | P22: =[1]!'364970:LAST' -> 7320 | Q22: =[1]!'364970:NAV' -> 7326.31 | R22: =(P22-I22)*-1*G22 -> 2217104 | S22: =(P22-L22)*J22 -> -2066155 | T22: =R22+S22 -> 150949 | U22: =_xlfn.IFNA(VLOOKUP(B22,[2]베타!$A$2:$C$1000,3,FALSE),0) -> -0.0509 | V22: =_xlfn.IFNA(VLOOKUP(B22,[2]베타!$A$2:$D$1000,4,FALSE),0) -> 0.5849 | W22: =_xlfn.IFNA(VLOOKUP(B22,[2]베타!$A$2:$E$1000,5,FALSE),0) -> 0.5155 | X22: =M22*Q22*U22 -> 0 | Y22: =M22*Q22*V22 -> 0 | Z22: =(P22*M22)-(X22+Y22) -> 0 | AA22: =IF(M22<0, P22-Q22, 0) -> 0 | AB22: =IF(M22>0, Q22*(1-0.2%)-P22, 0) -> 0 | AC22: =AA22/Q22*10000 -> 0 | AD22: =AB22/Q22*10000 -> 0 | AE22: =ABS(N22) -> 0 | AG22: =B22 -> 364970 | AH22: =-1*M22 -> 0 | AJ22: =ROUNDUP(VLOOKUP(B22,[2]베타!$A$2:$L$1000,12,FALSE),0) -> 5 | AK22: =ROUNDUP(VLOOKUP(B22,[2]베타!$A$2:$M$1000,13,FALSE),0) -> -26
B23: 0091P0 | C23: TIGER 코리아원자력 | D23: =VLOOKUP("A"&B23,[2]ETF!$A$4:$M$10000,13,FALSE) -> 50000 | E23: =[1]!'0091P0:VOL'+0 -> 882126 | F23: 019875 | G23: =IF([1]!'019875^0091P0:SELL_TDY_QTY'="NO", 0, [1]!'019875^0091P0:SELL_TDY_QTY') -> 0 | H23: =IF([1]!'019875^0091P0:SELL_TDY_AMT'="NO", 0, [1]!'019875^0091P0:SELL_TDY_AMT') -> 0 | I23: =IFERROR(H23/G23,0) -> 0 | J23: =IF([1]!'019875^0091P0:BUY_TDY_QTY'="NO", 0, [1]!'019875^0091P0:BUY_TDY_QTY') -> 0 | K23: =IF([1]!'019875^0091P0:BUY_TDY_AMT'="NO", 0, [1]!'019875^0091P0:BUY_TDY_AMT') -> 0 | L23: =IFERROR(K23/J23,0) -> 0 | M23: =J23-G23 -> 0 | N23: =M23*P23 -> 0 | O23: =M23/D23 -> 0 | P23: =[1]!'0091P0:LAST' -> 15865 | Q23: =[1]!'0091P0:NAV' -> 15837.74 | R23: =(P23-I23)*-1*G23 -> 0 | S23: =(P23-L23)*J23 -> 0 | T23: =R23+S23 -> 0 | U23: =_xlfn.IFNA(VLOOKUP(B23,[2]베타!$A$2:$C$1000,3,FALSE),0) -> 0.2045 | V23: =_xlfn.IFNA(VLOOKUP(B23,[2]베타!$A$2:$D$1000,4,FALSE),0) -> 0.8173 | W23: =_xlfn.IFNA(VLOOKUP(B23,[2]베타!$A$2:$E$1000,5,FALSE),0) -> 0.6259 | X23: =M23*Q23*U23 -> 0 | Y23: =M23*Q23*V23 -> 0 | Z23: =(P23*M23)-(X23+Y23) -> 0 | AA23: =IF(M23<0, P23-Q23, 0) -> 0 | AB23: =IF(M23>0, Q23*(1-0.2%)-P23, 0) -> 0 | AC23: =AA23/Q23*10000 -> 0 | AD23: =AB23/Q23*10000 -> 0 | AE23: =ABS(N23) -> 0 | AG23: =B23 -> 0091P0 | AH23: =-1*M23 -> 0 | AJ23: =ROUNDUP(VLOOKUP(B23,[2]베타!$A$2:$L$1000,12,FALSE),0) -> 10 | AK23: =ROUNDUP(VLOOKUP(B23,[2]베타!$A$2:$M$1000,13,FALSE),0) -> -31
B24: 292150 | C24: TIGER 코리아TOP10 | D24: =VLOOKUP("A"&B24,[2]ETF!$A$4:$M$10000,13,FALSE) -> 50000 | E24: =[1]!'292150:VOL'+0 -> 311017 | F24: 019875 | G24: =IF([1]!'019875^292150:SELL_TDY_QTY'="NO", 0, [1]!'019875^292150:SELL_TDY_QTY') -> 3783 | H24: =IF([1]!'019875^292150:SELL_TDY_AMT'="NO", 0, [1]!'019875^292150:SELL_TDY_AMT') -> 137718750 | I24: =IFERROR(H24/G24,0) -> 36404.639 | J24: =IF([1]!'019875^292150:BUY_TDY_QTY'="NO", 0, [1]!'019875^292150:BUY_TDY_QTY') -> 3783 | K24: =IF([1]!'019875^292150:BUY_TDY_AMT'="NO", 0, [1]!'019875^292150:BUY_TDY_AMT') -> 138696635 | L24: =IFERROR(K24/J24,0) -> 36663.134 | M24: =J24-G24 -> 0 | N24: =M24*P24 -> 0 | O24: =M24/D24 -> 0 | P24: =[1]!'292150:LAST' -> 36435 | Q24: =[1]!'292150:NAV' -> 36303.57 | R24: =(P24-I24)*-1*G24 -> -114855 | S24: =(P24-L24)*J24 -> -863030 | T24: =R24+S24 -> -977885 | U24: =_xlfn.IFNA(VLOOKUP(B24,[2]베타!$A$2:$C$1000,3,FALSE),0) -> 0.9661 | V24: =_xlfn.IFNA(VLOOKUP(B24,[2]베타!$A$2:$D$1000,4,FALSE),0) -> -0.0116 | W24: =_xlfn.IFNA(VLOOKUP(B24,[2]베타!$A$2:$E$1000,5,FALSE),0) -> 0.9806 | X24: =M24*Q24*U24 -> 0 | Y24: =M24*Q24*V24 -> 0 | Z24: =(P24*M24)-(X24+Y24) -> 0 | AA24: =IF(M24<0, P24-Q24, 0) -> 0 | AB24: =IF(M24>0, Q24*(1-0.2%)-P24, 0) -> 0 | AC24: =AA24/Q24*10000 -> 0 | AD24: =AB24/Q24*10000 -> 0 | AE24: =ABS(N24) -> 0 | AG24: =B24 -> 292150 | AH24: =-1*M24 -> 0 | AJ24: =ROUNDUP(VLOOKUP(B24,[2]베타!$A$2:$L$1000,12,FALSE),0) -> 3 | AK24: =ROUNDUP(VLOOKUP(B24,[2]베타!$A$2:$M$1000,13,FALSE),0) -> -22
B25: 139230 | C25: TIGER 200 중공업 | D25: =VLOOKUP("A"&B25,[2]ETF!$A$4:$M$10000,13,FALSE) -> 20000 | E25: =[1]!'139230:VOL'+0 -> 74681 | F25: 019875 | G25: =IF([1]!'019875^139230:SELL_TDY_QTY'="NO", 0, [1]!'019875^139230:SELL_TDY_QTY') -> 0 | H25: =IF([1]!'019875^139230:SELL_TDY_AMT'="NO", 0, [1]!'019875^139230:SELL_TDY_AMT') -> 0 | I25: =IFERROR(H25/G25,0) -> 0 | J25: =IF([1]!'019875^139230:BUY_TDY_QTY'="NO", 0, [1]!'019875^139230:BUY_TDY_QTY') -> 0 | K25: =IF([1]!'019875^139230:BUY_TDY_AMT'="NO", 0, [1]!'019875^139230:BUY_TDY_AMT') -> 0 | L25: =IFERROR(K25/J25,0) -> 0 | M25: =J25-G25 -> 0 | N25: =M25*P25 -> 0 | O25: =M25/D25 -> 0 | P25: =[1]!'139230:LAST' -> 12270 | Q25: =[1]!'139230:NAV' -> 12317.58 | R25: =(P25-I25)*-1*G25 -> 0 | S25: =(P25-L25)*J25 -> 0 | T25: =R25+S25 -> 0 | U25: =_xlfn.IFNA(VLOOKUP(B25,[2]베타!$A$2:$C$1000,3,FALSE),0) -> 0.2392 | V25: =_xlfn.IFNA(VLOOKUP(B25,[2]베타!$A$2:$D$1000,4,FALSE),0) -> 0.5334 | W25: =_xlfn.IFNA(VLOOKUP(B25,[2]베타!$A$2:$E$1000,5,FALSE),0) -> 0.6099 | X25: =M25*Q25*U25 -> 0 | Y25: =M25*Q25*V25 -> 0 | Z25: =(P25*M25)-(X25+Y25) -> 0 | AA25: =IF(M25<0, P25-Q25, 0) -> 0 | AB25: =IF(M25>0, Q25*(1-0.2%)-P25, 0) -> 0 | AC25: =AA25/Q25*10000 -> 0 | AD25: =AB25/Q25*10000 -> 0 | AE25: =ABS(N25) -> 0 | AG25: =B25 -> 139230 | AH25: =-1*M25 -> 0 | AJ25: =ROUNDUP(VLOOKUP(B25,[2]베타!$A$2:$L$1000,12,FALSE),0) -> 12 | AK25: =ROUNDUP(VLOOKUP(B25,[2]베타!$A$2:$M$1000,13,FALSE),0) -> -29
B26: 364990 | C26: TIGER 게임TOP10 | D26: =VLOOKUP("A"&B26,[2]ETF!$A$4:$M$10000,13,FALSE) -> 50000 | E26: =[1]!'364990:VOL'+0 -> 44650 | F26: 019875 | G26: =IF([1]!'019875^364990:SELL_TDY_QTY'="NO", 0, [1]!'019875^364990:SELL_TDY_QTY') -> 2 | H26: =IF([1]!'019875^364990:SELL_TDY_AMT'="NO", 0, [1]!'019875^364990:SELL_TDY_AMT') -> 9570 | I26: =IFERROR(H26/G26,0) -> 4785 | J26: =IF([1]!'019875^364990:BUY_TDY_QTY'="NO", 0, [1]!'019875^364990:BUY_TDY_QTY') -> 2 | K26: =IF([1]!'019875^364990:BUY_TDY_AMT'="NO", 0, [1]!'019875^364990:BUY_TDY_AMT') -> 9435 | L26: =IFERROR(K26/J26,0) -> 4717.5 | M26: =J26-G26 -> 0 | N26: =M26*P26 -> 0 | O26: =M26/D26 -> 0 | P26: =[1]!'364990:LAST' -> 4720 | Q26: =[1]!'364990:NAV' -> 4703.5 | R26: =(P26-I26)*-1*G26 -> 130 | S26: =(P26-L26)*J26 -> 5 | T26: =R26+S26 -> 135 | U26: =_xlfn.IFNA(VLOOKUP(B26,[2]베타!$A$2:$C$1000,3,FALSE),0) -> -0.076 | V26: =_xlfn.IFNA(VLOOKUP(B26,[2]베타!$A$2:$D$1000,4,FALSE),0) -> 0.328 | W26: =_xlfn.IFNA(VLOOKUP(B26,[2]베타!$A$2:$E$1000,5,FALSE),0) -> 0.1582 | X26: =M26*Q26*U26 -> 0 | Y26: =M26*Q26*V26 -> 0 | Z26: =(P26*M26)-(X26+Y26) -> 0 | AA26: =IF(M26<0, P26-Q26, 0) -> 0 | AB26: =IF(M26>0, Q26*(1-0.2%)-P26, 0) -> 0 | AC26: =AA26/Q26*10000 -> 0 | AD26: =AB26/Q26*10000 -> 0 | AE26: =ABS(N26) -> 0 | AG26: =B26 -> 364990 | AH26: =-1*M26 -> 0 | AJ26: =ROUNDUP(VLOOKUP(B26,[2]베타!$A$2:$L$1000,12,FALSE),0) -> 19 | AK26: =ROUNDUP(VLOOKUP(B26,[2]베타!$A$2:$M$1000,13,FALSE),0) -> -35
B27: 157500 | C27: TIGER 증권 | D27: =VLOOKUP("A"&B27,[2]ETF!$A$4:$M$10000,13,FALSE) -> 20000 | E27: =[1]!'157500:VOL'+0 -> 162504 | F27: 019875 | G27: =IF([1]!'019875^157500:SELL_TDY_QTY'="NO", 0, [1]!'019875^157500:SELL_TDY_QTY') -> 288 | H27: =IF([1]!'019875^157500:SELL_TDY_AMT'="NO", 0, [1]!'019875^157500:SELL_TDY_AMT') -> 3510810 | I27: =IFERROR(H27/G27,0) -> 12190.312 | J27: =IF([1]!'019875^157500:BUY_TDY_QTY'="NO", 0, [1]!'019875^157500:BUY_TDY_QTY') -> 288 | K27: =IF([1]!'019875^157500:BUY_TDY_AMT'="NO", 0, [1]!'019875^157500:BUY_TDY_AMT') -> 3498030 | L27: =IFERROR(K27/J27,0) -> 12145.938 | M27: =J27-G27 -> 0 | N27: =M27*P27 -> 0 | O27: =M27/D27 -> 0 | P27: =[1]!'157500:LAST' -> 12085 | Q27: =[1]!'157500:NAV' -> 12134.26 | R27: =(P27-I27)*-1*G27 -> 30330 | S27: =(P27-L27)*J27 -> -17550 | T27: =R27+S27 -> 12780 | U27: =_xlfn.IFNA(VLOOKUP(B27,[2]베타!$A$2:$C$1000,3,FALSE),0) -> 0.4799 | V27: =_xlfn.IFNA(VLOOKUP(B27,[2]베타!$A$2:$D$1000,4,FALSE),0) -> 0.4054 | W27: =_xlfn.IFNA(VLOOKUP(B27,[2]베타!$A$2:$E$1000,5,FALSE),0) -> 0.6292 | X27: =M27*Q27*U27 -> 0 | Y27: =M27*Q27*V27 -> 0 | Z27: =(P27*M27)-(X27+Y27) -> 0 | AA27: =IF(M27<0, P27-Q27, 0) -> 0 | AB27: =IF(M27>0, Q27*(1-0.2%)-P27, 0) -> 0 | AC27: =AA27/Q27*10000 -> 0 | AD27: =AB27/Q27*10000 -> 0 | AE27: =ABS(N27) -> 0 | AG27: =B27 -> 157500 | AH27: =-1*M27 -> 0 | AJ27: =ROUNDUP(VLOOKUP(B27,[2]베타!$A$2:$L$1000,12,FALSE),0) -> 6 | AK27: =ROUNDUP(VLOOKUP(B27,[2]베타!$A$2:$M$1000,13,FALSE),0) -> -30
B28: 228810 | C28: TIGER 미디어컨텐츠 | D28: =VLOOKUP("A"&B28,[2]ETF!$A$4:$M$10000,13,FALSE) -> 30000 | E28: =[1]!'228810:VOL'+0 -> 214125 | F28: 019875 | G28: =IF([1]!'019875^228810:SELL_TDY_QTY'="NO", 0, [1]!'019875^228810:SELL_TDY_QTY') -> 1531 | H28: =IF([1]!'019875^228810:SELL_TDY_AMT'="NO", 0, [1]!'019875^228810:SELL_TDY_AMT') -> 4726290 | I28: =IFERROR(H28/G28,0) -> 3087.0607 | J28: =IF([1]!'019875^228810:BUY_TDY_QTY'="NO", 0, [1]!'019875^228810:BUY_TDY_QTY') -> 1531 | K28: =IF([1]!'019875^228810:BUY_TDY_AMT'="NO", 0, [1]!'019875^228810:BUY_TDY_AMT') -> 4816365 | L28: =IFERROR(K28/J28,0) -> 3145.8948 | M28: =J28-G28 -> 0 | N28: =M28*P28 -> 0 | O28: =M28/D28 -> 0 | P28: =[1]!'228810:LAST' -> 3060 | Q28: =[1]!'228810:NAV' -> 3067.95 | R28: =(P28-I28)*-1*G28 -> 41430 | S28: =(P28-L28)*J28 -> -131505 | T28: =R28+S28 -> -90075 | U28: =_xlfn.IFNA(VLOOKUP(B28,[2]베타!$A$2:$C$1000,3,FALSE),0) -> -0.1847 | V28: =_xlfn.IFNA(VLOOKUP(B28,[2]베타!$A$2:$D$1000,4,FALSE),0) -> 0.6912 | W28: =_xlfn.IFNA(VLOOKUP(B28,[2]베타!$A$2:$E$1000,5,FALSE),0) -> 0.5385 | X28: =M28*Q28*U28 -> 0 | Y28: =M28*Q28*V28 -> 0 | Z28: =(P28*M28)-(X28+Y28) -> 0 | AA28: =IF(M28<0, P28-Q28, 0) -> 0 | AB28: =IF(M28>0, Q28*(1-0.2%)-P28, 0) -> 0 | AC28: =AA28/Q28*10000 -> 0 | AD28: =AB28/Q28*10000 -> 0 | AE28: =ABS(N28) -> 0 | AG28: =B28 -> 228810 | AH28: =-1*M28 -> 0 | AJ28: =ROUNDUP(VLOOKUP(B28,[2]베타!$A$2:$L$1000,12,FALSE),0) -> 20 | AK28: =ROUNDUP(VLOOKUP(B28,[2]베타!$A$2:$M$1000,13,FALSE),0) -> -33
B29: 472150 | C29: TIGER 배당커버드콜액티브 | D29: =VLOOKUP("A"&B29,[2]ETF!$A$4:$M$10000,13,FALSE) -> 10000 | E29: =[1]!'472150:VOL'+0 -> 3489279 | F29: 019870 | G29: =IF([1]!'019870^472150:SELL_TDY_QTY'="NO", 0, [1]!'019870^472150:SELL_TDY_QTY') -> 3619 | H29: =IF([1]!'019870^472150:SELL_TDY_AMT'="NO", 0, [1]!'019870^472150:SELL_TDY_AMT') -> 70494880 | I29: =IFERROR(H29/G29,0) -> 19479.105 | J29: =IF([1]!'019870^472150:BUY_TDY_QTY'="NO", 0, [1]!'019870^472150:BUY_TDY_QTY') -> 3619 | K29: =IF([1]!'019870^472150:BUY_TDY_AMT'="NO", 0, [1]!'019870^472150:BUY_TDY_AMT') -> 70823770 | L29: =IFERROR(K29/J29,0) -> 19569.983 | M29: =J29-G29 -> 0 | N29: =M29*P29 -> 0 | O29: =M29/D29 -> 0 | P29: =[1]!'472150:LAST' -> 19420 | Q29: =[1]!'472150:NAV' -> 19416.42 | R29: =(P29-I29)*-1*G29 -> 213900 | S29: =(P29-L29)*J29 -> -542790 | T29: =R29+S29 -> -328890 | U29: =_xlfn.IFNA(VLOOKUP(B29,[2]베타!$A$2:$C$1000,3,FALSE),0) -> 0.9804 | V29: =_xlfn.IFNA(VLOOKUP(B29,[2]베타!$A$2:$D$1000,4,FALSE),0) -> -0.0008 | W29: =_xlfn.IFNA(VLOOKUP(B29,[2]베타!$A$2:$E$1000,5,FALSE),0) -> 0.9862 | X29: =M29*Q29*U29 -> 0 | Y29: =M29*Q29*V29 -> 0 | Z29: =(P29*M29)-(X29+Y29) -> 0 | AA29: =IF(M29<0, P29-Q29, 0) -> 0 | AB29: =IF(M29>0, Q29*(1-0.2%)-P29, 0) -> 0 | AC29: =AA29/Q29*10000 -> 0 | AD29: =AB29/Q29*10000 -> 0 | AE29: =ABS(N29) -> 0 | AG29: =B29 -> 472150 | AH29: =-1*M29 -> 0 | AJ29: =ROUNDUP(VLOOKUP(B29,[2]베타!$A$2:$L$1000,12,FALSE),0) -> 11 | AK29: =ROUNDUP(VLOOKUP(B29,[2]베타!$A$2:$M$1000,13,FALSE),0) -> -15
B30: 307520 | C30: TIGER 지주회사 | D30: =VLOOKUP("A"&B30,[2]ETF!$A$4:$M$10000,13,FALSE) -> 50000 | E30: =[1]!'307520:VOL'+0 -> 212505 | F30: 019875 | G30: =IF([1]!'019875^307520:SELL_TDY_QTY'="NO", 0, [1]!'019875^307520:SELL_TDY_QTY') -> 16 | H30: =IF([1]!'019875^307520:SELL_TDY_AMT'="NO", 0, [1]!'019875^307520:SELL_TDY_AMT') -> 352265 | I30: =IFERROR(H30/G30,0) -> 22016.562 | J30: =IF([1]!'019875^307520:BUY_TDY_QTY'="NO", 0, [1]!'019875^307520:BUY_TDY_QTY') -> 16 | K30: =IF([1]!'019875^307520:BUY_TDY_AMT'="NO", 0, [1]!'019875^307520:BUY_TDY_AMT') -> 351560 | L30: =IFERROR(K30/J30,0) -> 21972.5 | M30: =J30-G30 -> 0 | N30: =M30*P30 -> 0 | O30: =M30/D30 -> 0 | P30: =[1]!'307520:LAST' -> 21895 | Q30: =[1]!'307520:NAV' -> 21955.81 | R30: =(P30-I30)*-1*G30 -> 1945 | S30: =(P30-L30)*J30 -> -1240 | T30: =R30+S30 -> 705 | U30: =_xlfn.IFNA(VLOOKUP(B30,[2]베타!$A$2:$C$1000,3,FALSE),0) -> 0.3637 | V30: =_xlfn.IFNA(VLOOKUP(B30,[2]베타!$A$2:$D$1000,4,FALSE),0) -> 0.3803 | W30: =_xlfn.IFNA(VLOOKUP(B30,[2]베타!$A$2:$E$1000,5,FALSE),0) -> 0.7504 | X30: =M30*Q30*U30 -> 0 | Y30: =M30*Q30*V30 -> 0 | Z30: =(P30*M30)-(X30+Y30) -> 0 | AA30: =IF(M30<0, P30-Q30, 0) -> 0 | AB30: =IF(M30>0, Q30*(1-0.2%)-P30, 0) -> 0 | AC30: =AA30/Q30*10000 -> 0 | AD30: =AB30/Q30*10000 -> 0 | AE30: =ABS(N30) -> 0 | AG30: =B30 -> 307520 | AH30: =-1*M30 -> 0 | AJ30: =ROUNDUP(VLOOKUP(B30,[2]베타!$A$2:$L$1000,12,FALSE),0) -> 5 | AK30: =ROUNDUP(VLOOKUP(B30,[2]베타!$A$2:$M$1000,13,FALSE),0) -> -30
B31: 157490 | C31: TIGER 소프트웨어 | D31: =VLOOKUP("A"&B31,[2]ETF!$A$4:$M$10000,13,FALSE) -> 20000 | E31: =[1]!'157490:VOL'+0 -> 119543 | F31: 019875 | G31: =IF([1]!'019875^157490:SELL_TDY_QTY'="NO", 0, [1]!'019875^157490:SELL_TDY_QTY') -> 1356 | H31: =IF([1]!'019875^157490:SELL_TDY_AMT'="NO", 0, [1]!'019875^157490:SELL_TDY_AMT') -> 11287817 | I31: =IFERROR(H31/G31,0) -> 8324.3488 | J31: =IF([1]!'019875^157490:BUY_TDY_QTY'="NO", 0, [1]!'019875^157490:BUY_TDY_QTY') -> 1356 | K31: =IF([1]!'019875^157490:BUY_TDY_AMT'="NO", 0, [1]!'019875^157490:BUY_TDY_AMT') -> 11265965 | L31: =IFERROR(K31/J31,0) -> 8308.2338 | M31: =J31-G31 -> 0 | N31: =M31*P31 -> 0 | O31: =M31/D31 -> 0 | P31: =[1]!'157490:LAST' -> 8315 | Q31: =[1]!'157490:NAV' -> 8289.43 | R31: =(P31-I31)*-1*G31 -> 12677 | S31: =(P31-L31)*J31 -> 9175 | T31: =R31+S31 -> 21852 | U31: =_xlfn.IFNA(VLOOKUP(B31,[2]베타!$A$2:$C$1000,3,FALSE),0) -> 0.1859 | V31: =_xlfn.IFNA(VLOOKUP(B31,[2]베타!$A$2:$D$1000,4,FALSE),0) -> 0.2998 | W31: =_xlfn.IFNA(VLOOKUP(B31,[2]베타!$A$2:$E$1000,5,FALSE),0) -> 0.3632 | X31: =M31*Q31*U31 -> 0 | Y31: =M31*Q31*V31 -> 0 | Z31: =(P31*M31)-(X31+Y31) -> 0 | AA31: =IF(M31<0, P31-Q31, 0) -> 0 | AB31: =IF(M31>0, Q31*(1-0.2%)-P31, 0) -> 0 | AC31: =AA31/Q31*10000 -> 0 | AD31: =AB31/Q31*10000 -> 0 | AE31: =ABS(N31) -> 0 | AG31: =B31 -> 157490 | AH31: =-1*M31 -> 0 | AJ31: =ROUNDUP(VLOOKUP(B31,[2]베타!$A$2:$L$1000,12,FALSE),0) -> 11 | AK31: =ROUNDUP(VLOOKUP(B31,[2]베타!$A$2:$M$1000,13,FALSE),0) -> -33
B32: 471760 | C32: TIGER AI반도체핵심공정 | D32: =VLOOKUP("A"&B32,[2]ETF!$A$4:$M$10000,13,FALSE) -> 50000 | E32: =[1]!'471760:VOL'+0 -> 645031 | F32: 019875 | G32: =IF([1]!'019875^471760:SELL_TDY_QTY'="NO", 0, [1]!'019875^471760:SELL_TDY_QTY') -> 1921 | H32: =IF([1]!'019875^471760:SELL_TDY_AMT'="NO", 0, [1]!'019875^471760:SELL_TDY_AMT') -> 27119665 | I32: =IFERROR(H32/G32,0) -> 14117.473 | J32: =IF([1]!'019875^471760:BUY_TDY_QTY'="NO", 0, [1]!'019875^471760:BUY_TDY_QTY') -> 1921 | K32: =IF([1]!'019875^471760:BUY_TDY_AMT'="NO", 0, [1]!'019875^471760:BUY_TDY_AMT') -> 27435130 | L32: =IFERROR(K32/J32,0) -> 14281.692 | M32: =J32-G32 -> 0 | N32: =M32*P32 -> 0 | O32: =M32/D32 -> 0 | P32: =[1]!'471760:LAST' -> 14100 | Q32: =[1]!'471760:NAV' -> 14143.47 | R32: =(P32-I32)*-1*G32 -> 33565 | S32: =(P32-L32)*J32 -> -349030 | T32: =R32+S32 -> -315465 | U32: =_xlfn.IFNA(VLOOKUP(B32,[2]베타!$A$2:$C$1000,3,FALSE),0) -> 0.5112 | V32: =_xlfn.IFNA(VLOOKUP(B32,[2]베타!$A$2:$D$1000,4,FALSE),0) -> 0.8111 | W32: =_xlfn.IFNA(VLOOKUP(B32,[2]베타!$A$2:$E$1000,5,FALSE),0) -> 0.7985 | X32: =M32*Q32*U32 -> 0 | Y32: =M32*Q32*V32 -> 0 | Z32: =(P32*M32)-(X32+Y32) -> 0 | AA32: =IF(M32<0, P32-Q32, 0) -> 0 | AB32: =IF(M32>0, Q32*(1-0.2%)-P32, 0) -> 0 | AC32: =AA32/Q32*10000 -> 0 | AD32: =AB32/Q32*10000 -> 0 | AE32: =ABS(N32) -> 0 | AG32: =B32 -> 471760 | AH32: =-1*M32 -> 0 | AJ32: =ROUNDUP(VLOOKUP(B32,[2]베타!$A$2:$L$1000,12,FALSE),0) -> 7 | AK32: =ROUNDUP(VLOOKUP(B32,[2]베타!$A$2:$M$1000,13,FALSE),0) -> -30
B33: 0052D0 | C33: TIGER 코리아배당다우존스 | D33: =VLOOKUP("A"&B33,[2]ETF!$A$4:$M$10000,13,FALSE) -> 50000 | E33: =[1]!'0052D0:VOL'+0 -> 70523 | F33: 019875 | G33: =IF([1]!'019875^0052D0:SELL_TDY_QTY'="NO", 0, [1]!'019875^0052D0:SELL_TDY_QTY') -> 280 | H33: =IF([1]!'019875^0052D0:SELL_TDY_AMT'="NO", 0, [1]!'019875^0052D0:SELL_TDY_AMT') -> 4361740 | I33: =IFERROR(H33/G33,0) -> 15577.643 | J33: =IF([1]!'019875^0052D0:BUY_TDY_QTY'="NO", 0, [1]!'019875^0052D0:BUY_TDY_QTY') -> 280 | K33: =IF([1]!'019875^0052D0:BUY_TDY_AMT'="NO", 0, [1]!'019875^0052D0:BUY_TDY_AMT') -> 4343975 | L33: =IFERROR(K33/J33,0) -> 15514.196 | M33: =J33-G33 -> 0 | N33: =M33*P33 -> 0 | O33: =M33/D33 -> 0 | P33: =[1]!'0052D0:LAST' -> 15405 | Q33: =[1]!'0052D0:NAV' -> 15502.57 | R33: =(P33-I33)*-1*G33 -> 48340 | S33: =(P33-L33)*J33 -> -30575 | T33: =R33+S33 -> 17765 | U33: =_xlfn.IFNA(VLOOKUP(B33,[2]베타!$A$2:$C$1000,3,FALSE),0) -> 0.1038 | V33: =_xlfn.IFNA(VLOOKUP(B33,[2]베타!$A$2:$D$1000,4,FALSE),0) -> 0.2279 | W33: =_xlfn.IFNA(VLOOKUP(B33,[2]베타!$A$2:$E$1000,5,FALSE),0) -> 0.4037 | X33: =M33*Q33*U33 -> 0 | Y33: =M33*Q33*V33 -> 0 | Z33: =(P33*M33)-(X33+Y33) -> 0 | AA33: =IF(M33<0, P33-Q33, 0) -> 0 | AB33: =IF(M33>0, Q33*(1-0.2%)-P33, 0) -> 0 | AC33: =AA33/Q33*10000 -> 0 | AD33: =AB33/Q33*10000 -> 0 | AE33: =ABS(N33) -> 0 | AG33: =B33 -> 0052D0 | AH33: =-1*M33 -> 0 | AJ33: =ROUNDUP(VLOOKUP(B33,[2]베타!$A$2:$L$1000,12,FALSE),0) -> 6 | AK33: =ROUNDUP(VLOOKUP(B33,[2]베타!$A$2:$M$1000,13,FALSE),0) -> -23
B34: 466940 | C34: TIGER 은행고배당플러스TOP10 | D34: =VLOOKUP("A"&B34,[2]ETF!$A$4:$M$10000,13,FALSE) -> 50000 | E34: =[1]!'466940:VOL'+0 -> 848870 | F34: 019875 | G34: =IF([1]!'019875^466940:SELL_TDY_QTY'="NO", 0, [1]!'019875^466940:SELL_TDY_QTY') -> 6383 | H34: =IF([1]!'019875^466940:SELL_TDY_AMT'="NO", 0, [1]!'019875^466940:SELL_TDY_AMT') -> 173165013 | I34: =IFERROR(H34/G34,0) -> 27129.095 | J34: =IF([1]!'019875^466940:BUY_TDY_QTY'="NO", 0, [1]!'019875^466940:BUY_TDY_QTY') -> 6383 | K34: =IF([1]!'019875^466940:BUY_TDY_AMT'="NO", 0, [1]!'019875^466940:BUY_TDY_AMT') -> 172349100 | L34: =IFERROR(K34/J34,0) -> 27001.269 | M34: =J34-G34 -> 0 | N34: =M34*P34 -> 0 | O34: =M34/D34 -> 0 | P34: =[1]!'466940:LAST' -> 26700 | Q34: =[1]!'466940:NAV' -> 26848.59 | R34: =(P34-I34)*-1*G34 -> 2738913 | S34: =(P34-L34)*J34 -> -1923000 | T34: =R34+S34 -> 815913 | U34: =_xlfn.IFNA(VLOOKUP(B34,[2]베타!$A$2:$C$1000,3,FALSE),0) -> 0.1052 | V34: =_xlfn.IFNA(VLOOKUP(B34,[2]베타!$A$2:$D$1000,4,FALSE),0) -> 0.1725 | W34: =_xlfn.IFNA(VLOOKUP(B34,[2]베타!$A$2:$E$1000,5,FALSE),0) -> 0.2584 | X34: =M34*Q34*U34 -> 0 | Y34: =M34*Q34*V34 -> 0 | Z34: =(P34*M34)-(X34+Y34) -> 0 | AA34: =IF(M34<0, P34-Q34, 0) -> 0 | AB34: =IF(M34>0, Q34*(1-0.2%)-P34, 0) -> 0 | AC34: =AA34/Q34*10000 -> 0 | AD34: =AB34/Q34*10000 -> 0 | AE34: =ABS(N34) -> 0 | AG34: =B34 -> 466940 | AH34: =-1*M34 -> 0 | AJ34: =ROUNDUP(VLOOKUP(B34,[2]베타!$A$2:$L$1000,12,FALSE),0) -> 4 | AK34: =ROUNDUP(VLOOKUP(B34,[2]베타!$A$2:$M$1000,13,FALSE),0) -> -22
B35: 139220 | C35: TIGER 200 건설 | D35: =VLOOKUP("A"&B35,[2]ETF!$A$4:$M$10000,13,FALSE) -> 20000 | E35: =[1]!'139220:VOL'+0 -> 343723 | F35: 019875 | G35: =IF([1]!'019875^139220:SELL_TDY_QTY'="NO", 0, [1]!'019875^139220:SELL_TDY_QTY') -> 0 | H35: =IF([1]!'019875^139220:SELL_TDY_AMT'="NO", 0, [1]!'019875^139220:SELL_TDY_AMT') -> 0 | I35: =IFERROR(H35/G35,0) -> 0 | J35: =IF([1]!'019875^139220:BUY_TDY_QTY'="NO", 0, [1]!'019875^139220:BUY_TDY_QTY') -> 0 | K35: =IF([1]!'019875^139220:BUY_TDY_AMT'="NO", 0, [1]!'019875^139220:BUY_TDY_AMT') -> 0 | L35: =IFERROR(K35/J35,0) -> 0 | M35: =J35-G35 -> 0 | N35: =M35*P35 -> 0 | O35: =M35/D35 -> 0 | P35: =[1]!'139220:LAST' -> 7375 | Q35: =[1]!'139220:NAV' -> 7400.53 | R35: =(P35-I35)*-1*G35 -> 0 | S35: =(P35-L35)*J35 -> 0 | T35: =R35+S35 -> 0 | U35: =_xlfn.IFNA(VLOOKUP(B35,[2]베타!$A$2:$C$1000,3,FALSE),0) -> 0.4238 | V35: =_xlfn.IFNA(VLOOKUP(B35,[2]베타!$A$2:$D$1000,4,FALSE),0) -> 0.5168 | W35: =_xlfn.IFNA(VLOOKUP(B35,[2]베타!$A$2:$E$1000,5,FALSE),0) -> 0.6182 | X35: =M35*Q35*U35 -> 0 | Y35: =M35*Q35*V35 -> 0 | Z35: =(P35*M35)-(X35+Y35) -> 0 | AA35: =IF(M35<0, P35-Q35, 0) -> 0 | AB35: =IF(M35>0, Q35*(1-0.2%)-P35, 0) -> 0 | AC35: =AA35/Q35*10000 -> 0 | AD35: =AB35/Q35*10000 -> 0 | AE35: =ABS(N35) -> 0 | AG35: =B35 -> 139220 | AH35: =-1*M35 -> 0 | AJ35: =ROUNDUP(VLOOKUP(B35,[2]베타!$A$2:$L$1000,12,FALSE),0) -> 12 | AK35: =ROUNDUP(VLOOKUP(B35,[2]베타!$A$2:$M$1000,13,FALSE),0) -> -32
B36: 365000 | C36: TIGER 인터넷TOP10 | D36: =VLOOKUP("A"&B36,[2]ETF!$A$4:$M$10000,13,FALSE) -> 50000 | E36: =[1]!'365000:VOL'+0 -> 134165 | F36: 019875 | G36: =IF([1]!'019875^365000:SELL_TDY_QTY'="NO", 0, [1]!'019875^365000:SELL_TDY_QTY') -> 30 | H36: =IF([1]!'019875^365000:SELL_TDY_AMT'="NO", 0, [1]!'019875^365000:SELL_TDY_AMT') -> 106825 | I36: =IFERROR(H36/G36,0) -> 3560.8333 | J36: =IF([1]!'019875^365000:BUY_TDY_QTY'="NO", 0, [1]!'019875^365000:BUY_TDY_QTY') -> 30 | K36: =IF([1]!'019875^365000:BUY_TDY_AMT'="NO", 0, [1]!'019875^365000:BUY_TDY_AMT') -> 105470 | L36: =IFERROR(K36/J36,0) -> 3515.6667 | M36: =J36-G36 -> 0 | N36: =M36*P36 -> 0 | O36: =M36/D36 -> 0 | P36: =[1]!'365000:LAST' -> 3505 | Q36: =[1]!'365000:NAV' -> 3503.91 | R36: =(P36-I36)*-1*G36 -> 1675 | S36: =(P36-L36)*J36 -> -320 | T36: =R36+S36 -> 1355 | U36: =_xlfn.IFNA(VLOOKUP(B36,[2]베타!$A$2:$C$1000,3,FALSE),0) -> 0.0803 | V36: =_xlfn.IFNA(VLOOKUP(B36,[2]베타!$A$2:$D$1000,4,FALSE),0) -> 0.506 | W36: =_xlfn.IFNA(VLOOKUP(B36,[2]베타!$A$2:$E$1000,5,FALSE),0) -> 0.5622 | X36: =M36*Q36*U36 -> 0 | Y36: =M36*Q36*V36 -> 0 | Z36: =(P36*M36)-(X36+Y36) -> 0 | AA36: =IF(M36<0, P36-Q36, 0) -> 0 | AB36: =IF(M36>0, Q36*(1-0.2%)-P36, 0) -> 0 | AC36: =AA36/Q36*10000 -> 0 | AD36: =AB36/Q36*10000 -> 0 | AE36: =ABS(N36) -> 0 | AG36: =B36 -> 365000 | AH36: =-1*M36 -> 0 | AJ36: =ROUNDUP(VLOOKUP(B36,[2]베타!$A$2:$L$1000,12,FALSE),0) -> 17 | AK36: =ROUNDUP(VLOOKUP(B36,[2]베타!$A$2:$M$1000,13,FALSE),0) -> -38
B37: 228800 | C37: TIGER 여행레저 | D37: =VLOOKUP("A"&B37,[2]ETF!$A$4:$M$10000,13,FALSE) -> 30000 | E37: =[1]!'228800:VOL'+0 -> 146441 | F37: 019875 | G37: =IF([1]!'019875^228800:SELL_TDY_QTY'="NO", 0, [1]!'019875^228800:SELL_TDY_QTY') -> 1177 | H37: =IF([1]!'019875^228800:SELL_TDY_AMT'="NO", 0, [1]!'019875^228800:SELL_TDY_AMT') -> 3209970 | I37: =IFERROR(H37/G37,0) -> 2727.2472 | J37: =IF([1]!'019875^228800:BUY_TDY_QTY'="NO", 0, [1]!'019875^228800:BUY_TDY_QTY') -> 1177 | K37: =IF([1]!'019875^228800:BUY_TDY_AMT'="NO", 0, [1]!'019875^228800:BUY_TDY_AMT') -> 3195555 | L37: =IFERROR(K37/J37,0) -> 2715 | M37: =J37-G37 -> 0 | N37: =M37*P37 -> 0 | O37: =M37/D37 -> 0 | P37: =[1]!'228800:LAST' -> 2705 | Q37: =[1]!'228800:NAV' -> 2711.55 | R37: =(P37-I37)*-1*G37 -> 26185 | S37: =(P37-L37)*J37 -> -11770 | T37: =R37+S37 -> 14415 | U37: =_xlfn.IFNA(VLOOKUP(B37,[2]베타!$A$2:$C$1000,3,FALSE),0) -> -0.0175 | V37: =_xlfn.IFNA(VLOOKUP(B37,[2]베타!$A$2:$D$1000,4,FALSE),0) -> 0.375 | W37: =_xlfn.IFNA(VLOOKUP(B37,[2]베타!$A$2:$E$1000,5,FALSE),0) -> 0.3333 | X37: =M37*Q37*U37 -> 0 | Y37: =M37*Q37*V37 -> 0 | Z37: =(P37*M37)-(X37+Y37) -> 0 | AA37: =IF(M37<0, P37-Q37, 0) -> 0 | AB37: =IF(M37>0, Q37*(1-0.2%)-P37, 0) -> 0 | AC37: =AA37/Q37*10000 -> 0 | AD37: =AB37/Q37*10000 -> 0 | AE37: =ABS(N37) -> 0 | AG37: =B37 -> 228800 | AH37: =-1*M37 -> 0 | AJ37: =ROUNDUP(VLOOKUP(B37,[2]베타!$A$2:$L$1000,12,FALSE),0) -> 18 | AK37: =ROUNDUP(VLOOKUP(B37,[2]베타!$A$2:$M$1000,13,FALSE),0) -> -32
B38: 138540 | C38: TIGER 현대차그룹플러스 | D38: =VLOOKUP("A"&B38,[2]ETF!$A$4:$M$10000,13,FALSE) -> 20000 | E38: =[1]!'138540:VOL'+0 -> 130510 | F38: 019875 | G38: =IF([1]!'019875^138540:SELL_TDY_QTY'="NO", 0, [1]!'019875^138540:SELL_TDY_QTY') -> 669 | H38: =IF([1]!'019875^138540:SELL_TDY_AMT'="NO", 0, [1]!'019875^138540:SELL_TDY_AMT') -> 32521825 | I38: =IFERROR(H38/G38,0) -> 48612.593 | J38: =IF([1]!'019875^138540:BUY_TDY_QTY'="NO", 0, [1]!'019875^138540:BUY_TDY_QTY') -> 669 | K38: =IF([1]!'019875^138540:BUY_TDY_AMT'="NO", 0, [1]!'019875^138540:BUY_TDY_AMT') -> 32922975 | L38: =IFERROR(K38/J38,0) -> 49212.22 | M38: =J38-G38 -> 0 | N38: =M38*P38 -> 0 | O38: =M38/D38 -> 0 | P38: =[1]!'138540:LAST' -> 48310 | Q38: =[1]!'138540:NAV' -> 48463.96 | R38: =(P38-I38)*-1*G38 -> 202435 | S38: =(P38-L38)*J38 -> -603585 | T38: =R38+S38 -> -401150 | U38: =_xlfn.IFNA(VLOOKUP(B38,[2]베타!$A$2:$C$1000,3,FALSE),0) -> 0.3759 | V38: =_xlfn.IFNA(VLOOKUP(B38,[2]베타!$A$2:$D$1000,4,FALSE),0) -> 0.293 | W38: =_xlfn.IFNA(VLOOKUP(B38,[2]베타!$A$2:$E$1000,5,FALSE),0) -> 0.5372 | X38: =M38*Q38*U38 -> 0 | Y38: =M38*Q38*V38 -> 0 | Z38: =(P38*M38)-(X38+Y38) -> 0 | AA38: =IF(M38<0, P38-Q38, 0) -> 0 | AB38: =IF(M38>0, Q38*(1-0.2%)-P38, 0) -> 0 | AC38: =AA38/Q38*10000 -> 0 | AD38: =AB38/Q38*10000 -> 0 | AG38: =B38 -> 138540 | AH38: =-1*M38 -> 0 | AJ38: =ROUNDUP(VLOOKUP(B38,[2]베타!$A$2:$L$1000,12,FALSE),0) -> 5 | AK38: =ROUNDUP(VLOOKUP(B38,[2]베타!$A$2:$M$1000,13,FALSE),0) -> -24
B39: 377990 | C39: TIGER Fn신재생에너지 | D39: =VLOOKUP("A"&B39,[2]ETF!$A$4:$M$10000,13,FALSE) -> 50000 | E39: =[1]!'377990:VOL'+0 -> 81848 | F39: 019875 | G39: =IF([1]!'019875^377990:SELL_TDY_QTY'="NO", 0, [1]!'019875^377990:SELL_TDY_QTY') -> 1 | H39: =IF([1]!'019875^377990:SELL_TDY_AMT'="NO", 0, [1]!'019875^377990:SELL_TDY_AMT') -> 23940 | I39: =IFERROR(H39/G39,0) -> 23940 | J39: =IF([1]!'019875^377990:BUY_TDY_QTY'="NO", 0, [1]!'019875^377990:BUY_TDY_QTY') -> 1 | K39: =IF([1]!'019875^377990:BUY_TDY_AMT'="NO", 0, [1]!'019875^377990:BUY_TDY_AMT') -> 23360 | L39: =IFERROR(K39/J39,0) -> 23360 | M39: =J39-G39 -> 0 | N39: =M39*P39 -> 0 | O39: =M39/D39 -> 0 | P39: =[1]!'377990:LAST' -> 23135 | Q39: =[1]!'377990:NAV' -> 23201.63 | R39: =(P39-I39)*-1*G39 -> 805 | S39: =(P39-L39)*J39 -> -225 | T39: =R39+S39 -> 580 | U39: =_xlfn.IFNA(VLOOKUP(B39,[2]베타!$A$2:$C$1000,3,FALSE),0) -> 0.2013 | V39: =_xlfn.IFNA(VLOOKUP(B39,[2]베타!$A$2:$D$1000,4,FALSE),0) -> 0.8172 | W39: =_xlfn.IFNA(VLOOKUP(B39,[2]베타!$A$2:$E$1000,5,FALSE),0) -> 0.6391 | X39: =M39*Q39*U39 -> 0 | Y39: =M39*Q39*V39 -> 0 | Z39: =(P39*M39)-(X39+Y39) -> 0 | AA39: =IF(M39<0, P39-Q39, 0) -> 0 | AB39: =IF(M39>0, Q39*(1-0.2%)-P39, 0) -> 0 | AC39: =AA39/Q39*10000 -> 0 | AD39: =AB39/Q39*10000 -> 0 | AE39: =ABS(N39) -> 0 | AG39: =B39 -> 377990 | AH39: =-1*M39 -> 0 | AJ39: =ROUNDUP(VLOOKUP(B39,[2]베타!$A$2:$L$1000,12,FALSE),0) -> 10 | AK39: =ROUNDUP(VLOOKUP(B39,[2]베타!$A$2:$M$1000,13,FALSE),0) -> -30
B40: 395270 | C40: HANARO Fn K-반도체 | D40: =VLOOKUP("A"&B40,[2]ETF!$A$4:$M$10000,13,FALSE) -> 50000 | E40: =[1]!'395270:VOL'+0 -> 904189 | F40: 019875 | G40: =IF([1]!'019875^395270:SELL_TDY_QTY'="NO", 0, [1]!'019875^395270:SELL_TDY_QTY') -> 5293 | H40: =IF([1]!'019875^395270:SELL_TDY_AMT'="NO", 0, [1]!'019875^395270:SELL_TDY_AMT') -> 285275550 | I40: =IFERROR(H40/G40,0) -> 53896.76 | J40: =IF([1]!'019875^395270:BUY_TDY_QTY'="NO", 0, [1]!'019875^395270:BUY_TDY_QTY') -> 5293 | K40: =IF([1]!'019875^395270:BUY_TDY_AMT'="NO", 0, [1]!'019875^395270:BUY_TDY_AMT') -> 285914745 | L40: =IFERROR(K40/J40,0) -> 54017.522 | M40: =J40-G40 -> 0 | N40: =M40*P40 -> 0 | O40: =M40/D40 -> 0 | P40: =[1]!'395270:LAST' -> 53370 | Q40: =[1]!'395270:NAV' -> 53452.78 | R40: =(P40-I40)*-1*G40 -> 2788140 | S40: =(P40-L40)*J40 -> -3427335 | T40: =R40+S40 -> -639195 | U40: =_xlfn.IFNA(VLOOKUP(B40,[2]베타!$A$2:$C$1000,3,FALSE),0) -> 1.1755 | V40: =_xlfn.IFNA(VLOOKUP(B40,[2]베타!$A$2:$D$1000,4,FALSE),0) -> 0.0971 | W40: =_xlfn.IFNA(VLOOKUP(B40,[2]베타!$A$2:$E$1000,5,FALSE),0) -> 0.9138 | X40: =M40*Q40*U40 -> 0 | Y40: =M40*Q40*V40 -> 0 | Z40: =(P40*M40)-(X40+Y40) -> 0 | AA40: =IF(M40<0, P40-Q40, 0) -> 0 | AB40: =IF(M40>0, Q40*(1-0.2%)-P40, 0) -> 0 | AC40: =AA40/Q40*10000 -> 0 | AD40: =AB40/Q40*10000 -> 0 | AE40: =ABS(N40) -> 0 | AG40: =B40 -> 395270 | AH40: =-1*M40 -> 0 | AJ40: =ROUNDUP(VLOOKUP(B40,[2]베타!$A$2:$L$1000,12,FALSE),0) -> 2 | AK40: =ROUNDUP(VLOOKUP(B40,[2]베타!$A$2:$M$1000,13,FALSE),0) -> -23
B41: 091220 | C41: TIGER 은행 | D41: =VLOOKUP("A"&B41,[2]ETF!$A$4:$M$10000,13,FALSE) -> 20000 | E41: =[1]!'091220:VOL'+0 -> 94118 | F41: 019875 | G41: =IF([1]!'019875^091220:SELL_TDY_QTY'="NO", 0, [1]!'019875^091220:SELL_TDY_QTY') -> 0 | H41: =IF([1]!'019875^091220:SELL_TDY_AMT'="NO", 0, [1]!'019875^091220:SELL_TDY_AMT') -> 0 | I41: =IFERROR(H41/G41,0) -> 0 | J41: =IF([1]!'019875^091220:BUY_TDY_QTY'="NO", 0, [1]!'019875^091220:BUY_TDY_QTY') -> 0 | K41: =IF([1]!'019875^091220:BUY_TDY_AMT'="NO", 0, [1]!'019875^091220:BUY_TDY_AMT') -> 0 | L41: =IFERROR(K41/J41,0) -> 0 | M41: =J41-G41 -> 0 | N41: =M41*P41 -> 0 | O41: =M41/D41 -> 0 | P41: =[1]!'091220:LAST' -> 17065 | Q41: =[1]!'091220:NAV' -> 17140.77 | R41: =(P41-I41)*-1*G41 -> 0 | S41: =(P41-L41)*J41 -> 0 | T41: =R41+S41 -> 0 | U41: =_xlfn.IFNA(VLOOKUP(B41,[2]베타!$A$2:$C$1000,3,FALSE),0) -> 0.0486 | V41: =_xlfn.IFNA(VLOOKUP(B41,[2]베타!$A$2:$D$1000,4,FALSE),0) -> 0.2094 | W41: =_xlfn.IFNA(VLOOKUP(B41,[2]베타!$A$2:$E$1000,5,FALSE),0) -> 0.1869 | X41: =M41*Q41*U41 -> 0 | Y41: =M41*Q41*V41 -> 0 | Z41: =(P41*M41)-(X41+Y41) -> 0 | AA41: =IF(M41<0, P41-Q41, 0) -> 0 | AB41: =IF(M41>0, Q41*(1-0.2%)-P41, 0) -> 0 | AC41: =AA41/Q41*10000 -> 0 | AD41: =AB41/Q41*10000 -> 0 | AE41: =ABS(N41) -> 0 | AG41: =B41 -> 091220 | AH41: =-1*M41 -> 0 | AJ41: =ROUNDUP(VLOOKUP(B41,[2]베타!$A$2:$L$1000,12,FALSE),0) -> 8 | AK41: =ROUNDUP(VLOOKUP(B41,[2]베타!$A$2:$M$1000,13,FALSE),0) -> -30
B42: 261070 | C42: TIGER 코스닥150바이오테크 | D42: =VLOOKUP("A"&B42,[2]ETF!$A$4:$M$10000,13,FALSE) -> 20000 | E42: =[1]!'261070:VOL'+0 -> 383818 | F42: 019875 | G42: =IF([1]!'019875^261070:SELL_TDY_QTY'="NO", 0, [1]!'019875^261070:SELL_TDY_QTY') -> 2000 | H42: =IF([1]!'019875^261070:SELL_TDY_AMT'="NO", 0, [1]!'019875^261070:SELL_TDY_AMT') -> 25149875 | I42: =IFERROR(H42/G42,0) -> 12574.938 | J42: =IF([1]!'019875^261070:BUY_TDY_QTY'="NO", 0, [1]!'019875^261070:BUY_TDY_QTY') -> 2000 | K42: =IF([1]!'019875^261070:BUY_TDY_AMT'="NO", 0, [1]!'019875^261070:BUY_TDY_AMT') -> 25504225 | L42: =IFERROR(K42/J42,0) -> 12752.112 | M42: =J42-G42 -> 0 | N42: =M42*P42 -> 0 | O42: =M42/D42 -> 0 | P42: =[1]!'261070:LAST'+0 -> 12340 | Q42: =[1]!'261070:NAV'+0 -> 12322.12 | R42: =(P42-I42)*-1*G42 -> 469875 | S42: =(P42-L42)*J42 -> -824225 | T42: =R42+S42 -> -354350 | U42: =_xlfn.IFNA(VLOOKUP(B42,[2]베타!$A$2:$C$1000,3,FALSE),0) -> -0.2623 | V42: =_xlfn.IFNA(VLOOKUP(B42,[2]베타!$A$2:$D$1000,4,FALSE),0) -> 1.0611 | W42: =_xlfn.IFNA(VLOOKUP(B42,[2]베타!$A$2:$E$1000,5,FALSE),0) -> 0.6973 | X42: =M42*Q42*U42 -> 0 | Y42: =M42*Q42*V42 -> 0 | Z42: =(P42*M42)-(X42+Y42) -> 0 | AA42: =IF(M42<0, P42-Q42, 0) -> 0 | AB42: =IF(M42>0, Q42*(1-0.2%)-P42, 0) -> 0 | AC42: =AA42/Q42*10000 -> 0 | AD42: =AB42/Q42*10000 -> 0 | AG42: =B42 -> 261070 | AH42: =-1*M42 -> 0 | AJ42: =ROUNDUP(VLOOKUP(B42,[2]베타!$A$2:$L$1000,12,FALSE),0) -> 11 | AK42: =ROUNDUP(VLOOKUP(B42,[2]베타!$A$2:$M$1000,13,FALSE),0) -> -35
...

Sheet Sheet2
R1: 0.9
P2: 0 | Q2: 0 | R2: 0
J3: ABS 포지션 | K3: 0 | O3: 상품 | P3: ETF 델타 | Q3: 선물 델타 | R3: NET 델타 | S3: 계약수 환산 | T3: 필요 계약수 | U3: 당일 손익 | V3: NET
J4: 매도 포지션 | K4: 0 | N4: #DIV/0! | O4: KOSPI 200 | P4: 0 | Q4: 0 | R4: 0 | S4: 0 | T4: 0 | U4: 6087242 | V4: 바스켓
J5: 매수 포재션 | K5: 0 | N5: #DIV/0! | O5: KOSDAQ 150 | P5: 0 | Q5: 0 | R5: 0 | S5: 0 | T5: 0 | V5: 현금
B7: 종목코드 | C7: 종목명 | D7: 1CU | E7: 시장 거래량 | F7: 펀드코드 | G7: 당일매도수량 | H7: 당일매도금액 | I7: 매도단가 | J7: 당일매수수량 | K7: 당일매수금액 | L7: 매수단가 | M7: NET 포지션 수량 | N7: NET 포지션 금액 | O7: CU 비중 | P7: 현재가 | Q7: 매도 손익 | R7: 매수 손익 | S7: 당일 손익 | T7: 1계약 델타 | U7: 전체 잔고 수량
B9: - | C9: - | D9: - | E9: - | F9: - | G9: 93 | H9: 2938118000 | I9: - | J9: 93 | K9: 2928765000 | L9: - | M9: 0 | N9: 0 | O9: - | P9: - | Q9: 25948000 | R9: -16595000 | S9: 9353000 | T9: 65473000 | U9: 0
B10: A0569 | C10: 미니 코스피 200 선물 | D10: 0 | E10: - | F10: 028875 | G10: 43 | H10: 2242428000 | I10: 1042.9898 | J10: 43 | K10: 2233695000 | L10: 1038.9279 | M10: 0 | N10: 0 | O10: - | P10: 1032.8 | Q10: 21908000 | R10: -13175000 | S10: 8733000 | T10: 51640000 | U10: 0
B11: A0669 | C11: 코스닥 150 선물 | D11: 0 | E11: - | F11: 028875 | G11: 50 | H11: 695690000 | I11: 1391.38 | J11: 50 | K11: 695070000 | L11: 1390.14 | M11: 0 | N11: 0 | O11: - | P11: 1383.3 | Q11: 4040000 | R11: -3420000 | S11: 620000 | T11: 13833000 | U11: 0
G12: =@IF(@KBMonitor|DATA!'019875^091220:SELL_TDY_QTY'="NO", 0, KBMonitor|DATA!'019875^091220:SELL_TDY_QTY') | N12: 0 | T12: * 200과 150은 전일종가(금액)으로 계산 | AA12: 유리 여부
B13: 종목코드 | C13: 종목명 | D13: 1CU | E13: 시장 거래량 | F13: 펀드코드 | G13: 당일매도수량 | H13: 당일매도금액 | I13: 매도단가 | J13: 당일매수수량 | K13: 당일매수금액 | L13: 매수단가 | M13: NET 포지션 수량 | N13: NET 포지션 금액 | O13: CU 비중 | P13: 현재가 | Q13: NAV | R13: 매도 손익 | S13: 매수 손익 | T13: 당일 손익 | U13: KS 베타 | V13: KQ 베타 | W13: R-Squared | X13: W.KOSPI200 | Y13: W.KOSDAQ150 | Z13: W.200&150 외 | AA13: 매도 손익 (nav 대비) | AB13: 매수 손익 (nav 대비) | AC13: 매도 손익 (nav 대비) | AD13: 매수 손익 (nav 대비) | AE13: 포지션 abs
B14: - | C14: - | D14: - | E14: - | F14: - | G14: 218583 | H14: 4781740996 | I14: - | J14: 218583 | K14: 4785006754 | L14: - | M14: 0 | N14: 0 | O14: - | P14: - | Q14: - | R14: 45624941 | S14: -48890699 | T14: -3265758 | U14: 0.25538684 | V14: 0.46778684 | W14: 0.5729 | X14: 0 | Y14: 0 | Z14: 0 | AA14: 0 | AB14: 0 | AC14: 0 | AD14: 0 | AE14: 0 | AG14: 종목코드 | AH14: 정리매매 | AJ14: 매도 bp | AK14: 매수 bp
B15: 396500 | C15: TIGER 반도체TOP10 | D15: 50000 | E15: 7272468 | F15: 019875 | G15: 78372 | H15: 2680505060 | I15: 34202.331 | J15: 78372 | K15: 2686885015 | L15: 34283.737 | M15: 0 | N15: 0 | O15: 0 | P15: 33910 | Q15: 33974.39 | R15: 22910540 | S15: -29290495 | T15: -6379955 | U15: 1.1175 | V15: 0.1842 | W15: 0.9274 | X15: 0 | Y15: 0 | Z15: 0 | AA15: 0 | AB15: 0 | AC15: 0 | AD15: 0 | AE15: 0 | AG15: 396500 | AH15: 0 | AJ15: -3 | AK15: -20
B16: 228790 | C16: TIGER 화장품 | D16: 30000 | E16: 9774397 | F16: 019875 | G16: 4059 | H16: 19281855 | I16: 4750.3954 | J16: 4059 | K16: 19323495 | L16: 4760.6541 | M16: 0 | N16: 0 | O16: 0 | P16: 4720 | Q16: 4730.48 | R16: 123375 | S16: -165015 | T16: -41640 | U16: -0.211 | V16: 0.5851 | W16: 0.3567 | X16: 0 | Y16: 0 | Z16: 0 | AA16: 0 | AB16: 0 | AC16: 0 | AD16: 0 | AE16: 0 | AG16: 228790 | AH16: 0 | AJ16: 14 | AK16: -28
B17: 462010 | C17: TIGER 2차전지소재Fn | D17: 50000 | E17: 2593180 | F17: 019875 | G17: 1767 | H17: 8706400 | I17: 4927.2213 | J17: 1767 | K17: 8494840 | L17: 4807.4929 | M17: 0 | N17: 0 | O17: 0 | P17: 4775 | Q17: 4779.8 | R17: 268975 | S17: -57415 | T17: 211560 | U17: 0.0594 | V17: 0.8415 | W17: 0.6174 | X17: 0 | Y17: 0 | Z17: 0 | AA17: 0 | AB17: 0 | AC17: 0 | AD17: 0 | AE17: 0 | AG17: 462010 | AH17: 0 | AJ17: 10 | AK17: -29
B18: 364980 | C18: TIGER 2차전지TOP10 | D18: 50000 | E18: 4056999 | F18: 019875 | G18: 47838 | H18: 495100400 | I18: 10349.521 | J18: 47838 | K18: 492394585 | L18: 10292.959 | M18: 0 | N18: 0 | O18: 0 | P18: 10180 | Q18: 10199.49 | R18: 8109560 | S18: -5403745 | T18: 2705815 | U18: 0.0699 | V18: 0.6894 | W18: 0.4887 | X18: 0 | Y18: 0 | Z18: 0 | AA18: 0 | AB18: 0 | AC18: 0 | AD18: 0 | AE18: 0 | AG18: 364980 | AH18: 0 | AJ18: 9 | AK18: -28
B19: 0117V0 | C19: TIGER 코리아AI전력기기TOP3플러스 | D19: 50000 | E19: 1104092 | F19: 019875 | G19: 2729 | H19: 49657675 | I19: 18196.29 | J19: 2729 | K19: 50436405 | L19: 18481.643 | M19: 0 | N19: 0 | O19: 0 | P19: 17950 | Q19: 17963.4 | R19: 672125 | S19: -1450855 | T19: -778730 | U19: 0.4144 | V19: 0.7155 | W19: 0.6341 | X19: 0 | Y19: 0 | Z19: 0 | AA19: 0 | AB19: 0 | AC19: 0 | AD19: 0 | AE19: 0 | AG19: 0117V0 | AH19: 0 | AJ19: 7 | AK19: -27
B20: 305540 | C20: TIGER 2차전지테마 | D20: 50000 | E20: 571319 | F20: 019875 | G20: 1001 | H20: 19023575 | I20: 19004.57 | J20: 1001 | K20: 18953575 | L20: 18934.64 | M20: 0 | N20: 0 | O20: 0 | P20: 18450 | Q20: 18449.6 | R20: 555125 | S20: -485125 | T20: 70000 | U20: 0.0416 | V20: 0.7049 | W20: 0.5319 | X20: 0 | Y20: 0 | Z20: 0 | AA20: 0 | AB20: 0 | AC20: 0 | AD20: 0 | AE20: 0 | AG20: 305540 | AH20: 0 | AJ20: 9 | AK20: -28
B21: 494670 | C21: TIGER 조선TOP10 | D21: 50000 | E21: 410617 | F21: 019875 | G21: 20807 | H21: 436190212 | I21: 20963.628 | J21: 20807 | K21: 433007335 | L21: 20810.657 | M21: 0 | N21: 0 | O21: 0 | P21: 20730 | Q21: 20733.82 | R21: 4861102 | S21: -1678225 | T21: 3182877 | U21: 0.1698 | V21: 0.4181 | W21: 0.3854 | X21: 0 | Y21: 0 | Z21: 0 | AA21: 0 | AB21: 0 | AC21: 0 | AD21: 0 | AE21: 0 | AG21: 494670 | AH21: 0 | AJ21: 5 | AK21: -26
B22: 364970 | C22: TIGER 바이오TOP10 | D22: 50000 | E22: 1567969 | F22: 019875 | G22: 20055 | H22: 149019704 | I22: 7430.5512 | J22: 20055 | K22: 148868755 | L22: 7423.0244 | M22: 0 | N22: 0 | O22: 0 | P22: 7330 | Q22: 7336.02 | R22: 2016554 | S22: -1865605 | T22: 150949 | U22: -0.0509 | V22: 0.5849 | W22: 0.5155 | X22: 0 | Y22: 0 | Z22: 0 | AA22: 0 | AB22: 0 | AC22: 0 | AD22: 0 | AE22: 0 | AG22: 364970 | AH22: 0 | AJ22: 5 | AK22: -26
B23: 0091P0 | C23: TIGER 코리아원자력 | D23: 50000 | E23: 844367 | F23: 019875 | G23: 0 | H23: 0 | I23: 0 | J23: 0 | K23: 0 | L23: 0 | M23: 0 | N23: 0 | O23: 0 | P23: 15865 | Q23: 15872.83 | R23: 0 | S23: 0 | T23: 0 | U23: 0.2045 | V23: 0.8173 | W23: 0.6259 | X23: 0 | Y23: 0 | Z23: 0 | AA23: 0 | AB23: 0 | AC23: 0 | AD23: 0 | AE23: 0 | AG23: 0091P0 | AH23: 0 | AJ23: 10 | AK23: -31
B24: 292150 | C24: TIGER 코리아TOP10 | D24: 50000 | E24: 280457 | F24: 019875 | G24: 3783 | H24: 137718750 | I24: 36404.639 | J24: 3783 | K24: 138696635 | L24: 36663.134 | M24: 0 | N24: 0 | O24: 0 | P24: 36275 | Q24: 36312.88 | R24: 490425 | S24: -1468310 | T24: -977885 | U24: 0.9661 | V24: -0.0116 | W24: 0.9806 | X24: 0 | Y24: 0 | Z24: 0 | AA24: 0 | AB24: 0 | AC24: 0 | AD24: 0 | AE24: 0 | AG24: 292150 | AH24: 0 | AJ24: 3 | AK24: -22
B25: 139230 | C25: TIGER 200 중공업 | D25: 20000 | E25: 67303 | F25: 019875 | G25: 0 | H25: 0 | I25: 0 | J25: 0 | K25: 0 | L25: 0 | M25: 0 | N25: 0 | O25: 0 | P25: 12340 | Q25: 12340.11 | R25: 0 | S25: 0 | T25: 0 | U25: 0.2392 | V25: 0.5334 | W25: 0.6099 | X25: 0 | Y25: 0 | Z25: 0 | AA25: 0 | AB25: 0 | AC25: 0 | AD25: 0 | AE25: 0 | AG25: 139230 | AH25: 0 | AJ25: 12 | AK25: -29
B26: 364990 | C26: TIGER 게임TOP10 | D26: 50000 | E26: 44273 | F26: 019875 | G26: 2 | H26: 9570 | I26: 4785 | J26: 2 | K26: 9435 | L26: 4717.5 | M26: 0 | N26: 0 | O26: 0 | P26: 4715 | Q26: 4712.38 | R26: 140 | S26: -5 | T26: 135 | U26: -0.076 | V26: 0.328 | W26: 0.1582 | X26: 0 | Y26: 0 | Z26: 0 | AA26: 0 | AB26: 0 | AC26: 0 | AD26: 0 | AE26: 0 | AG26: 364990 | AH26: 0 | AJ26: 19 | AK26: -35
... B30: 307520 | C30: TIGER 지주회사 | D30: 50000 | E30: 208433 | F30: 019875 | G30: 16 | H30: 352265 | I30: 22016.562 | J30: 16 | K30: 351560 | L30: 21972.5 | M30: 0 | N30: 0 | O30: 0 | P30: 21900 | Q30: 21923.78 | R30: 1865 | S30: -1160 | T30: 705 | U30: 0.3637 | V30: 0.3803 | W30: 0.7504 | X30: 0 | Y30: 0 | Z30: 0 | AA30: 0 | AB30: 0 | AC30: 0 | AD30: 0 | AE30: 0 | AG30: 307520 | AH30: 0 | AJ30: 5 | AK30: -30
B31: 157490 | C31: TIGER 소프트웨어 | D31: 20000 | F31: 019875 | G31: 1356 | H31: 11287817 | I31: 8324.3488 | J31: 1356 | K31: 11265965 | L31: 8308.2338 | M31: 0 | N31: 0 | O31: 0 | P31: 8290 | Q31: 8297.47 | R31: 46577 | S31: -24725 | T31: 21852 | U31: 0.1859 | V31: 0.2998 | W31: 0.3632 | X31: 0 | Y31: 0 | Z31: 0 | AA31: 0 | AB31: 0 | AC31: 0 | AD31: 0 | AE31: 0 | AG31: 157490 | AH31: 0 | AJ31: 11 | AK31: -33
B32: 471760 | C32: TIGER AI반도체핵심공정 | D32: 50000 | E32: 635046 | F32: 019875 | G32: 1921 | H32: 27119665 | I32: 14117.473 | J32: 1921 | K32: 27435130 | L32: 14281.692 | M32: 0 | N32: 0 | O32: 0 | P32: 14190 | Q32: 14224.8 | R32: -139325 | S32: -176140 | T32: -315465 | U32: 0.5112 | V32: 0.8111 | W32: 0.7985 | X32: 0 | Y32: 0 | Z32: 0 | AA32: 0 | AB32: 0 | AC32: 0 | AD32: 0 | AE32: 0 | AG32: 471760 | AH32: 0 | AJ32: 7 | AK32: -30
B33: 0052D0 | C33: TIGER 코리아배당다우존스 | D33: 50000 | E33: 57305 | F33: 019875 | G33: 280 | H33: 4361740 | I33: 15577.643 | J33: 280 | K33: 4343975 | L33: 15514.196 | M33: 0 | N33: 0 | O33: 0 | P33: 15475 | Q33: 15481.76 | R33: 28740 | S33: -10975 | T33: 17765 | U33: 0.1038 | V33: 0.2279 | W33: 0.4037 | X33: 0 | Y33: 0 | Z33: 0 | AA33: 0 | AB33: 0 | AC33: 0 | AD33: 0 | AE33: 0 | AG33: 0052D0 | AH33: 0 | AJ33: 6 | AK33: -23
B34: 466940 | C34: TIGER 은행고배당플러스TOP10 | D34: 50000 | E34: 810965 | F34: 019875 | G34: 6383 | H34: 173165013 | I34: 27129.095 | J34: 6383 | K34: 172349100 | L34: 27001.269 | M34: 0 | N34: 0 | O34: 0 | P34: 26785 | Q34: 26777.4 | R34: 2196358 | S34: -1380445 | T34: 815913 | U34: 0.1052 | V34: 0.1725 | W34: 0.2584 | X34: 0 | Y34: 0 | Z34: 0 | AA34: 0 | AB34: 0 | AC34: 0 | AD34: 0 | AE34: 0 | AG34: 466940 | AH34: 0 | AJ34: 4 | AK34: -22
B35: 139220 | C35: TIGER 200 건설 | D35: 20000 | E35: 317711 | F35: 019875 | G35: 0 | H35: 0 | I35: 0 | J35: 0 | K35: 0 | L35: 0 | M35: 0 | N35: 0 | O35: 0 | P35: 7400 | Q35: 7404.52 | R35: 0 | S35: 0 | T35: 0 | U35: 0.4238 | V35: 0.5168 | W35: 0.6182 | X35: 0 | Y35: 0 | Z35: 0 | AA35: 0 | AB35: 0 | AC35: 0 | AD35: 0 | AE35: 0 | AG35: 139220 | AH35: 0 | AJ35: 12 | AK35: -32
B36: 365000 | C36: TIGER 인터넷TOP10 | D36: 50000 | E36: 130272 | F36: 019875 | G36: 30 | H36: 106825 | I36: 3560.8333 | J36: 30 | K36: 105470 | L36: 3515.6667 | M36: 0 | N36: 0 | O36: 0 | P36: 3510 | Q36: 3506.08 | R36: 1525 | S36: -170 | T36: 1355 | U36: 0.0803 | V36: 0.506 | W36: 0.5622 | X36: 0 | Y36: 0 | Z36: 0 | AA36: 0 | AB36: 0 | AC36: 0 | AD36: 0 | AE36: 0 | AG36: 365000 | AH36: 0 | AJ36: 17 | AK36: -38
B37: 228800 | C37: TIGER 여행레저 | D37: 30000 | E37: 142297 | F37: 019875 | G37: 1177 | H37: 3209970 | I37: 2727.2472 | J37: 1177 | K37: 3195555 | L37: 2715 | M37: 0 | N37: 0 | O37: 0 | P37: 2725 | Q37: 2719.22 | R37: 2645 | S37: 11770 | T37: 14415 | U37: -0.0175 | V37: 0.375 | W37: 0.3333 | X37: 0 | Y37: 0 | Z37: 0 | AA37: 0 | AB37: 0 | AC37: 0 | AD37: 0 | AE37: 0 | AG37: 228800 | AH37: 0 | AJ37: 18 | AK37: -32
B38: 138540 | C38: TIGER 현대차그룹플러스 | D38: 20000 | E38: 121690 | F38: 019875 | G38: 669 | H38: 32521825 | I38: 48612.593 | J38: 669 | K38: 32922975 | L38: 49212.22 | M38: 0 | N38: 0 | O38: 0 | P38: 48300 | Q38: 48323.91 | R38: 209125 | S38: -610275 | T38: -401150 | U38: 0.3759 | V38: 0.293 | W38: 0.5372 | X38: 0 | Y38: 0 | Z38: 0 | AA38: 0 | AB38: 0 | AC38: 0 | AD38: 0 | AG38: 138540 | AH38: 0 | AJ38: 5 | AK38: -24
B39: 377990 | C39: TIGER Fn신재생에너지 | D39: 50000 | E39: 76744 | F39: 019875 | G39: 1 | H39: 23940 | I39: 23940 | J39: 1 | K39: 23360 | L39: 23360 | M39: 0 | N39: 0 | O39: 0 | P39: 23265 | Q39: 23270.46 | R39: 675 | S39: -95 | T39: 580 | U39: 0.2013 | V39: 0.8172 | W39: 0.6391 | X39: 0 | Y39: 0 | Z39: 0 | AA39: 0 | AB39: 0 | AC39: 0 | AD39: 0 | AE39: 0 | AG39: 377990 | AH39: 0 | AJ39: 10 | AK39: -30
B40: 395270 | C40: HANARO Fn K-반도체 | D40: 50000 | E40: 859501 | F40: 019875 | G40: 5293 | H40: 285275550 | I40: 53896.76 | J40: 5293 | K40: 285914745 | L40: 54017.522 | M40: 0 | N40: 0 | O40: 0 | P40: 53570 | Q40: 53669.75 | R40: 1729540 | S40: -2368735 | T40: -639195 | U40: 1.1755 | V40: 0.0971 | W40: 0.9138 | X40: 0 | Y40: 0 | Z40: 0 | AA40: 0 | AB40: 0 | AC40: 0 | AD40: 0 | AE40: 0 | AG40: 395270 | AH40: 0 | AJ40: 2 | AK40: -23
B41: 091220 | C41: TIGER 은행 | D41: 20000 | E41: 90828 | F41: 019875 | G41: 0 | H41: 0 | I41: 0 | J41: 0 | K41: 0 | L41: 0 | M41: 0 | N41: 0 | O41: 0 | P41: 17085 | Q41: 17091.67 | R41: 0 | S41: 0 | T41: 0 | U41: 0.0486 | V41: 0.2094 | W41: 0.1869 | X41: 0 | Y41: 0 | Z41: 0 | AA41: 0 | AB41: 0 | AC41: 0 | AD41: 0 | AE41: 0 | AG41: 091220 | AH41: 0 | AJ41: 8 | AK41: -30
B42: 261070 | C42: TIGER 코스닥150바이오테크 | D42: 20000 | E42: 380643 | F42: 019875 | G42: 2000 | H42: 25149875 | I42: 12574.938 | J42: 2000 | K42: 25504225 | L42: 12752.112 | M42: 0 | N42: 0 | O42: 0 | P42: 12365 | Q42: 12384.66 | R42: 419875 | S42: -774225 | T42: -354350 | U42: -0.2623 | V42: 1.0611 | W42: 0.6973 | X42: 0 | Y42: 0 | Z42: 0 | AA42: 0 | AB42: 0 | AC42: 0 | AD42: 0 | AG42: 261070 | AH42: 0 | AJ42: 11 | AK42: -35
B43: 261060 | C43: TIGER 코스닥150IT | D43: 20000 | E43: 16483 | F43: 019875 | G43: 10 | H43: 227890 | I43: 22789 | J43: 10 | K43: 226850 | L43: 22685 | M43: 0 | N43: 0 | O43: 0 | P43: 22825 | Q43: 22872.24 | R43: -360 | S43: 1400 | T43: 1040 | U43: 0.2093 | V43: 1.0199 | W43: 0.8372 | X43: 0 | Y43: 0 | Z43: 0 | AA43: 0 | AB43: 0 | AC43: 0 | AD43: 0 | AG43: 261060 | AH43: 0 | AJ43: 18 | AK43: -42
B44: 138520 | C44: TIGER 삼성그룹 | D44: 20000 | E44: 16928 | F44: 019875 | G44: 980 | H44: 35319200 | I44: 36040 | J44: 980 | K44: 35321430 | L44: 36042.276 | M44: 0 | N44: 0 | O44: 0 | P44: 35950 | Q44: 35945.38 | R44: 88200 | S44: -90430 | T44: -2230 | U44: 0.8007 | V44: 0.0775 | W44: 0.9127 | X44: 0 | Y44: 0 | Z44: 0 | AA44: 0 | AB44: 0 | AC44: 0 | AD44: 0 | AG44: 138520 | AH44: 0 | AJ44: 12 | AK44: -32
B45: 139250 | C45: TIGER 200 에너지화학 | D45: 20000 | E45: 21626 | F45: 019875 | G45: 28 | H45: 490040 | I45: 17501.429 | J45: 28 | K45: 500640 | L45: 17880 | M45: 0 | N45: 0 | O45: 0 | P45: 17420 | Q45: 17452.42 | R45: 2280 | S45: -12880 | T45: -10600 | U45: 0.2662 | V45: 0.3982 | W45: 0.6178 | X45: 0 | Y45: 0 | Z45: 0 | AA45: 0 | AB45: 0 | AC45: 0 | AD45: 0 | AG45: 139250 | AH45: 0 | AJ45: 19 | AK45: -34
...

Sheet Sheet3
